Workbook

Sheet 00_Cover
A1: AUROBINDO PHARMA | OUTPERFORM UNDERWRITING MODEL
A2: As of 6 October 2026 | ₹ crore unless stated | Internal research working draft
B4: RATING OUTPUT
B5: Rating | C5: ='09_Valuation'!C32 | D5: Upgrade from Market-Perform
B6: Current price | C6: ='09_Valuation'!C30 | D6: NSE close, 6 Oct 2026 [S21]
B7: Target price | C7: ='09_Valuation'!C29 | D7: DCF-derived, rounded to nearest ₹50
B8: Upside | C8: ='09_Valuation'!C31 | D8: Ex-dividend
B9: FY26A–FY31E EPS CAGR | C9: 0.17120225 | D9: Model output
B10: FY26A–FY31E EBITDA CAGR | C10: 0.13778327 | D10: Model output
B13: THE UPGRADE IN ONE PAGE
B14: Catalyst | C14: Claim | D14: First-principles test | E14: Model sheet
B15: Lannett | C15: 40% utilization becomes the earnings lever | D15: 3.6bn-dose capacity vs ~1.4bn current output; site transfers and fixed-cost absorption take EBITDA margin to 16% in FY28E and 19% in FY29E. | E15: 02_Lannett
B16: FDA / respiratory | C16: Risk is narrower; Raleigh can progress | D16: Raleigh is VAI/closed and QVAR is approved. Eugia remains the sterile bottleneck, but respiratory EBITDA covers the modelled Eugia drag by FY29E. | E16: 03_FDA / 04_Resp_Eugia
B17: Pen-G | C17: Domestic protection helps, captive economics sustain | D17: Base case uses 15,000MT installed capacity, separates external revenue from captive savings and lets PLI fall to zero after FY29E. | E17: 05_PenG
B18: Biosimilars | C18: Late entry can still clear the margin hurdle | D18: Own EU infrastructure, partner channels and declining clinical spend take EBITDA margin from -20% in FY27E to 26% in FY30E. | E18: 06_Biosimilars
B19: US dermatology | C19: The second product amortizes the platform | D19: ADQUEY is launched. Public sources do not identify product two; the sheet shows the exact sales hurdle needed for segment break-even. | E19: 07_Dermatology
B22: MODEL NAVIGATION AND CONTROL
B23: 01_Thesis | C23: Old thesis vs new evidence; catalyst scorecard
B24: 02_Lannett | C24: Utilization, ADHD/non-ADHD, CBE-30/PAS transfer matrix, margin bridge
B25: 03_FDA | C25: Site-level inspection tracker and risk-weighted approval capacity
B26: 04_Resp_Eugia | C26: Product-level respiratory build and Eugia offset
B27: 05_PenG | C27: Volume/mix/price/PLI/captive savings and ROIC
B28: 06_Biosimilars | C28: Molecule-by-molecule launch build and margin bridge
B29: 07_Dermatology | C29: ADQUEY + undisclosed product-two profitability hurdle
B30: 08_Financials | C30: Segment revenue, EBITDA, EPS and estimate revisions
B31: 09_Valuation | C31: DCF, sensitivity, market multiples and rating triggers
B32: 10_Sources | C32: Primary-source log and analyst assumption register
B33: 11_QC | C33: Model checks
B36: Legend | C36: Hardcode / analyst assumption | D36: ="Formula / linked output" | E36: Source-backed facts carry cell comments or source IDs

Sheet 01_Thesis
A1: THESIS BRIDGE | WHAT CHANGED SINCE INITIATION
A2: The upgrade requires both earnings conversion and a narrower left-tail risk. Price performance alone is not evidence.
B4: ORIGINAL OBJECTION → NEW EVIDENCE → MODEL CONSEQUENCE
B5: Issue | C5: Original MP thesis | D5: New evidence | E5: First-principles test | F5: FY28E EBITDA | G5: FY29E EBITDA | H5: Confidence | I5: Failure condition
B6: Lannett | C6: PV only ~₹12/share; 5–6pp US margin dilution | D6: Deal closed; $60m quarterly base; ~40% utilization; 12-month plan and synergies | E6: Can added volume cover fixed cost before relying on price? | F6: 405 | G6: 559 | H6: Medium-high | I6: Utilization remains below 50% by FY29
B7: FDA | C7: Quality issues persisted into a fifth year | D7: Raleigh VAI/closed; Seymour observations procedural; several API sites at 0–3 observations | E7: Has risk moved from enterprise-wide to site-specific? | F7: 0 | G7: 0 | H7: Medium | I7: Raleigh regresses or another oral/API site receives OAI
B8: Respiratory | C8: Pipeline optional but timing uncertain | D8: Advair launched; QVAR approved; Raleigh applications can progress | E8: Does launch EBITDA cover sterile approval drag? | F8: 112 | G8: 233 | H8: Medium-high | I8: QVAR launch slips beyond FY28 or Advair share <2%
B9: Pen-G | C9: Benefit seen as already priced; import economics adverse | D9: MIP introduced; 800–900t/month run-rate; external supply and exports commenced | E9: Does ex-PLI EBITDA remain positive at export prices? | F9: 548 | G9: 522 | H9: Medium-high | I9: Yield/cost miss keeps ex-PLI ROIC below 10%
B10: Biosimilars | C10: Second-wave, delayed, single-digit return | D10: Four products commercial in Europe/UK; US filings scheduled; clinical spend falls | E10: Can shared infrastructure lift EBITDA margin above group margin? | F10: 38 | G10: 278 | H10: Medium | I10: Tender conversion or US filing slips by >12 months
B11: US derma | C11: Not in original core case | D11: ADQUEY launched and dedicated field platform created | E11: Can two products cover the fixed field cost? | F11: -102 | G11: 53 | H11: Low-medium | I11: Second product absent and ADQUEY sales <US$60m in FY29
B14: RATING BRIDGE
B15: Old target price | C15: 1498 | D15: Uploaded initiation [S1]
B16: DCF fair value | C16: ='09_Valuation'!C28 | D16: 09_Valuation
B17: Rounded target | C17: ='09_Valuation'!C29 | D17: Nearest ₹50
B18: Current price | C18: ='09_Valuation'!C30 | D18: 6 Oct 2026 [S21]
B19: Upside | C19: ='09_Valuation'!C31 | D19: Target/current - 1
B20: Rating | C20: ='09_Valuation'!C32 | D20: Threshold: >15% expected return

Sheet 02_Lannett
A1: LANNETT | 40% UTILIZATION IS THE EARNINGS LEVER
A2: Site transfers are modelled by regulatory route; ADHD growth remains quota-constrained.
B4: TRANSACTION AND CAPACITY FACTS
B5: Purchase price (US$m) | C5: 250 | D5: S5/S6
B6: FY25 net sales (US$m) | C6: 306 | D6: S5
B7: Demonstrated capacity (bn doses) | C7: 3.6 | D7: S5
B8: Current annual output (bn units) | C8: 1.4 | D8: S5
B9: Implied utilization | C9: 0.38888889 | D9: Calculated
B10: Base quarterly sales target (US$m) | C10: 60 | D10: S4
B11: FTC product divestitures | C11: 4 | D11: S7
B12: Site footprint | C12: ~425k sq ft incl. 116k leased distribution | D12: S5
B13: Workforce / active products | C13: 500+ employees / ~70 active products | D13: S5
B14: BASE-CASE OPERATING BUILD
C15: FY27E | D15: FY28E | E15: FY29E | F15: FY30E | G15: FY31E
B16: Capacity (bn doses) | C16: 3.6 | D16: 3.6 | E16: 3.6 | F16: 3.6 | G16: 3.6
B17: Utilization | C17: 0.4 | D17: 0.47 | E17: 0.56 | F17: 0.64 | G17: 0.7
B18: Output (bn doses) | C18: =C16*C17 | D18: =D16*D17 | E18: =E16*E17 | F18: =F16*F17 | G18: =G16*G17
B19: Base acquired revenue (US$m) | C19: 180 | D19: 240 | E19: 245 | F19: 250 | G19: 255
B20: Risk-adjusted site transfers (US$m) | C20: 0 | D20: 25 | E20: 60 | F20: 80 | G20: 90
B21: Total revenue (US$m) | C21: =C19+C20 | D21: =D19+D20 | E21: =E19+E20 | F21: =F19+F20 | G21: =G19+G20
B22: INR/US$ | C22: 94.5 | D22: 95.5 | E22: 96.5 | F22: 97.5 | G22: 98.5
B23: Revenue (₹cr) | C23: =C21*C22/10 | D23: =D21*D22/10 | E23: =E21*E22/10 | F23: =F21*F22/10 | G23: =G21*G22/10
B24: EBITDA margin | C24: 0.12 | D24: 0.16 | E24: 0.19 | F24: 0.21 | G24: 0.22
B25: EBITDA (₹cr) | C25: =C23*C24 | D25: =D23*D24 | E25: =E23*E24 | F25: =F23*F24 | G25: =G23*G24
B26: Incremental revenue per +10pp utilization (US$m) | C26: =$C$7*10%*($C$6/$C$8) | D26: =$C$7*10%*($C$6/$C$8) | E26: =$C$7*10%*($C$6/$C$8) | F26: =$C$7*10%*($C$6/$C$8) | G26: =$C$7*10%*($C$6/$C$8)
B27: Incremental EBITDA per +10pp utilization (US$m) | C27: =C26*30% | D27: =D26*30% | E27: =E26*30% | F27: =F26*30% | G27: =G26*30%
B30: ADHD VS NON-ADHD / CDMO
C31: FY27E | D31: FY28E | E31: FY29E | F31: FY30E | G31: FY31E
B32: ADHD / controlled share | C32: 0.08 | D32: 0.08 | E32: 0.09 | F32: 0.1 | G32: 0.1
B33: Non-ADHD generics share | C33: 0.5 | D33: 0.52 | E33: 0.54 | F33: 0.55 | G33: 0.56
B34: CDMO / other share | C34: 0.42 | D34: 0.4 | E34: 0.37 | F34: 0.35 | G34: 0.34
B35: Mix check | C35: =SUM(C32:C34) | D35: =SUM(D32:D34) | E35: =SUM(E32:E34) | F35: =SUM(F32:F34) | G35: =SUM(G32:G34)
B36: ADHD growth constraint | C36: 0.05 | D36: 0.05 | E36: 0.05 | F36: 0.05 | G36: 0.05
B37: FY25 disclosed composition | C37: Controlled 6% | D37: Non-controlled 47% | E37: CMO 47% | F37: S5
B39: SITE-TRANSFER MATRIX | CBE-30 VS PAS
B40: Program | C40: Route | D40: Submission | E40: Model lag (months) | F40: Approval probability | G40: Steady-state sales (US$m) | H40: FY27E | I40: FY28E | J40: FY29E | K40: FY30E | L40: FY31E
B41: Transfer 1 | C41: CBE-30 | D41: FY27 Q2 | E41: 6 | F41: 0.85 | G41: 10 | H41: 0 | I41: 5 | J41: 9 | K41: 10 | L41: 10
B42: Transfer 2 | C42: CBE-30 | D42: FY27 Q3 | E42: 6 | F42: 0.85 | G42: 12 | H42: 0 | I42: 5 | J42: 10 | K42: 12 | L42: 12
B43: Transfer 3 | C43: CBE-30 | D43: FY27 Q4 | E43: 9 | F43: 0.8 | G43: 10 | H43: 0 | I43: 4 | J43: 8 | K43: 10 | L43: 10
B44: Transfer 4 | C44: CBE-30 | D44: FY28 Q1 | E44: 9 | F44: 0.8 | G44: 10 | H44: 0 | I44: 3 | J44: 7 | K44: 9 | L44: 10
...

Sheet 03_FDA
A1: FDA | THE RISK IS NARROWER, NOT GONE
A2: Non-sterile and API outcomes have improved. Eugia remains the approval bottleneck.
B4: SITE-LEVEL TRACKER
B5: Site | C5: Dosage / role | D5: Inspection date | E5: 483 obs. | F5: Status | G5: Latest outcome | H5: Pending ANDAs | I5: Revenue exposure | J5: Risk score (1-5) | K5: Approval release prob. | L5: Risk-weighted pending | M5: Source
B6: Raleigh, NC | C6: Inhalers / derma / transdermal | D6: Mar–Apr 2025 | E6: 11 | F6: VAI / EIR closed | G6: Applications can progress | H6: 13 | I6: Not disclosed | J6: 2 | K6: 0.75 | L6: =H6*K6
B7: Lannett Seymour | C7: Oral solids / liquids / controlled | D7: 17–21 Aug 2026 | E7: 4 | F7: 483 issued | G7: Procedural observations | H7: 0 | I7: Acquired business | J7: 2 | K7: 0.6 | L7: =H7*K7
B8: Auro Peptides | C8: Peptides | D8: Aug 2026 | E8: 1 | F8: 483 issued | G8: Maintenance; no data-integrity flag | H8: 0 | I8: Not disclosed | J8: 1 | K8: 0.7 | L8: =H8*K8
B9: Apitoria Unit VI | C9: API | D9: Aug 2026 | E9: 3 | F9: 483 issued | G9: Procedural observations | H9: 0 | I9: Not disclosed | J9: 2 | K9: 0.65 | L9: =H9*K9
B10: Apitoria Unit IV | C10: API | D10: Sep 2026 | E10: 0 | F10: No observations | G10: Inspection closed cleanly | H10: 0 | I10: Not disclosed | J10: 1 | K10: 0.9 | L10: =H10*K10
B11: Apitoria Unit II | C11: API | D11: Sep 2026 | E11: 1 | F11: 483 issued | G11: Procedural observation | H11: 0 | I11: Not disclosed | J11: 1 | K11: 0.75 | L11: =H11*K11
B12: Apitoria Unit V | C12: API | D12: 2025 | E12: 3 | F12: VAI / EIR closed | G12: Inspection closed | H12: 0 | I12: Not disclosed | J12: 2 | K12: 0.75 | L12: =H12*K12
B13: Eugia Unit I | C13: Sterile injectables | D13: Feb 2026 | E13: 4 | F13: OAI + Warning Letter | G13: Existing supply unchanged | H13: 11 | I13: ~2% group revenue | J13: 5 | K13: 0.15 | L13: =H13*K13
B14: Eugia Unit II | C14: Sterile injectables | D14: 2025 | E14: 9 | F14: OAI | G14: New approvals constrained | H14: 1 | I14: Not disclosed | J14: 5 | K14: 0.15 | L14: =H14*K14
B15: Eugia Unit III | C15: Sterile injectables | D15: Jan–Feb 2026 | E15: 11 | F15: OAI | G15: New approvals constrained | H15: 40 | I15: Core Eugia site | J15: 5 | K15: 0.15 | L15: =H15*K15
B18: PORTFOLIO-LEVEL READ-THROUGH
B19: Non-Eugia sites tracked | C19: 7 | D19: The recent data set spans respiratory/oral/API/peptide sites.
B20: Non-Eugia sites at OAI | C20: 0 | D20: Seymour classification still pending; observations described as procedural.
B21: Eugia sites at OAI | C21: 3 | D21: Sterile bottleneck remains real.
B22: Eugia ANDAs under review | C22: 52 | D22: 11 + 1 + 40 based on Q1 presentation.
B23: Risk-adjusted Eugia approvals | C23: 7.8 | D23: 52 × 15% release probability; analyst probability.
B24: Conclusion | C24: LESS BUMPY, NOT CLEAR | D24: The probability of an enterprise-wide quality shock has fallen; the cost is now concentrated in sterile launch timing.

Sheet 04_Resp_Eugia
A1: RESPIRATORY | LAUNCH EBITDA COVERS THE EUGIA DELAY
A2: The model uses disclosed TAMs only for approved products and conservative market shares.
B4: PRODUCT BUILD (US$m)
B5: Product | C5: Status | D5: Disclosed TAM | E5: Accessible TAM | F5: Launch / risk | G5: FY27E | H5: FY28E | I5: FY29E | J5: FY30E | K5: FY31E | L5: Source / basis
B6: Generic Advair Diskus | C6: Launched 31 Aug 2026 | D6: 908 | E6: 0.7 | F6: 2 of 3 strengths; multi-player | G6: 10 | H6: 30 | I6: 42 | J6: 48 | K6: 50 | L6: S14
B7: Beclomethasone / QVAR | C7: Approved 15 Sep 2026 | D7: 301 | E7: 0.35 | F7: Legacy device; RediHaler is distinct | G7: 0 | H7: 12 | I7: 20 | J7: 24 | K7: 27 | L7: S13
B8: Spiriva generic | C8: In development | D8: 1000 | E8: 0.5 | F8: Analyst TAM proxy; launch FY29E | G8: 0 | H8: 0 | I8: 16 | J8: 30 | K8: 38 | L8: S4 + analyst
B9: Flovent generic | C9: In development | D9: 500 | E9: 0.5 | F9: Analyst TAM proxy; launch FY30E | G9: 0 | H9: 0 | I9: 0 | J9: 10 | K9: 15 | L9: S4 + analyst
B10: Other inhalation | C10: Pipeline | D10: 0 | E10: 0 | F10: No value before FY31E | G10: 0 | H10: 0 | I10: 0 | J10: 0 | K10: 2 | L10: Analyst
B11: Respiratory revenue | G11: =SUM(G6:G10) | H11: =SUM(H6:H10) | I11: =SUM(I6:I10) | J11: =SUM(J6:J10) | K11: =SUM(K6:K10)
B14: EBITDA OFFSET VS EUGIA
C15: FY27E | D15: FY28E | E15: FY29E | F15: FY30E | G15: FY31E
B16: Respiratory revenue (US$m) | C16: 10 | D16: 42 | E16: 78 | F16: 112 | G16: 132
B17: Respiratory EBITDA margin | C17: 0.2 | D17: 0.28 | E17: 0.31 | F17: 0.33 | G17: 0.34
B18: Respiratory EBITDA (US$m) | C18: =C16*C17 | D18: =D16*D17 | E18: =E16*E17 | F18: =F16*F17 | G18: =G16*G17
B19: Eugia EBITDA drag vs unconstrained case (US$m) | C19: 15 | D19: 22 | E19: 20 | F19: 12 | G19: 0
B20: Offset ratio | C20: =IFERROR(C18/C19,999%) | D20: =IFERROR(D18/D19,999%) | E20: =IFERROR(E18/E19,999%) | F20: =IFERROR(F18/F19,999%) | G20: =IFERROR(G18/G19,999%)
B21: Net respiratory less Eugia drag (US$m) | C21: =C18-C19 | D21: =D18-D19 | E21: =E18-E19 | F21: =F18-F19 | G21: =G18-G19
B24: Read-through | C24: Advair contributes first, while QVAR proves Raleigh's MDI platform can clear FDA review. The revenue case gives no credit to undisclosed products before FY31E. Respiratory EBITDA exceeds the estimated sterile approval drag in FY29E; that is the point at which the US mix starts improving even if Eugia remediation is incomplete.
B28: DEVICE / RLD CAVEATS
B29: QVAR addressability | C29: Approved beclomethasone aerosol is not the same device as QVAR RediHaler. Base case applies 35% accessibility to the disclosed US$301m combined market.
B30: Cipla in-silico read-through | C30: A model-informed filing route can reduce clinical burden, but it does not establish device substitutability or Aurobindo approval timing for a new RLD case.
B31: Manufacturing architecture | C31: Manager workplan indicates outsourced device components with fill-finish/assembly at Raleigh. Public company material confirms Raleigh manufacturing only; the sourcing split is treated as manager input.

Sheet 05_PenG
A1: PEN-G | VALUE COMES FROM THREE SEPARATE POOLS
A2: External sales, captive savings and PLI are shown separately to avoid double counting.
B4: VOLUME, MIX AND ECONOMICS
C5: FY27E | D5: FY28E | E5: FY29E | F5: FY30E | G5: FY31E
B6: Installed capacity (MT) | C6: 15000 | D6: 15000 | E6: 15000 | F6: 15000 | G6: 15000
B7: Production (MT) | C7: 10000 | D7: 12000 | E7: 13500 | F7: 14500 | G7: 15000
B8: Utilization | C8: =C7/C6 | D8: =D7/D6 | E8: =E7/E6 | F8: =F7/F6 | G8: =G7/G6
B9: Captive conversion share | C9: 0.6 | D9: 0.5 | E9: 0.45 | F9: 0.45 | G9: 0.43
B10: Domestic third-party share | C10: 0.25 | D10: 0.3 | E10: 0.3 | F10: 0.3 | G10: 0.32
B11: Export share | C11: 0.15 | D11: 0.2 | E11: 0.25 | F11: 0.25 | G11: 0.25
B12: Mix check | C12: =SUM(C9:C11) | D12: =SUM(D9:D11) | E12: =SUM(E9:E11) | F12: =SUM(F9:F11) | G12: =SUM(G9:G11)
B13: Domestic realization (₹/kg) | C13: 2216 | D13: 2216 | E13: 2216 | F13: 2216 | G13: 2216
B14: Export realization (₹/kg) | C14: 1850 | D14: 1850 | E14: 1850 | F14: 1850 | G14: 1850
B15: External revenue (₹cr) | C15: =C7*(C10*C13+C11*C14)*1000/10000000 | D15: =D7*(D10*D13+D11*D14)*1000/10000000 | E15: =E7*(E10*E13+E11*E14)*1000/10000000 | F15: =F7*(F10*F13+F11*F14)*1000/10000000 | G15: =G7*(G10*G13+G11*G14)*1000/10000000
B16: External operating EBITDA margin | C16: 0.05 | D16: 0.11 | E16: 0.15 | F16: 0.17 | G16: 0.18
B17: External operating EBITDA (₹cr) | C17: =C15*C16 | D17: =D15*D16 | E17: =E15*E16 | F17: =F15*F16 | G17: =G15*G16
B18: Captive savings (₹/kg) | C18: 300 | D18: 325 | E18: 350 | F18: 375 | G18: 400
B19: Captive savings (₹cr) | C19: =C7*C9*C18*1000/10000000 | D19: =D7*D9*D18*1000/10000000 | E19: =E7*E9*E18*1000/10000000 | F19: =F7*F9*F18*1000/10000000 | G19: =G7*G9*G18*1000/10000000
B20: PLI rate | C20: 0.2 | D20: 0.15 | E20: 0.05 | F20: 0 | G20: 0
B21: PLI eligible realization (₹/kg) | C21: 1200 | D21: 1200 | E21: 1200 | F21: 1200 | G21: 1200
B22: PLI income (₹cr) | C22: =C7*C21*1000/10000000*C20 | D22: =D7*D21*1000/10000000*D20 | E22: =E7*E21*1000/10000000*E20 | F22: =F7*F21*1000/10000000*F20 | G22: =G7*G21*1000/10000000*G20
B23: Total EBITDA incl. PLI (₹cr) | C23: =C17+C19+C22 | D23: =D17+D19+D22 | E23: =E17+E19+E22 | F23: =F17+F19+F22 | G23: =G17+G19+G22
B24: Total EBITDA ex. PLI (₹cr) | C24: =C17+C19 | D24: =D17+D19 | E24: =E17+E19 | F24: =F17+F19 | G24: =G17+G19
B25: EBITDA ROIC incl. PLI | C25: =C23/2270.05 | D25: =D23/2270.05 | E25: =E23/2270.05 | F25: =F23/2270.05 | G25: =G23/2270.05
B26: EBITDA ROIC ex. PLI | C26: =C24/2270.05 | D26: =D24/2270.05 | E26: =E24/2270.05 | F26: =F24/2270.05 | G26: =G24/2270.05
B29: PRICE FLOOR AND VERTICAL-INTEGRATION MAP
B30: Stage | C30: Policy / price | D30: Aurobindo use | E30: Value mechanism | F30: Base-case treatment | G30: Source
B31: Penicillin G | C31: MIP ₹2,216/kg | D31: External + captive | E31: Domestic price floor / fermentation yield | F31: External revenue plus captive savings | G31: S16
B32: 6-APA | C32: MIP ₹3,405/kg | D32: Captive conversion + export | E32: Intermediate spread and import substitution | F32: Included through ₹/kg captive saving | G32: S16/S4
B33: Amoxicillin trihydrate | C33: MIP ₹2,733/kg | D33: API / formulations | E33: Downstream margin and supply security | F33: No separate revenue credit | G33: S16
B34: Finished dosage | C34: Market price | D34: Captive formulations | E34: Lower input volatility | F34: Embedded in core margins | G34: Analyst
B37: SENSITIVITY | FY30E EBITDA EX-PLI (₹cr)
B38: Savings / export price | C38: 1650 | D38: 1850 | E38: 2050
B39: 325 | C39: 477.61695 | D39: 489.94195 | E39: 502.26695
B40: 375 | C40: 510.24195 | D40: 522.56695 | E40: 534.89195
B41: 425 | C41: 542.86695 | D41: 555.19195 | E41: 567.51695

Sheet 06_Biosimilars
A1: BIOSIMILARS | SECOND WAVE, BUT FIXED-COST ABSORPTION MATTERS
A2: Late entry caps share; existing EU infrastructure and completed trials support margin conversion.
B4: MOLECULE-BY-MOLECULE REVENUE BUILD (US$m)
B5: Product | C5: Molecule | D5: Status | E5: Route to market | F5: Base launch | G5: Probability | H5: FY27E | I5: FY28E | J5: FY29E | K5: FY30E | L5: FY31E | M5: Evidence | N5: Key risk
B6: Bevqolva | C6: Bevacizumab | D6: Launched | E6: Auro / partners | F6: FY27 | G6: 1 | H6: 9 | I6: 16 | J6: 22 | K6: 28 | L6: 32 | M6: UK/EU/Mexico | N6: Price and tender share
B7: Zefylti | C7: Filgrastim | D7: Launched | E7: Auro / Orion / STADA | F7: FY27 | G7: 1 | H7: 8 | I7: 14 | J7: 20 | K7: 24 | L7: 27 | M7: UK/EU/Mexico | N7: Tender timing
B8: Dyrupeg | C8: Pegfilgrastim | D8: Launched | E8: Auro / partners | F8: FY27 | G8: 1 | H8: 7 | I8: 13 | J8: 18 | K8: 22 | L8: 25 | M8: UK/EU/Mexico | N8: Mature category
B9: Dazublys | C9: Trastuzumab | D9: Launched | E9: Auro / partners | F9: FY27 | G9: 1 | H9: 6 | I9: 12 | J9: 20 | K9: 26 | L9: 30 | M9: UK/EU | N9: Oncology tender access
B10: Denosumab pair | C10: Denosumab | D10: Filed EMA | E10: Auro / partners | F10: FY28/29 | G10: 0.8 | H10: 0 | I10: 10 | J10: 30 | K10: 55 | L10: 70 | M10: EMA review; US filing planned | N10: Crowded second wave
B11: Omazijev | C11: Omalizumab | D11: Phase 3 successful | E11: Auro / partners | F11: FY29 | G11: 0.75 | H11: 0 | I11: 5 | J11: 25 | K11: 40 | L11: 55 | M11: EMA filing targeted | N11: Filing/approval lag
B12: BP08 | C12: Tocilizumab | D12: Pivotal complete | E12: Partners | F12: FY29/30 | G12: 0.65 | H12: 0 | I12: 0 | J12: 10 | K12: 25 | L12: 35 | M12: Filing 2027 | N12: Tender competition
B13: BP05 | C13: Ranibizumab | D13: Phase 3 near complete | E13: Partners | F13: FY30 | G13: 0.6 | H13: 0 | I13: 0 | J13: 8 | K13: 20 | L13: 28 | M13: Pipeline disclosure | N13: Ophthalmic competition
B14: Other / next wave | C14: Multiple | D14: Preclinical / early | E14: TBD | F14: FY31+ | G14: 0.35 | H14: 5 | I14: 10 | J14: 7 | K14: 20 | L14: 48 | M14: No molecule-specific credit | N14: Execution
B15: Total revenue | H15: =SUM(H6:H14) | I15: =SUM(I6:I14) | J15: =SUM(J6:J14) | K15: =SUM(K6:K14) | L15: =SUM(L6:L14)
B18: MARGIN CONVERSION
C19: FY27E | D19: FY28E | E19: FY29E | F19: FY30E | G19: FY31E
B20: Revenue (US$m) | C20: 35 | D20: 80 | E20: 160 | F20: 260 | G20: 350
B21: Gross margin | C21: 0.62 | D21: 0.63 | E21: 0.64 | F21: 0.65 | G21: 0.65
B22: Commercial / partner fees | C22: 0.35 | D22: 0.31 | E22: 0.27 | F22: 0.24 | G22: 0.22
B23: R&D / fixed overhead | C23: 0.47 | D23: 0.27 | E23: 0.19 | F23: 0.15 | G23: 0.13
B24: EBITDA margin | C24: =C21-C22-C23 | D24: =D21-D22-D23 | E24: =E21-E22-E23 | F24: =F21-F22-F23 | G24: =G21-G22-G23
B25: EBITDA (US$m) | C25: =C20*C24 | D25: =D20*D24 | E25: =E20*E24 | F25: =F20*F24 | G25: =G20*G24
B26: EBITDA (₹cr) | C26: =C25*'08_Financials'!D5/10 | D26: =D25*'08_Financials'!E5/10 | E26: =E25*'08_Financials'!F5/10 | F26: =F25*'08_Financials'!G5/10 | G26: =G25*'08_Financials'!H5/10
B27: Clinical/R&D spend (₹cr) | C27: 525 | D27: 450 | E27: 420 | F27: 400 | G27: 420
B30: Why second-wave can still work | C30: The model does not assume premium share. It assumes tenders convert over two to three quarters, partner fees remain high and US entries are late. The return improves because four launched products and the next four programs share development, manufacturing and commercial infrastructure. FDA data show a crowded denosumab field [S18], so the investment case depends on cost absorption rather than first-mover pricing.

Sheet 07_Dermatology
A1: US DERMATOLOGY | TWO PRODUCTS AMORTIZE THE FIELD PLATFORM
A2: ADQUEY is disclosed. Product two is kept as an unnamed hurdle case until the company identifies it.
B4: PROFITABILITY BUILD (US$m)
C5: FY27E | D5: FY28E | E5: FY29E | F5: FY30E | G5: FY31E
B6: ADQUEY net sales | C6: 8 | D6: 35 | E6: 60 | F6: 85 | G6: 105
B7: Pipeline product 2 sales | C7: 0 | D7: 0 | E7: 15 | F7: 40 | G7: 65
B8: Total dermatology sales | C8: =SUM(C6:C7) | D8: =SUM(D6:D7) | E8: =SUM(E6:E7) | F8: =SUM(F6:F7) | G8: =SUM(G6:G7)
B9: Contribution margin after COGS/royalty/rebates | C9: 0.58 | D9: 0.58 | E9: 0.58 | F9: 0.58 | G9: 0.58
B10: Contribution profit | C10: =C8*C9 | D10: =D8*D9 | E10: =E8*E9 | F10: =F8*F9 | G10: =G8*G9
B11: Fixed commercial / medical cost | C11: 25 | D11: 31 | E11: 38 | F11: 42 | G11: 46
B12: EBITDA | C12: =C10-C11 | D12: =D10-D11 | E12: =E10-E11 | F12: =F10-F11 | G12: =G10-G11
B13: Break-even revenue | C13: =C11/C9 | D13: =D11/D9 | E13: =E11/E9 | F13: =F11/F9 | G13: =G11/G9
B14: Product 2 sales required for break-even | C14: =MAX(0,C13-C6) | D14: =MAX(0,D13-D6) | E14: =MAX(0,E13-E6) | F14: =MAX(0,F13-F6) | G14: =MAX(0,G13-G6)
B15: EBITDA margin | C15: =IFERROR(C12/C8,0) | D15: =IFERROR(D12/D8,0) | E15: =IFERROR(E12/E8,0) | F15: =IFERROR(F12/F8,0) | G15: =IFERROR(G12/G8,0)
B19: DISCLOSURE STATUS AND INVESTMENT TEST
B20: Launched product | C20: ADQUEY (difamilast 1% ointment) | D20: Publicly verified [S19/S20]
B21: Indication | C21: Mild-to-moderate atopic dermatitis, age 2+ | D21: Publicly verified
B22: Addressable market | C22: $1.3bn MAT July 2026 | D22: Company / IQVIA disclosure
B23: Second product | C23: UNDISCLOSED | D23: Do not name or assign molecule without company confirmation
B24: FY29 break-even hurdle | C24: US$5.5m second-product sales | D24: Formula: fixed cost / contribution margin - ADQUEY sales
B25: FY29 no-product-2 EBITDA | C25: US$-3.2m | D25: Shows the downside is bounded if ADQUEY reaches US$60m

Sheet 08_Financials
A1: CONSOLIDATED FINANCIALS | THE REVISION ARRIVES AFTER FY27
A2: Catalyst revenue is separated from core segments to prevent double counting.
C4: FY26A | D4: FY27E | E4: FY28E | F4: FY29E | G4: FY30E | H4: FY31E
B5: INR/US$ | C5: 90 | D5: 94.5 | E5: 95.5 | F5: 96.5 | G5: 97.5 | H5: 98.5
B7: REVENUE BY BUSINESS
B8: US core | C8: 14408 | D8: 14408 | E8: 14984.32 | F8: 15583.69 | G8: 16207.04 | H8: 16855.32
B9: Lannett | C9: 0 | D9: ='02_Lannett'!C23 | E9: ='02_Lannett'!D23 | F9: ='02_Lannett'!E23 | G9: ='02_Lannett'!F23 | H9: ='02_Lannett'!G23
B10: Respiratory | C10: 0 | D10: ='04_Resp_Eugia'!C16*D$5/10 | E10: ='04_Resp_Eugia'!D16*E$5/10 | F10: ='04_Resp_Eugia'!E16*F$5/10 | G10: ='04_Resp_Eugia'!F16*G$5/10 | H10: ='04_Resp_Eugia'!G16*H$5/10
B11: US dermatology | C11: 0 | D11: ='07_Dermatology'!C8*D$5/10 | E11: ='07_Dermatology'!D8*E$5/10 | F11: ='07_Dermatology'!E8*F$5/10 | G11: ='07_Dermatology'!F8*G$5/10 | H11: ='07_Dermatology'!G8*H$5/10
B12: Europe core | C12: 10315 | D12: 11243.35 | E12: 12142.82 | F12: 13114.25 | G12: 14032.25 | H12: 14874.18
B13: Biosimilars | C13: 0 | D13: ='06_Biosimilars'!C20*D$5/10 | E13: ='06_Biosimilars'!D20*E$5/10 | F13: ='06_Biosimilars'!E20*F$5/10 | G13: ='06_Biosimilars'!F20*G$5/10 | H13: ='06_Biosimilars'!G20*H$5/10
B14: Growth Markets | C14: 3499 | D14: 4023.85 | E14: 4506.71 | F14: 5047.51 | G14: 5552.26 | H14: 5996.44
B15: ARV | C15: 1384 | D15: 1453.2 | E15: 1511.33 | F15: 1556.67 | G15: 1603.37 | H15: 1651.47
B16: API ex-Pen-G | C16: 3850 | D16: 3965.5 | E16: 4084.47 | F16: 4207.01 | G16: 4333.22 | H16: 4463.21
B17: Pen-G external | C17: 197 | D17: ='05_PenG'!C15 | E17: ='05_PenG'!D15 | F17: ='05_PenG'!E15 | G17: ='05_PenG'!F15 | H17: ='05_PenG'!G15
B18: Revenue | C18: =SUM(C8:C17) | D18: =SUM(D8:D17) | E18: =SUM(E8:E17) | F18: =SUM(F8:F17) | G18: =SUM(G8:G17) | H18: =SUM(H8:H17)
B19: YoY growth | C19: – | D19: =D18/C18-1 | E19: =E18/D18-1 | F19: =F18/E18-1 | G19: =G18/F18-1 | H19: =H18/G18-1
B22: EBITDA BY BUSINESS
B23: US core | C23: – | D23: 3429.104 | E23: 3596.2368 | F23: 3786.8367 | G23: 3970.7248 | H23: 4129.5534
B24: Lannett | C24: – | D24: 204.12 | E24: 404.92 | F24: 559.2175 | G24: 675.675 | H24: 747.615
B25: Respiratory | C25: – | D25: 18.9 | E25: 112.308 | F25: 233.337 | G25: 360.36 | H25: 442.068
B26: US dermatology | C26: – | D26: -192.78 | E26: -102.185 | F26: 53.075 | G26: 297.375 | H26: 518.11
B27: Europe core | C27: – | D27: 2304.8868 | E27: 2549.9922 | F27: 2780.221 | G27: 3016.9338 | H27: 3197.9487
B28: Biosimilars | C28: – | D28: -66.15 | E28: 38.2 | F28: 277.92 | G28: 659.1 | H28: 1034.25
B29: Growth Markets | C29: – | D29: 764.5315 | E29: 878.80845 | F29: 1009.502 | G29: 1110.452 | H29: 1199.288
B30: ARV | C30: – | D30: 217.98 | E30: 226.6995 | F30: 233.5005 | G30: 240.5055 | H30: 247.7205
B31: API ex-Pen-G | C31: – | D31: 872.41 | E31: 898.5834 | F31: 925.5422 | G31: 953.3084 | H31: 981.9062
B32: Pen-G total | C32: – | D32: 461.575 | E32: 547.5936 | F32: 521.90325 | G32: 522.56695 | H32: 574.3374
B33: EBITDA | C33: 6856 | D33: =SUM(D23:D32) | E33: =SUM(E23:E32) | F33: =SUM(F23:F32) | G33: =SUM(G23:G32) | H33: =SUM(H23:H32)
B34: EBITDA margin | C34: =C33/C18 | D34: =D33/D18 | E34: =E33/E18 | F34: =F33/F18 | G34: =G33/G18 | H34: =H33/H18
B37: P&L AND ESTIMATE REVISION
B38: EBITDA | C38: 6856 | D38: 8014.5772 | E38: 9151.1569 | F38: 10381.055 | G38: 11807.001 | H38: 13072.797
B39: D&A | C39: 1778 | D39: 1950 | E39: 2080 | F39: 2200 | G39: 2300 | H39: 2400
B40: EBIT | C40: =C38-C39 | D40: =D38-D39 | E40: =E38-E39 | F40: =F38-F39 | G40: =G38-G39 | H40: =H38-H39
B41: Interest | C41: 384 | D41: 450 | E41: 400 | F41: 350 | G41: 300 | H41: 250
B42: Other income | C42: 404 | D42: 350 | E42: 380 | F42: 400 | G42: 420 | H42: 450
B43: PBT | C43: =C40-C41+C42 | D43: =D40-D41+D42 | E43: =E40-E41+E42 | F43: =F40-F41+F42 | G43: =G40-G41+G42 | H43: =H40-H41+H42
B44: Tax rate | C44: 0.31 | D44: 0.31 | E44: 0.3 | F44: 0.29 | G44: 0.29 | H44: 0.29
B45: PAT | C45: =C43*(1-C44) | D45: =D43*(1-D44) | E45: =E43*(1-E44) | F45: =F43*(1-F44) | G45: =G43*(1-G44) | H45: =H43*(1-H44)
B46: Shares (cr) | C46: 58.08 | D46: 58.08 | E46: 58.08 | F46: 58.08 | G46: 58.08 | H46: 58.08
...

Sheet 09_Valuation
A1: VALUATION | DCF SETS ₹2,100; MULTIPLES ARE A CROSS-CHECK
A2: Base case preserves the old-note WACC discipline and uses a lower terminal growth rate than the original initiation.
C4: FY27E | D4: FY28E | E4: FY29E | F4: FY30E | G4: FY31E | H4: FY32E | I4: FY33E | J4: FY34E | K4: FY35E | L4: FY36E
B5: Revenue | C5: ='08_Financials'!D18 | D5: ='08_Financials'!E18 | E5: ='08_Financials'!F18 | F5: ='08_Financials'!G18 | G5: ='08_Financials'!H18 | H5: =G5*(1+7.000%) | I5: =H5*(1+6.500%) | J5: =I5*(1+6.000%) | K5: =J5*(1+5.500%) | L5: =K5*(1+5.000%)
B6: EBITDA | C6: ='08_Financials'!D33 | D6: ='08_Financials'!E33 | E6: ='08_Financials'!F33 | F6: ='08_Financials'!G33 | G6: ='08_Financials'!H33 | H6: =H5*24.200% | I6: =I5*24.500% | J6: =J5*24.700% | K6: =K5*24.900% | L6: =L5*25.000%
B7: EBITDA margin | C7: =C6/C5 | D7: =D6/D5 | E7: =E6/E5 | F7: =F6/F5 | G7: =G6/G5 | H7: =H6/H5 | I7: =I6/I5 | J7: =J6/J5 | ... L7: =L6/L5
B8: D&A | C8: ='08_Financials'!D39 | D8: ='08_Financials'!E39 | E8: ='08_Financials'!F39 | F8: ='08_Financials'!G39 | G8: ='08_Financials'!H39 | H8: =H5*4.0% | I8: =I5*4.0% | J8: =J5*4.0% | K8: =K5*4.0% | L8: =L5*4.0%
B9: EBIT | C9: =C6-C8 | D9: =D6-D8 | E9: =E6-E8 | F9: =F6-F8 | G9: =G6-G8 | H9: =H6-H8 | I9: =I6-I8 | J9: =J6-J8 | ... L9: =L6-L8
B10: Cash tax rate | C10: 0.28 | D10: 0.28 | E10: 0.28 | F10: 0.28 | G10: 0.28 | H10: 0.28 | I10: 0.28 | J10: 0.28 | K10: 0.28 | L10: 0.28
B11: NOPAT | C11: =C9*(1-C10) | D11: =D9*(1-D10) | E11: =E9*(1-E10) | F11: =F9*(1-F10) | G11: =G9*(1-G10) | H11: =H9*(1-H10) | I11: =I9*(1-I10) | J11: =J9*(1-J10) | ... L11: =L9*(1-L10)
B12: Capex | C12: 3300 | D12: 2850 | E12: 2450 | F12: 2250 | G12: 2100 | H12: =H5*3.5% | I12: =I5*3.5% | J12: =J5*3.5% | K12: =K5*3.5% | L12: =L5*3.5%
B13: Change in NWC | C13: =(C5-'08_Financials'!C18)*4.5% | D13: =(D5-C5)*4.5% | E13: =(E5-D5)*4.5% | F13: =(F5-E5)*4.5% | G13: =(G5-F5)*4.5% | H13: =(H5-G5)*4.5% | I13: =(I5-H5)*4.5% | J13: =(J5-I5)*4.5% | K13: =(K5-J5)*4.5% | L13: =(L5-K5)*4.5%
B14: FCFF | C14: =C11+C8-C12-C13 | D14: =D11+D8-D12-D13 | E14: =E11+E8-E12-E13 | F14: =F11+F8-F12-F13 | G14: =G11+G8-G12-G13 | H14: =H11+H8-H12-H13 | I14: =I11+I8-I12-I13 | J14: =J11+J8-J12-J13 | ... L14: =L11+L8-L12-L13
B15: Discount period | C15: 0.5 | D15: 1.5 | E15: 2.5 | F15: 3.5 | G15: 4.5 | H15: 5.5 | I15: 6.5 | J15: 7.5 | K15: 8.5 | L15: 9.5
B16: PV of FCFF | C16: =C14/(1+$C$20)^C15 | D16: =D14/(1+$C$20)^D15 | E16: =E14/(1+$C$20)^E15 | F16: =F14/(1+$C$20)^F15 | G16: =G14/(1+$C$20)^G15 | H16: =H14/(1+$C$20)^H15 | I16: =I14/(1+$C$20)^I15 | J16: =J14/(1+$C$20)^J15 | ... L16: =L14/(1+$C$20)^L15
B19: DCF OUTPUT
B20: WACC | C20: 0.105 | D20: Original initiation used 10.5% [S1]
B21: Terminal growth | C21: 0.045 | D21: Below original 5.0% [S1]
B22: PV of explicit FCFF | C22: =SUM(C16:L16) | D22: FY27E–FY36E
B23: PV of terminal value | C23: =L14*(1+$C$21)/($C$20-$C$21)/(1+$C$20)^L15 | D23: Gordon growth
B24: Enterprise value | C24: =C22+C23 | D24: Sum
B25: Net cash (30 Jun 2026) | C25: 397 | D25: Company Q1 disclosure
B26: Equity value | C26: =C24+C25 | D26: EV + net cash
B27: Diluted shares (cr) | C27: 58.08 | D27: Model
B28: DCF fair value / share | C28: =C26/C27 | D28: Unrounded
B29: Target price | C29: =ROUND(C28/50,0)*50 | D29: Rounded to nearest ₹50
B30: Current price | C30: 1686 | D30: 6 Oct 2026
B31: Upside | C31: =C29/C30-1 | D31: Ex-dividend
B32: Rating | C32: =IF(C31>15%,"OUTPERFORM","MARKET-PERFORM") | D32: >15% expected return hurdle
B35: DCF SENSITIVITY | FAIR VALUE / SHARE
B36: WACC / TGR | C36: 0.035 | D36: 0.04 | E36: 0.045 | F36: 0.05 | G36: 0.055
B37: 0.095 | C37: 2234.9524 | D37: 2372.7454 | E37: 2538.097 | F37: 2740.1933 | G37: 2992.8138
B38: 0.1 | C38: 2049.5634 | D38: 2161.7287 | E38: 2294.2878 | F38: 2453.3586 | G38: 2647.7784
B39: 0.105 | C39: 1891.0039 | D39: 1983.51 | E39: 2091.4337 | F39: 2218.98 | G39: 2372.0355
B40: 0.11 | C40: 1753.8975 | D40: 1831.0511 | E40: 1920.0745 | F40: 2023.9352 | G40: 2146.6796
B41: 0.115 | C41: 1634.2123 | D41: 1699.1913 | E41: 1773.4531 | F41: 1859.1398 | G41: 1959.1075
B44: VALUATION COMPS | TTM SNAPSHOT
B45: Company | C45: Price (₹) | D45: TTM P/E | E45: Premium/(discount) to Auro | F45: Comment | G45: Source
B46: Aurobindo | C46: 1686 | D46: 26.34 | E46: 0 | F46: Current multiple before estimate conversion | G46: S22
B47: Sun Pharma | C47: 1795 | D47: 35.59 | E47: 0.35117692 | F47: Specialty-heavy; upper bound | G47: S22
...

Sheet 10_Sources
A1: SOURCE LOG AND ASSUMPTION REGISTER
A2: Primary company, FDA/FTC and Government of India sources are preferred. Analyst estimates are labelled.
B4: ID | C4: Source | D4: Used for | E4: URL / file | F4: Date | G4: Type
B5: S1 | C5: Uploaded sector initiation note | D5: Original Market-Perform rating, ₹1,498 target, old forecasts and objections | E5: Local upload: India Healthcare_ Innovation Power Decade...pdf | F5: 30 Aug 2026 | G5: Fact
B6: S2 | C6: Aurobindo Q4/FY26 press release | D6: FY26 revenue, EBITDA, PAT and geography/API revenue | E6: https://www.aurobindo.com/api/uploads/resultsannouncement/APL_PressRelease_Q4FY26.pdf | F6: 21 May 2026 | G6: Fact
B7: S3 | C7: Aurobindo Q1FY27 earnings presentation | D7: Q1 financials, filings, biosimilar pipeline and country launches | E7: https://www.aurobindo.com/api/uploads/resultsannouncement/APL_EarningsPresentation_Q1FY27.pdf | F7: 5 Aug 2026 | G7: Fact
B8: S4 | C8: Aurobindo Q1FY27 earnings call transcript | D8: Lannett run-rate/utilization/synergies; Pen-G run-rate and demand; biosimilar filings; Eugia guidance | E8: https://www.aurobindo.com/api/uploads/conferencecalltranscripts/APL_ECT_Q1FY27_Final.pdf | F8: Aug 2026 | G8: Fact
B9: S5 | C9: Lannett transaction summary | D9: $250m price, $306m FY25 sales, 3.6bn dose capacity, 1.4bn output and FY25 business mix | E9: https://www.aurobindo.com/api/uploads/disclosureofeventsinformation/LtrToSEsLannett30072025.pdf | F9: 30 Jul 2025 | G9: Fact
B10: S6 | C10: Lannett FTC approval press release | D10: Acquisition terms, approximately 4bn dose capacity and strategic rationale | E10: https://www.aurobindo.com/api/uploads/corporateannouncements/LtrToSEsLnnettPR22062026.pdf | F10: 22 Jun 2026 | G10: Fact
B11: S7 | C11: FTC Aurobindo-Lannett case | D11: Four product divestitures and divested product identities | E11: https://www.ftc.gov/legal-library/browse/cases-proceedings/251-0096-aurobindo-lannett-matter | F11: 18 Jun 2026 | G11: Fact
B12: S8 | C12: Lannett Seymour FDA inspection disclosure | D12: Four procedural observations in August 2026 inspection | E12: https://www.aurobindo.com/api/uploads/disclosureofeventsinformation/LtrToSEsLannettUSFDA24082026.pdf | F12: 24 Aug 2026 | G12: Fact
B13: S9 | C13: Raleigh VAI/EIR disclosure | D13: VAI classification, inspection closed; pending inhaler/derma applications can progress | E13: https://www.aurobindo.com/api/uploads/disclosureofeventsinformation/LtrToSEsAurolifeNCVAI17082026.pdf | F13: 17 Aug 2026 | G13: Fact
B14: S10 | C14: Eugia Unit I warning letter disclosure | D14: OAI/Warning Letter; current supply unchanged; approximately 2% of group revenue | E14: https://www.aurobindo.com/api/uploads/disclosureofeventsinformation/LtrToSEsEugiaUnitIWarningLetter14082026.pdf | F14: 14 Aug 2026 | G14: Fact
B15: S11 | C15: Eugia Unit III OAI disclosure | D15: 11 observations and OAI classification | E15: https://www.aurobindo.com/api/uploads/disclosureofeventsinformation/LtrToSEsEuigaUnit3USFDAinspection12062026.pdf | F15: 12 Jun 2026 | G15: Fact
... B26: S22 | C26: Google Finance peer pages | D26: 6 October 2026 market prices and TTM P/E for Indian pharma peer context | E26: https://www.google.com/finance/quote/AUROPHARMA:NSE | F26: 6 Oct 2026 | G26: Market snapshot
B29: KEY ANALYST ASSUMPTIONS
B30: Lannett | C30: Utilization path 40% → 70%; site-transfer route, timing and probabilities | D30: No product-specific transfer schedule is disclosed.
B31: Respiratory | C31: Market shares and revenue ramps; Spiriva/Flovent TAM proxies | D31: Only Advair and QVAR TAMs are company-disclosed.
B32: Pen-G | C32: Export realization ₹1,850/kg; captive saving ₹300–400/kg | D32: MIP applies domestically; export economics must stand alone.
B33: Biosimilars | C33: Molecule sales curves and partner economics | D33: Pipeline/status is disclosed; revenue and margin forecasts are analyst estimates.
B34: Dermatology | C34: Unnamed product-two FY29 launch and US$15m first-year sales | D34: Public sources name ADQUEY only. Product-two identity must be confirmed.
B35: DCF | C35: 28% cash tax, 4.5% of incremental sales working capital, 10.5% WACC, 4.5% TGR | D35: WACC continuity with original note; TGR reduced by 50bp.

Sheet 11_QC
A1: MODEL QUALITY CONTROL
A2: All checks should show PASS. Formula outputs recalculate when opened in Excel.
B4: Check | C4: Value | D4: Status | E4: Interpretation
B5: FY26 segment revenue matches reported total | C5: ='08_Financials'!C18 | D5: =IF(ABS(C5-33653)<1,"PASS","FAIL") | E5: Reported FY26 revenue ₹33,653cr [S2]
B6: FY26 EBITDA matches reported total | C6: ='08_Financials'!C33 | D6: =IF(ABS(C6-6856)<1,"PASS","FAIL") | E6: Reported FY26 EBITDA ₹6,856cr [S2]
B7: Lannett revenue linkage FY28 | C7: ='08_Financials'!E9-'02_Lannett'!D23 | D7: =IF(ABS(C7)<0.1,"PASS","FAIL") | E7: Cross-sheet linkage
B8: Pen-G mix FY29 | C8: ='05_PenG'!E12 | D8: =IF(ABS(C8-1)<0.0001,"PASS","FAIL") | E8: Captive + domestic + export = 100%
B9: Biosimilar product sales sum FY30 | C9: ='06_Biosimilars'!K15-'06_Biosimilars'!F20 | D9: =IF(ABS(C9)<0.1,"PASS","FAIL") | E9: Product build equals segment revenue
B10: Dermatology product sales sum FY29 | C10: ='07_Dermatology'!E8-'08_Financials'!F11*10/'08_Financials'!F5 | D10: =IF(ABS(C10)<0.1,"PASS","FAIL") | E10: US$ build equals INR segment revenue
B11: Target price > current price | C11: =2100-1686.0 | D11: =IF(C11>0,"PASS","FAIL") | E11: Required for Outperform
B12: Upside above 15% hurdle | C12: =2100/1686.0-1 | D12: =IF(C12>15%,"PASS","FAIL") | E12: House rating test
B13: No PLI after FY29 | C13: ='05_PenG'!F22+'05_PenG'!G22 | D13: =IF(ABS(C13)<0.1,"PASS","FAIL") | E13: Prevents subsidy from supporting terminal economics
B14: FY29 respiratory covers Eugia drag | C14: ='04_Resp_Eugia'!E21 | D14: =IF(C14>0,"PASS","FAIL") | E14: Net EBITDA positive
B17: KNOWN DATA GAPS
B18: US dermatology product 2 | C18: Identity, approval status and launch date are not public. Model is a hurdle case.
B19: Lannett site transfers | C19: Product names and CBE-30/PAS classifications are not disclosed. Route matrix is illustrative.
B20: Pen-G export pricing | C20: No public realized export price. Base uses ₹1,850/kg and sensitivity.
B21: Facility-level revenue | C21: Except Eugia Unit I (~2% of group), site revenue exposure is not disclosed.
