Workbook

Sheet Summary
A1: SAI LIFE SCIENCES LIMITED | Integrated Three-Statement Model | FY2024A - FY2035E
A2: All figures in INR million unless stated (Rs 1 crore = Rs 10 million). Fiscal year ends 31 March. FY2024A-FY2026A = reported consolidated Ind AS. FY2027E-FY2035E = analyst estimates. Single base case. BLUE = hardcoded input BLACK = formula GREEN = cross-sheet link.
A5: QUARTERLY UPDATE CHECKLIST (everything below lives on the Revenue_Model sheet in blue cells)
A6: 1. Segment revenue. Roll reported CRO and CDMO revenue in section A forward one year. Both come straight off page 21 and page 24 of the quarterly investor deck.
A7: 2. DRIVERS 1 and 2 - CRO. Net billable FTE additions, and revenue per FTE growth. Then glance at the implied USD rate per FTE underneath; if it leaves the USD 55-90k band, one of the two is wrong.
A8: 3. DRIVERS 3 and 4 - commercial CDMO. Net new commercial molecules (the deck gives the count directly), and growth in revenue per commercial molecule. Remember driver 4 embeds the dilution from newly qualified molecules, which earn far less in year one than the portfolio average.
A9: 4. DRIVER 5 - development CDMO. A single growth rate covering pre-clinical through Phase III, validation, process R&D and tech transfer. Sanity-check it against the disclosed programme counts in section F.
A10: 5. DRIVER 6 - capacity. KL commissioned in the year. Then check the revenue-per-effective-KL flag; if it reads REVIEW, the model is forecasting output the plant cannot make.
A11: 6. Costs and capex sit on the Schedules sheet. Update the capex plan, the CDMO material ratio, wage growth and headcount additions from the call. Everything else flows.
A12: 7. Finish on the Sources_Checks sheet. The master check must read ALL CHECKS OK before you circulate anything.
A15: KEY FINANCIAL SUMMARY
B16: INR mn | C16: FY2024A | D16: FY2025A | E16: FY2026A | F16: FY2027E | G16: FY2028E | H16: FY2029E | I16: FY2030E | J16: FY2031E | K16: FY2032E | L16: FY2033E | M16: FY2034E | N16: FY2035E | P16: Source / basis
A17: Revenue from operations | B17: INR mn | C17: =Statements!C6 -> 14651.78 | D17: =Statements!D6 -> 16945.7 | E17: =Statements!E6 -> 21924.92 | F17: =Statements!F6 -> 25155.942 | G17: =Statements!G6 -> 28557.44 | H17: =Statements!H6 -> 32501.745 | I17: =Statements!I6 -> 36659.531 | J17: =Statements!J6 -> 41035.764 | ... N17: =Statements!N6 -> 62332.848
A18: Revenue growth (%) | B18: % | D18: =D17/C17-1 -> 0.15656255 | E18: =E17/D17-1 -> 0.29383383 | F18: =F17/E17-1 -> 0.14736755 | G18: =G17/F17-1 -> 0.13521648 | H18: =H17/G17-1 -> 0.13811832 | I18: =I17/H17-1 -> 0.12792501 | J18: =J17/I17-1 -> 0.11937505 | K18: =K17/J17-1 -> 0.121102 | ... N18: =N17/M17-1 -> 0.099548835
A19: CRO / Discovery revenue | B19: INR mn | C19: =Revenue_Model!C17 -> 4970 | D19: =Revenue_Model!D17 -> 6260 | E19: =Revenue_Model!E17 -> 7750 | F19: =Revenue_Model!F17 -> 8900.6064 | G19: =Revenue_Model!G17 -> 10058.487 | H19: =Revenue_Model!H17 -> 11261.4 | I19: =Revenue_Model!I17 -> 12449.618 | J19: =Revenue_Model!J17 -> 13635.75 | ... N19: =Revenue_Model!N17 -> 18008.098
A20: CDMO / CMC revenue | B20: INR mn | C20: =Revenue_Model!C39 -> 9680 | D20: =Revenue_Model!D39 -> 10680 | E20: =Revenue_Model!E39 -> 14170 | F20: =Revenue_Model!F39 -> 16255.335 | G20: =Revenue_Model!G39 -> 18498.952 | H20: =Revenue_Model!H39 -> 21240.345 | I20: =Revenue_Model!I39 -> 24209.913 | J20: =Revenue_Model!J39 -> 27400.015 | ... N20: =Revenue_Model!N39 -> 44324.749
A21: CRO mix (%) | B21: % | C21: =C19/C17 -> 0.33920793 | D21: =D19/D17 -> 0.36941525 | E21: =E19/E17 -> 0.35347905 | F21: =F19/F17 -> 0.35381726 | G21: =G19/G17 -> 0.3522195 | H21: =H19/H17 -> 0.34648601 | I21: =I19/I17 -> 0.33960112 | J21: =J19/J17 -> 0.3322894 | ... N21: =N19/N17 -> 0.28890223
A22: CDMO mix (%) | B22: % | C22: =C20/C17 -> 0.66067058 | D22: =D20/D17 -> 0.63024838 | E22: =E20/E17 -> 0.64629654 | F22: =F20/F17 -> 0.64618274 | G22: =G20/G17 -> 0.6477805 | H22: =H20/H17 -> 0.65351399 | I22: =I20/I17 -> 0.66039888 | J22: =J20/J17 -> 0.6677106 | ... N22: =N20/N17 -> 0.71109777
A23: Material margin (%) | B23: % | C23: =Statements!C9 -> 0.6957844 | D23: =Statements!D9 -> 0.72514325 | E23: =Statements!E9 -> 0.73961501 | F23: =Statements!F9 -> 0.73260701 | G23: =Statements!G9 -> 0.73538256 | H23: =Statements!H9 -> 0.73701608 | I23: =Statements!I9 -> 0.73640911 | J23: =Statements!J9 -> 0.73571187 | ... N23: =Statements!N9 -> 0.72658141
A24: EBITDA | B24: INR mn | C24: =Statements!C13 -> 3001.15 | D24: =Statements!D13 -> 4247.37 | E24: =Statements!E13 -> 6611.77 | F24: =Statements!F13 -> 6733.4559 | G24: =Statements!G13 -> 7497.83 | H24: =Statements!H13 -> 8572.4128 | I24: =Statements!I13 -> 9686.0861 | J24: =Statements!J13 -> 10861.099 | ... N24: =Statements!N13 -> 16921.48
A25: EBITDA margin (%) | B25: % | C25: =Statements!C14 -> 0.20483177 | D25: =Statements!D14 -> 0.25064589 | E25: =Statements!E14 -> 0.30156416 | F25: =Statements!F14 -> 0.26766861 | G25: =Statements!G14 -> 0.2625526 | H25: =Statements!H14 -> 0.26375239 | I25: =Statements!I14 -> 0.2642174 | J25: =Statements!J14 -> 0.26467398 | ... N25: =Statements!N14 -> 0.27146971
A26: EBIT | B26: INR mn | C26: =Statements!C16 -> 1806.79 | D26: =Statements!D16 -> 2861.64 | E26: =Statements!E16 -> 4943.22 | F26: =Statements!F16 -> 4322.2061 | G26: =Statements!G16 -> 4322.3286 | H26: =Statements!H16 -> 4804.1125 | I26: =Statements!I16 -> 5515.7981 | J26: =Statements!J16 -> 6347.0032 | ... N26: =Statements!N16 -> 11195.364
A27: Profit after tax | B27: INR mn | C27: =Statements!C26 -> 828.09 | D27: =Statements!D26 -> 1701.32 | E27: =Statements!E26 -> 3489.1 | F27: =Statements!F26 -> 3060.1782 | G27: =Statements!G26 -> 2642.015 | H27: =Statements!H26 -> 2709.0214 | I27: =Statements!I26 -> 3105.3765 | J27: =Statements!J26 -> 3628.3951 | ... N27: =Statements!N26 -> 7422.383
A28: PAT margin (%) | B28: % | C28: =Statements!C27 -> 0.056518048 | D28: =Statements!D27 -> 0.10039833 | E28: =Statements!E27 -> 0.15913855 | F28: =Statements!F27 -> 0.12164832 | G28: =Statements!G27 -> 0.092515823 | H28: =Statements!H27 -> 0.083350028 | I28: =Statements!I27 -> 0.084708571 | J28: =Statements!J27 -> 0.088420314 | ... N28: =Statements!N27 -> 0.11907659
A29: Diluted EPS | B29: INR | C29: =Statements!C30 -> 4.5300328 | D29: =Statements!D30 -> 8.609919 | E29: =Statements!E30 -> 16.430119 | F29: =Statements!F30 -> 14.275882 | G29: =Statements!G30 -> 12.211199 | H29: =Statements!H30 -> 12.406216 | I29: =Statements!I30 -> 14.092287 | J29: =Statements!J30 -> 16.317661 | ... N29: =Statements!N30 -> 32.220798
A30: EPS growth (%) | B30: % | D30: =D29/C29-1 -> 0.90063061 | E30: =E29/D29-1 -> 0.90827795 | F30: =F29/E29-1 -> -0.13111507 | G30: =G29/F29-1 -> -0.14462738 | H30: =H29/G29-1 -> 0.015970351 | I30: =I29/H29-1 -> 0.13590537 | J30: =J29/I29-1 -> 0.1579143 | K30: =K29/J29-1 -> 0.21100402 | ... N30: =N29/M29-1 -> 0.17690435
A31: Capex | B31: INR mn | C31: =Schedules!C52 -> 1816.9 | D31: =Schedules!D52 -> 3692.8 | E31: =Schedules!E52 -> 5929.61 | F31: =Schedules!F52 -> 12000 | G31: =Schedules!G52 -> 8500 | H31: =Schedules!H52 -> 7000 | I31: =Schedules!I52 -> 7500 | J31: =Schedules!J52 -> 7000 | ... N31: =Schedules!N52 -> 7500
A32: Capex (% of revenue) | B32: % | C32: =Schedules!C53 -> 0.12400541 | D32: =Schedules!D53 -> 0.21791959 | E32: =Schedules!E53 -> 0.2704507 | F32: =Schedules!F53 -> 0.47702448 | G32: =Schedules!G53 -> 0.29764573 | H32: =Schedules!H53 -> 0.21537305 | I32: =Schedules!I53 -> 0.20458527 | J32: =Schedules!J53 -> 0.17058291 | ... N32: =Schedules!N53 -> 0.12032179
A33: Cash flow from operations | B33: INR mn | C33: =Statements!C80 -> 2630.87 | D33: =Statements!D80 -> 3140.45 | E33: =Statements!E80 -> 5091.33 | F33: =Statements!F80 -> 5755.271 | G33: =Statements!G80 -> 4908.9222 | H33: =Statements!H80 -> 6379.7585 | I33: =Statements!I80 -> 7729.0276 | J33: =Statements!J80 -> 8510.7345 | ... N33: =Statements!N80 -> 12973.793
A34: Free cash flow (CFO less capex) | B34: INR mn | C34: =Statements!C106 -> 813.97 | D34: =Statements!D106 -> -552.35 | E34: =Statements!E106 -> -838.28 | F34: =Statements!F106 -> -6244.729 | G34: =Statements!G106 -> -3591.0778 | H34: =Statements!H106 -> -620.24153 | I34: =Statements!I106 -> 229.02761 | J34: =Statements!J106 -> 1510.7345 | ... N34: =Statements!N106 -> 5473.7932
A35: Net debt / (net cash) | B35: INR mn | C35: =Schedules!C138 -> 5513.63 | D35: =Schedules!D138 -> -3352.46 | E35: =Schedules!E138 -> -627.38 | F35: =Schedules!F138 -> 6188.9163 | G35: =Schedules!G138 -> 10860.339 | H35: =Schedules!H138 -> 12926.281 | I35: =Schedules!I138 -> 14317.128 | J35: =Schedules!J138 -> 14566.022 | ... N35: =Schedules!N138 -> 6539.6827
A36: Net debt / EBITDA | B36: x | C36: =Schedules!C139 -> 1.8371724 | D36: =Schedules!D139 -> -0.78930256 | E36: =Schedules!E139 -> -0.094888358 | F36: =Schedules!F139 -> 0.91912926 | G36: =Schedules!G139 -> 1.4484643 | H36: =Schedules!H139 -> 1.5078929 | I36: =Schedules!I139 -> 1.4781129 | J36: =Schedules!J139 -> 1.3411186 | ... N36: =Schedules!N139 -> 0.38647226
A37: ROCE (%) | B37: % | D37: =Statements!D107 -> 0.14517628 | E37: =Statements!E107 -> 0.20444257 | F37: =Statements!F107 -> 0.14003124 | G37: =Statements!G107 -> 0.1086802 | H37: =Statements!H107 -> 0.10405787 | I37: =Statements!I107 -> 0.10778728 | J37: =Statements!J107 -> 0.11386566 | K37: =Statements!K107 -> 0.12456335 | ... N37: =Statements!N107 -> 0.15346056
A38: ROE (%) | B38: % | D38: =Statements!D108 -> 0.10963887 | E38: =Statements!E108 -> 0.15130391 | F38: =Statements!F108 -> 0.11566624 | G38: =Statements!G108 -> 0.089593039 | H38: =Statements!H108 -> 0.083747255 | I38: =Statements!I108 -> 0.087624027 | J38: =Statements!J108 -> 0.093050879 | K38: =Statements!K108 -> 0.10259547 | ... N38: =Statements!N108 -> 0.12112921
A40: KEY OPERATING ASSUMPTIONS
A41: Billable discovery FTEs | B41: count | C41: =Revenue_Model!C13 -> 1127 | D41: =Revenue_Model!D13 -> 1161 | E41: =Revenue_Model!E13 -> 1313 | F41: =Revenue_Model!F13 -> 1443 | G41: =Revenue_Model!G13 -> 1568 | H41: =Revenue_Model!H13 -> 1688 | I41: =Revenue_Model!I13 -> 1803 | J41: =Revenue_Model!J13 -> 1908 | ... N41: =Revenue_Model!N13 -> 2228
A42: Revenue per billable discovery FTE | B42: INR mn | C42: =Revenue_Model!C15 -> 4.4099379 | D42: =Revenue_Model!D15 -> 5.3919035 | E42: =Revenue_Model!E15 -> 5.9025133 | F42: =Revenue_Model!F15 -> 6.1681264 | G42: =Revenue_Model!G15 -> 6.4148515 | H42: =Revenue_Model!H15 -> 6.6714455 | I42: =Revenue_Model!I15 -> 6.9049461 | J42: =Revenue_Model!J15 -> 7.1466193 | ... N42: =Revenue_Model!N15 -> 8.0826295
A43: Installed GMP capacity | B43: KL | C43: =Revenue_Model!C46 -> 475 | D43: =Revenue_Model!D46 -> 609 | E43: =Revenue_Model!E46 -> 700 | F43: =Revenue_Model!F46 -> 925 | G43: =Revenue_Model!G46 -> 1150 | H43: =Revenue_Model!H46 -> 1250 | I43: =Revenue_Model!I46 -> 1400 | J43: =Revenue_Model!J46 -> 1500 | ... N43: =Revenue_Model!N46 -> 2100
A44: Effective revenue-generating capacity | B44: KL | C44: =Revenue_Model!C47 -> 475 | D44: =Revenue_Model!D47 -> 515.2 | E44: =Revenue_Model!E47 -> 636.3 | F44: =Revenue_Model!F47 -> 767.5 | G44: =Revenue_Model!G47 -> 992.5 | H44: =Revenue_Model!H47 -> 1180 | I44: =Revenue_Model!I47 -> 1295 | J44: =Revenue_Model!J47 -> 1430 | ... N44: =Revenue_Model!N47 -> 2030
A45: Total employees | B45: count | C45: =Schedules!C10 -> 3345 | D45: =Schedules!D10 -> 3401 | E45: =Schedules!E10 -> 3800 | F45: =Schedules!F10 -> 4120 | G45: =Schedules!G10 -> 4420 | H45: =Schedules!H10 -> 4700 | I45: =Schedules!I10 -> 4960 | J45: =Schedules!J10 -> 5200 | ... N45: =Schedules!N10 -> 5960
...

Sheet Revenue_Model
A1: SHEET 2 | REVENUE MODEL
A2: SIX forecast drivers, all in blue. CRO = billable FTEs x revenue per FTE. CDMO = commercial molecules x revenue per molecule, plus development revenue. Capacity is a cross-check, not a driver. Single base case.
B3: INR mn | C3: FY2024A | D3: FY2025A | E3: FY2026A | F3: FY2027E | G3: FY2028E | H3: FY2029E | I3: FY2030E | J3: FY2031E | K3: FY2032E | L3: FY2033E | M3: FY2034E | N3: FY2035E | P3: Source / basis
A5: A. REPORTED SEGMENT REVENUE (anchor - refresh from the quarterly deck)
A6: CRO / Discovery Services - reported | B6: INR mn | C6: 4970 | D6: 6260 | E6: 7750 | P6: Q4FY26 investor presentation p.21 - Discovery revenue FY22-FY26 (Rs Cr x 10). REPORTED FACT.
A7: CDMO / CMC Services - reported | B7: INR mn | C7: 9680 | D7: 10680 | E7: 14170 | P7: Q4FY26 investor presentation p.24 - CMC revenue FY22-FY26 (Rs Cr x 10). REPORTED FACT.
A8: Revenue from operations - audited | B8: INR mn | C8: 14651.78 | D8: 16945.7 | E8: 21924.92 | P8: FY25 Annual Report p.179 (FY24 & FY25); audited FY26 consolidated results filed 14-May-2026. REPORTED FACT.
A9: Rounding on segment disclosure (Rs Cr granularity) | B9: INR mn | C9: =C8-C6-C7 -> 1.78 | D9: =D8-D6-D7 -> 5.7 | E9: =E8-E6-E7 -> 4.92 | P9: Segments are disclosed in Rs Cr only; the residual is carried so the build ties exactly to audited revenue.
A11: B. CRO / DISCOVERY = BILLABLE FTEs x REVENUE PER FTE [ DRIVERS 1 and 2 ]
A12: DRIVER 1 Net billable FTE additions | B12: count | F12: 130 | G12: 125 | H12: 120 | I12: 115 | J12: 105 | K12: 95 | L12: 85 | M12: 75 | N12: 65 | P12: Implied historical additions: +34 in FY25, +152 in FY26.
A13: Billable discovery FTEs | B13: count | C13: 1127 | D13: 1161 | E13: 1313 | F13: =E13+F12 -> 1443 | G13: =F13+G12 -> 1568 | H13: =G13+H12 -> 1688 | I13: =H13+I12 -> 1803 | J13: =I13+J12 -> 1908 | K13: =J13+K12 -> 2003 | L13: =K13+L12 -> 2088 | M13: =L13+M12 -> 2163 | N13: =M13+N12 -> 2228 | P13: ANALYST ESTIMATE. Sai discloses 2,605 scientists of 3,401 employees at FY25 but does NOT split them between Discovery and CMC - management declined the split on the Q4FY26 call. Utilisation is embedded here rather than modelled separately. History is calibrated so the implied FTE rate sits inside observed Indian discovery rate cards.
A14: DRIVER 2 Revenue per FTE - growth | B14: % | F14: 0.045 | G14: 0.04 | H14: 0.04 | I14: 0.035 | J14: 0.035 | K14: 0.035 | L14: 0.03 | M14: 0.03 | N14: 0.03 | P14: Contractual escalation, mix shift toward integrated / biology / DMPK work, and FX. Implied history: FY25 +22.3%, FY26 +9.5%.
A15: Revenue per billable FTE | B15: INR mn | C15: =C6/C13 -> 4.4099379 | D15: =D6/D13 -> 5.3919035 | E15: =E6/E13 -> 5.9025133 | F15: =E15*(1+F14) -> 6.1681264 | G15: =F15*(1+G14) -> 6.4148515 | H15: =G15*(1+H14) -> 6.6714455 | I15: =H15*(1+I14) -> 6.9049461 | J15: =I15*(1+J14) -> 7.1466193 | K15: =J15*(1+K14) -> 7.3967509 | L15: =K15*(1+L14) -> 7.6186535 | M15: =L15*(1+M14) -> 7.8472131 | N15: =M15*(1+N14) -> 8.0826295 | P15: History derived (reported CRO revenue / billable FTEs).
A16: CROSS-CHECK: implied rate per FTE (USD 000 @ INR 84/USD) | B16: USD k | C16: =C15*1000/84 -> 52.499261 | D16: =D15*1000/84 -> 64.189328 | E16: =E15*1000/84 -> 70.268016 | F16: =F15*1000/84 -> 73.430077 | G16: =G15*1000/84 -> 76.36728 | H16: =H15*1000/84 -> 79.421971 | I16: =I15*1000/84 -> 82.20174 | J16: =J15*1000/84 -> 85.078801 | ... N16: =N15*1000/84 -> 96.221779 | P16: Indian discovery rate cards typically run USD 55k-90k for med-chem and biology FTEs.
A17: CRO / Discovery revenue | B17: INR mn | C17: =C13*C15 -> 4970 | D17: =D13*D15 -> 6260 | E17: =E13*E15 -> 7750 | F17: =F13*F15 -> 8900.6064 | G17: =G13*G15 -> 10058.487 | H17: =H13*H15 -> 11261.4 | I17: =I13*I15 -> 12449.618 | J17: =J13*J15 -> 13635.75 | ... N17: =N13*N15 -> 18008.098
A18: check: engine vs reported (history) - must be nil | B18: INR mn | C18: =C17-C6 -> 0 | D18: =D17-D6 -> 0 | E18: =E17-E6 -> 0
A19: CRO growth (%) | B19: % | D19: =D17/C17-1 -> 0.25955734 | E19: =E17/D17-1 -> 0.23801917 | F19: =F17/E17-1 -> 0.14846535 | G19: =G17/F17-1 -> 0.13009009 | H19: =H17/G17-1 -> 0.11959184 | I19: =I17/H17-1 -> 0.10551244 | J19: =J17/I17-1 -> 0.095274542 | K19: =K17/J17-1 -> 0.086533019 | ... N19: =N17/M17-1 -> 0.060952381
A20: CRO bridge (volume / price - foots exactly)
A21: Opening CRO revenue | B21: INR mn | D21: =C17 -> 4970 | E21: =D17 -> 6260 | F21: =E17 -> 7750 | G21: =F17 -> 8900.6064 | H21: =G17 -> 10058.487 | I21: =H17 -> 11261.4 | J21: =I17 -> 12449.618 | K21: =J17 -> 13635.75 | ... N21: =M17 -> 16973.522
A22: + FTE additions (volume) | B22: INR mn | D22: =(D13-C13)*C15 -> 149.93789 | E22: =(E13-D13)*D15 -> 819.56934 | F22: =(F13-E13)*E15 -> 767.32673 | G22: =(G13-F13)*F15 -> 771.0158 | H22: =(H13-G13)*G15 -> 769.78218 | I22: =(I13-H13)*H15 -> 767.21624 | J22: =(J13-I13)*I15 -> 725.01934 | K22: =(K13-J13)*J15 -> 678.92883 | ... N22: =(N13-M13)*M15 -> 510.06885
A23: + Rate, service mix and FX (price) | B23: INR mn | D23: =D13*(D15-C15) -> 1140.0621 | E23: =E13*(E15-D15) -> 670.43066 | F23: =F13*(F15-E15) -> 383.2797 | G23: =G13*(G15-F15) -> 386.86489 | H23: =H13*(H15-G15) -> 433.13077 | I23: =I13*(I15-H15) -> 421.00157 | J23: =J13*(J15-I15) -> 461.1123 | K23: =K13*(K15-J15) -> 501.01374 | ... N23: =N13*(N15-M15) -> 524.50772
A24: = Closing CRO revenue | B24: INR mn | D24: =D21+D22+D23 -> 6260 | E24: =E21+E22+E23 -> 7750 | F24: =F21+F22+F23 -> 8900.6064 | G24: =G21+G22+G23 -> 10058.487 | H24: =H21+H22+H23 -> 11261.4 | I24: =I21+I22+I23 -> 12449.618 | J24: =J21+J22+J23 -> 13635.75 | K24: =K21+K22+K23 -> 14815.692 | ... N24: =N21+N22+N23 -> 18008.098
A25: check: bridge vs CRO revenue - must be nil | B25: INR mn | D25: =D24-D17 -> 0 | E25: =E24-E17 -> 0 | F25: =F24-F17 -> 0 | G25: =G24-G17 -> 0 | H25: =H24-H17 -> 0 | I25: =I24-I17 -> 0 | J25: =J24-J17 -> 0 | K25: =K24-K17 -> 0 | ... N25: =N24-N17 -> 0
A27: C. CDMO / CMC = COMMERCIAL MANUFACTURING + DEVELOPMENT [ DRIVERS 3, 4 and 5 ]
A28: Two mutually exclusive and collectively exhaustive buckets. Commercial is a molecule count times an average revenue per molecule; development is everything pre-commercial, forecast as a growth rate because Sai does not disclose revenue by development stage.
A29: C1. Commercial manufacturing
A30: DRIVER 3 Net new commercial molecules (qualifications less exits) | B30: count | D30: 4 | E30: 4 | F30: 2 | G30: 2 | H30: 3 | I30: 3 | J30: 3 | K30: 4 | L30: 4 | M30: 4 | N30: 4 | P30: REPORTED: FY26 added 4 commercial molecules, 30 to 34 (Q4FY26 call), with two additional large-pharma commercial supply qualifications received. Forecast is net of assumed de-listings and customer in-sourcing.
A31: Commercial molecules | B31: count | C31: 26 | D31: 30 | E31: 34 | F31: =E31+F30 -> 36 | G31: =F31+G30 -> 38 | H31: =G31+H30 -> 41 | I31: =H31+I30 -> 44 | J31: =I31+J30 -> 47 | K31: =J31+K30 -> 51 | L31: =K31+L30 -> 55 | M31: =L31+M30 -> 59 | N31: =M31+N30 -> 63 | P31: REPORTED: FY25 = 30, FY26 = 34 (Q4FY26 deck p.15 and call). FY24 = ANALYST ESTIMATE.
A32: DRIVER 4 Revenue per commercial molecule - growth | B32: % | F32: 0.095 | G32: 0.09 | H32: 0.085 | I32: 0.08 | J32: 0.075 | K32: 0.07 | L32: 0.07 | M32: 0.065 | N32: 0.06 | P32: Embeds BOTH underlying volume and price growth on the existing portfolio AND the maturation of newly qualified molecules, which earn roughly Rs 110mn in year one against a portfolio average of Rs 243mn. Implied history: FY24 220.4, FY25 201.0, FY26 243.2 - the FY25 dip is the disclosed customer destocking on a commercial intermediate.
A33: Revenue per commercial molecule | B33: INR mn | C33: =C34/C31 -> 220.38462 | D33: =D34/D31 -> 201 | E33: =E34/E31 -> 243.23529 | F33: =E33*(1+F32) -> 266.34265 | G33: =F33*(1+G32) -> 290.31349 | H33: =G33*(1+H32) -> 314.99013 | I33: =H33*(1+I32) -> 340.18934 | J33: =I33*(1+J32) -> 365.70354 | K33: =J33*(1+K32) -> 391.30279 | L33: =K33*(1+L32) -> 418.69399 | M33: =L33*(1+M32) -> 445.9091 | N33: =M33*(1+N32) -> 472.66364 | P33: History derived. This is the single most important CDMO number in the model - watch it against the count.
A34: Commercial manufacturing revenue | B34: INR mn | C34: 5730 | D34: 6030 | E34: 8270 | F34: =F33*F31 -> 9588.3353 | G34: =G33*G31 -> 11031.912 | H34: =H33*H31 -> 12914.595 | I34: =I33*I31 -> 14968.331 | J34: =J33*J31 -> 17188.067 | K34: =K33*K31 -> 19956.442 | L34: =L33*L31 -> 23028.169 | M34: =M33*M31 -> 26308.637 | N34: =N33*N31 -> 29777.809 | P34: History is the balancing figure so the two buckets tie exactly to reported CDMO revenue. ANALYST ESTIMATE of the split between commercial and development - Sai does not disclose it.
A35: C2. Development (pre-clinical, Phase I-III, validation, process R&D and tech transfer)
A36: DRIVER 5 Development revenue - growth | B36: % | F36: 0.13 | G36: 0.12 | H36: 0.115 | I36: 0.11 | J36: 0.105 | K36: 0.1 | L36: 0.095 | M36: 0.09 | N36: 0.085 | P36: Forecast as a growth rate, not a programme count, because Sai discloses programme counts but never revenue per programme. Implied history: +17.7% FY25, +26.9% FY26. Includes the dedicated large-pharma development FTE teams management flagged on the Q4FY26 call.
A37: Development revenue | B37: INR mn | C37: 3950 | D37: 4650 | E37: 5900 | F37: =E37*(1+F36) -> 6667 | G37: =F37*(1+G36) -> 7467.04 | H37: =G37*(1+H36) -> 8325.7496 | I37: =H37*(1+I36) -> 9241.5821 | J37: =I37*(1+J36) -> 10211.948 | K37: =J37*(1+K36) -> 11233.143 | L37: =K37*(1+L36) -> 12300.292 | M37: =L37*(1+M36) -> 13407.318 | N37: =M37*(1+N36) -> 14546.94 | P37: Residual of reported CDMO revenue less commercial manufacturing. ANALYST ESTIMATE.
A38: C3. CDMO revenue
A39: CDMO / CMC revenue | B39: INR mn | C39: =C34+C37 -> 9680 | D39: =D34+D37 -> 10680 | E39: =E34+E37 -> 14170 | F39: =F34+F37 -> 16255.335 | G39: =G34+G37 -> 18498.952 | H39: =H34+H37 -> 21240.345 | I39: =I34+I37 -> 24209.913 | J39: =J34+J37 -> 27400.015 | ... N39: =N34+N37 -> 44324.749
A40: check: buckets vs reported (history) - must be nil | B40: INR mn | C40: =C39-C7 -> 0 | D40: =D39-D7 -> 0 | E40: =E39-E7 -> 0
A41: CDMO growth (%) | B41: % | D41: =D39/C39-1 -> 0.10330579 | E41: =E39/D39-1 -> 0.32677903 | F41: =F39/E39-1 -> 0.14716551 | G41: =G39/F39-1 -> 0.13802343 | H41: =H39/G39-1 -> 0.14819177 | I41: =I39/H39-1 -> 0.1398079 | J41: =J39/I39-1 -> 0.1317684 | K41: =K39/J39-1 -> 0.13830542 | ... N41: =N39/M39-1 -> 0.11604391
A42: Commercial as % of CDMO | B42: % | C42: =C34/C39 -> 0.59194215 | D42: =D34/D39 -> 0.56460674 | E42: =E34/E39 -> 0.58362738 | F42: =F34/F39 -> 0.58985774 | G42: =G34/G39 -> 0.59635336 | H42: =H34/H39 -> 0.60802192 | I42: =I34/I39 -> 0.61827281 | J42: =J34/J39 -> 0.62730136 | ... N42: =N34/N39 -> 0.67180999
A44: D. MANUFACTURING CAPACITY (cross-check, deliberately NOT a revenue driver) [ DRIVER 6 ]
...

Sheet Statements
A1: SHEET 3 | INCOME STATEMENT, BALANCE SHEET AND CASH FLOW STATEMENT
A2: Consolidated, Ind AS, INR million. FY2024A-FY2026A are hardcoded from the audited financial statements. FY2027E-FY2035E are fully formula-driven from the Revenue_Model and Schedules sheets.
B3: INR mn | C3: FY2024A | D3: FY2025A | E3: FY2026A | F3: FY2027E | G3: FY2028E | H3: FY2029E | I3: FY2030E | J3: FY2031E | K3: FY2032E | L3: FY2033E | M3: FY2034E | N3: FY2035E | P3: Source / basis
A5: I. CONSOLIDATED INCOME STATEMENT
A6: Revenue from operations | B6: INR mn | C6: =Schedules!C6 -> 14651.78 | D6: =Schedules!D6 -> 16945.7 | E6: =Schedules!E6 -> 21924.92 | F6: =Schedules!F6 -> 25155.942 | G6: =Schedules!G6 -> 28557.44 | H6: =Schedules!H6 -> 32501.745 | I6: =Schedules!I6 -> 36659.531 | J6: =Schedules!J6 -> 41035.764 | ... N6: =Schedules!N6 -> 62332.848
A7: Cost of materials, chemicals & reagents (net of WIP) | B7: INR mn | C7: =-Schedules!C19 -> -4457.3 | D7: =-Schedules!D19 -> -4657.64 | E7: =-Schedules!E19 -> -5708.92 | F7: =-Schedules!F19 -> -6726.5226 | G7: =-Schedules!G19 -> -7556.7966 | H7: =-Schedules!H19 -> -8547.4362 | I7: =-Schedules!I19 -> -9663.1183 | J7: =-Schedules!J19 -> -10845.265 | ... N7: =-Schedules!N19 -> -17042.96
A8: Material margin | B8: INR mn | C8: =C6+C7 -> 10194.48 | D8: =D6+D7 -> 12288.06 | E8: =E6+E7 -> 16216 | F8: =F6+F7 -> 18429.419 | G8: =G6+G7 -> 21000.643 | H8: =H6+H7 -> 23954.309 | I8: =I6+I7 -> 26996.413 | J8: =J6+J7 -> 30190.499 | ... N8: =N6+N7 -> 45289.888
A9: Material margin (%) | B9: % | C9: =C8/C6 -> 0.6957844 | D9: =D8/D6 -> 0.72514325 | E9: =E8/E6 -> 0.73961501 | F9: =F8/F6 -> 0.73260701 | G9: =G8/G6 -> 0.73538256 | H9: =H8/H6 -> 0.73701608 | I9: =I8/I6 -> 0.73640911 | J9: =J8/J6 -> 0.73571187 | ... N9: =N8/N6 -> 0.72658141
A10: Employee benefits expense | B10: INR mn | C10: =-Schedules!C27 -> -4949.05 | D10: =-Schedules!D27 -> -5491.18 | E10: =-Schedules!E27 -> -6830.55 | F10: =-Schedules!F27 -> -7961.1858 | G10: =-Schedules!G27 -> -9155.8274 | H10: =-Schedules!H27 -> -10417.343 | I10: =-Schedules!I27 -> -11741.188 | J10: =-Schedules!J27 -> -13109.415 | ... N10: =-Schedules!N27 -> -18879.685
A11: Other operating expenses | B11: INR mn | C11: =-Schedules!C40 -> -2390.54 | D11: =-Schedules!D40 -> -2740.27 | E11: =-Schedules!E40 -> -3073.86 | F11: =-Schedules!F40 -> -3936.0251 | G11: =-Schedules!G40 -> -4575.4451 | H11: =-Schedules!H40 -> -5224.567 | I11: =-Schedules!I40 -> -5862.415 | J11: =-Schedules!J40 -> -6548.2712 | ... N11: =-Schedules!N40 -> -9987.3862
A12: Net foreign exchange gain / (loss) | B12: INR mn | C12: =Schedules!C44 -> 146.26 | D12: =Schedules!D44 -> 190.76 | E12: =Schedules!E44 -> 300.18 | F12: =Schedules!F44 -> 201.24753 | G12: =Schedules!G44 -> 228.45952 | H12: =Schedules!H44 -> 260.01396 | I12: =Schedules!I44 -> 293.27625 | J12: =Schedules!J44 -> 328.28611 | ... N12: =Schedules!N44 -> 498.66278
A13: EBITDA | B13: INR mn | C13: =C8+C10+C11+C12 -> 3001.15 | D13: =D8+D10+D11+D12 -> 4247.37 | E13: =E8+E10+E11+E12 -> 6611.77 | F13: =F8+F10+F11+F12 -> 6733.4559 | G13: =G8+G10+G11+G12 -> 7497.83 | H13: =H8+H10+H11+H12 -> 8572.4128 | I13: =I8+I10+I11+I12 -> 9686.0861 | J13: =J8+J10+J11+J12 -> 10861.099 | ... N13: =N8+N10+N11+N12 -> 16921.48
A14: EBITDA margin (%) | B14: % | C14: =C13/C6 -> 0.20483177 | D14: =D13/D6 -> 0.25064589 | E14: =E13/E6 -> 0.30156416 | F14: =F13/F6 -> 0.26766861 | G14: =G13/G6 -> 0.2625526 | H14: =H13/H6 -> 0.26375239 | I14: =I13/I6 -> 0.2642174 | J14: =J13/J6 -> 0.26467398 | ... N14: =N13/N6 -> 0.27146971
A15: Depreciation and amortisation | B15: INR mn | C15: =-Schedules!C88 -> -1194.36 | D15: =-Schedules!D88 -> -1385.73 | E15: =-Schedules!E88 -> -1668.55 | F15: =-Schedules!F88 -> -2411.2497 | G15: =-Schedules!G88 -> -3175.5013 | H15: =-Schedules!H88 -> -3768.3003 | I15: =-Schedules!I88 -> -4170.2881 | J15: =-Schedules!J88 -> -4514.0958 | ... N15: =-Schedules!N88 -> -5726.1158
A16: EBIT | B16: INR mn | C16: =C13+C15 -> 1806.79 | D16: =D13+D15 -> 2861.64 | E16: =E13+E15 -> 4943.22 | F16: =F13+F15 -> 4322.2061 | G16: =G13+G15 -> 4322.3286 | H16: =H13+H15 -> 4804.1125 | I16: =I13+I15 -> 5515.7981 | J16: =J13+J15 -> 6347.0032 | ... N16: =N13+N15 -> 11195.364
A17: EBIT margin (%) | B17: % | C17: =C16/C6 -> 0.12331539 | D17: =D16/D6 -> 0.16887116 | E17: =E16/E6 -> 0.22546126 | F17: =F16/F6 -> 0.17181651 | G17: =G16/G6 -> 0.15135561 | H17: =H16/H6 -> 0.14781091 | I17: =I16/I6 -> 0.15046014 | J17: =J16/J6 -> 0.15467004 | ... N17: =N16/N6 -> 0.17960617
A18: Other income (interest and investment income) | B18: INR mn | C18: =Schedules!C136 -> 144.65 | D18: =Schedules!D136 -> 177.03 | E18: =Schedules!E136 -> 191.1 | F18: =Schedules!F136 -> 78.9315 | G18: =Schedules!G136 -> 83.896123 | H18: =Schedules!H136 -> 91.842405 | I18: =Schedules!I136 -> 100.83828 | J18: =Schedules!J136 -> 110.31242 | ... N18: =Schedules!N136 -> 155.31222
A19: Finance costs | B19: INR mn | C19: =-Schedules!C131 -> -859.1 | D19: =-Schedules!D131 -> -761.64 | E19: =-Schedules!E131 -> -392.39 | F19: =-Schedules!F131 -> -293.51595 | G19: =-Schedules!G131 -> -859.89587 | H19: =-Schedules!H131 -> -1259.6847 | I19: =-Schedules!I131 -> -1448.3458 | J19: =-Schedules!J131 -> -1586.9866 | ... N19: =-Schedules!N131 -> -1387.7462
A20: Profit before exceptional items and tax | B20: INR mn | C20: =C16+C18+C19 -> 1092.34 | D20: =D16+D18+D19 -> 2277.03 | E20: =E16+E18+E19 -> 4741.93 | F20: =F16+F18+F19 -> 4107.6217 | G20: =G16+G18+G19 -> 3546.3289 | H20: =H16+H18+H19 -> 3636.2703 | I20: =I16+I18+I19 -> 4168.2906 | J20: =J16+J18+J19 -> 4870.3291 | ... N20: =N16+N18+N19 -> 9962.9302
A21: Exceptional items | B21: INR mn | C21: =Schedules!C142 -> 0 | D21: =Schedules!D142 -> 0 | E21: =Schedules!E142 -> -80.01 | F21: =Schedules!F142 -> 0 | G21: =Schedules!G142 -> 0 | H21: =Schedules!H142 -> 0 | I21: =Schedules!I142 -> 0 | J21: =Schedules!J142 -> 0 | ... N21: =Schedules!N142 -> 0
A22: Profit before tax | B22: INR mn | C22: =C20+C21 -> 1092.34 | D22: =D20+D21 -> 2277.03 | E22: =E20+E21 -> 4661.92 | F22: =F20+F21 -> 4107.6217 | G22: =G20+G21 -> 3546.3289 | H22: =H20+H21 -> 3636.2703 | I22: =I20+I21 -> 4168.2906 | J22: =J20+J21 -> 4870.3291 | ... N22: =N20+N21 -> 9962.9302
A23: Current tax | B23: INR mn | C23: =-Schedules!C150 -> -77.57 | D23: =-Schedules!D150 -> -338.44 | E23: =-Schedules!E150 -> -884.02 | F23: =-Schedules!F150 -> -817.00595 | G23: =-Schedules!G150 -> -723.45109 | H23: =-Schedules!H150 -> -760.34412 | I23: =-Schedules!I150 -> -892.84784 | J23: =-Schedules!J150 -> -1068.0632 | ... N23: =-Schedules!N150 -> -2286.4925
A24: Deferred tax | B24: INR mn | C24: =-Schedules!C149 -> -186.68 | D24: =-Schedules!D149 -> -237.27 | E24: =-Schedules!E149 -> -288.8 | F24: =-Schedules!F149 -> -230.43758 | G24: =-Schedules!G149 -> -180.86277 | H24: =-Schedules!H149 -> -166.90481 | I24: =-Schedules!I149 -> -170.06626 | J24: =-Schedules!J149 -> -173.87075 | ... N24: =-Schedules!N149 -> -254.05472
A25: Total tax expense | B25: INR mn | C25: =C23+C24 -> -264.25 | D25: =D23+D24 -> -575.71 | E25: =E23+E24 -> -1172.82 | F25: =F23+F24 -> -1047.4435 | G25: =G23+G24 -> -904.31387 | H25: =H23+H24 -> -927.24892 | I25: =I23+I24 -> -1062.9141 | J25: =J23+J24 -> -1241.9339 | ... N25: =N23+N24 -> -2540.5472
A26: Profit after tax | B26: INR mn | C26: =C22+C25 -> 828.09 | D26: =D22+D25 -> 1701.32 | E26: =E22+E25 -> 3489.1 | F26: =F22+F25 -> 3060.1782 | G26: =G22+G25 -> 2642.015 | H26: =H22+H25 -> 2709.0214 | I26: =I22+I25 -> 3105.3765 | J26: =J22+J25 -> 3628.3951 | ... N26: =N22+N25 -> 7422.383
A27: PAT margin (%) | B27: % | C27: =C26/C6 -> 0.056518048 | D27: =D26/D6 -> 0.10039833 | E27: =E26/E6 -> 0.15913855 | F27: =F26/F6 -> 0.12164832 | G27: =G26/G6 -> 0.092515823 | H27: =H26/H6 -> 0.083350028 | I27: =I26/I6 -> 0.084708571 | J27: =J26/J6 -> 0.088420314 | ... N27: =N26/N6 -> 0.11907659
A28: Effective tax rate (%) | B28: % | C28: =-C25/C22 -> 0.24191186 | D28: =-D25/D22 -> 0.25283374 | E28: =-E25/E22 -> 0.25157446 | F28: =-F25/F22 -> 0.255 | G28: =-G25/G22 -> 0.255 | H28: =-H25/H22 -> 0.255 | I28: =-I25/I22 -> 0.255 | J28: =-J25/J22 -> 0.255 | ... N28: =-N25/N22 -> 0.255
A29: Diluted weighted average shares | B29: mn | C29: =Schedules!C169 -> 182.8 | D29: =Schedules!D169 -> 197.6 | E29: =Schedules!E169 -> 212.36 | F29: =Schedules!F169 -> 214.36 | G29: =Schedules!G169 -> 216.36 | H29: =Schedules!H169 -> 218.36 | I29: =Schedules!I169 -> 220.36 | J29: =Schedules!J169 -> 222.36 | ... N29: =Schedules!N169 -> 230.36
A30: Diluted EPS | B30: INR | C30: =C26/C29 -> 4.5300328 | D30: =D26/D29 -> 8.609919 | E30: =E26/E29 -> 16.430119 | F30: =F26/F29 -> 14.275882 | G30: =G26/G29 -> 12.211199 | H30: =H26/H29 -> 12.406216 | I30: =I26/I29 -> 14.092287 | J30: =J26/J29 -> 16.317661 | ... N30: =N26/N29 -> 32.220798
A31: CHECK: PAT vs audited (history) - must be nil | B31: INR mn | C31: =C26-828.09 -> 0 | D31: =D26-1701.32 -> 0 | E31: =E26-3489.1 -> 0
A33: II. CONSOLIDATED BALANCE SHEET
A34: Assets
A35: Property, plant and equipment | B35: INR mn | C35: =Schedules!C76 -> 9263.55 | D35: =Schedules!D76 -> 11850.12 | E35: =Schedules!E76 -> 15344.14 | F35: =Schedules!F76 -> 23174.474 | G35: =Schedules!G76 -> 30840.077 | H35: =Schedules!H76 -> 35236.208 | I35: =Schedules!I76 -> 38791.205 | J35: =Schedules!J76 -> 41931.917 | ... N35: =Schedules!N76 -> 52509.961
A36: Right-of-use assets | B36: INR mn | C36: =Schedules!C81 -> 2397.13 | D36: =Schedules!D81 -> 2923.44 | E36: =Schedules!E81 -> 2743.01 | F36: =Schedules!F81 -> 2617.4406 | G36: =Schedules!G81 -> 2556.8096 | H36: =Schedules!H81 -> 2557.4587 | I36: =Schedules!I81 -> 2612.0519 | J36: =Schedules!J81 -> 2714.5283 | ... N36: =Schedules!N81 -> 3557.8716
A37: Capital work-in-progress | B37: INR mn | C37: =Schedules!C69 -> 1068.95 | D37: =Schedules!D69 -> 1244.56 | E37: =Schedules!E69 -> 2704.53 | F37: =Schedules!F69 -> 4680 | G37: =Schedules!G69 -> 2652 | H37: =Schedules!H69 -> 1842.75 | I37: =Schedules!I69 -> 1974.375 | J37: =Schedules!J69 -> 1706.25 | ... N37: =Schedules!N69 -> 1828.125
A38: Intangible assets | B38: INR mn | C38: =Schedules!C64 -> 137.73 | D38: =Schedules!D64 -> 108.56 | E38: =Schedules!E64 -> 61.17 | F38: =Schedules!F64 -> 281.7126 | G38: =Schedules!G64 -> 385.48583 | H38: =Schedules!H64 -> 437.17895 | I38: =Schedules!I64 -> 487.24958 | J38: =Schedules!J64 -> 516.55467 | ... N38: =Schedules!N64 -> 611.21475
A39: Other non-current assets | B39: INR mn | C39: =Schedules!C175 -> 432.86 | D39: =Schedules!D175 -> 427.96 | E39: =Schedules!E175 -> 1303.25 | F39: =Schedules!F175 -> 1257.7971 | G39: =Schedules!G175 -> 1370.7571 | H39: =Schedules!H175 -> 1495.0803 | I39: =Schedules!I175 -> 1649.6789 | J39: =Schedules!J175 -> 1805.5736 | ... N39: =Schedules!N175 -> 2493.3139
A40: Total non-current assets | B40: INR mn | C40: =C35+C36+C37+C38+C39 -> 13300.22 | D40: =D35+D36+D37+D38+D39 -> 16554.64 | E40: =E35+E36+E37+E38+E39 -> 22156.1 | F40: =F35+F36+F37+F38+F39 -> 32011.425 | G40: =G35+G36+G37+G38+G39 -> 37805.13 | H40: =H35+H36+H37+H38+H39 -> 41568.676 | I40: =I35+I36+I37+I38+I39 -> 45514.56 | J40: =J35+J36+J37+J38+J39 -> 48674.824 | ... N40: =N35+N36+N37+N38+N39 -> 61000.486
A41: Inventories | B41: INR mn | C41: =Schedules!C97 -> 874.43 | D41: =Schedules!D97 -> 1188.65 | E41: =Schedules!E97 -> 1509.68 | F41: =Schedules!F97 -> 1750.7388 | G41: =Schedules!G97 -> 1946.1339 | H41: =Schedules!H97 -> 2177.8399 | I41: =Schedules!I97 -> 2435.6353 | J41: =Schedules!J97 -> 2703.888 | ... N41: =Schedules!N97 -> 4202.3736
A42: Trade receivables | B42: INR mn | C42: =Schedules!C99 -> 2561.84 | D42: =Schedules!D99 -> 3547.83 | E42: =Schedules!E99 -> 3736.23 | F42: =Schedules!F99 -> 4273.0641 | G42: =Schedules!G99 -> 4850.8527 | H42: =Schedules!H99 -> 5431.7985 | I42: =Schedules!I99 -> 6126.6613 | J42: =Schedules!J99 -> 6745.6051 | ... N42: =Schedules!N99 -> 10246.495
...

Sheet Schedules
A1: SHEET 4 | SUPPORTING SCHEDULES
A2: Cost build, PP&E and capex, working capital, debt and interest, tax, equity and share count. Every forecast line in the Statements sheet is driven from this sheet.
B3: INR mn | C3: FY2024A | D3: FY2025A | E3: FY2026A | F3: FY2027E | G3: FY2028E | H3: FY2029E | I3: FY2030E | J3: FY2031E | K3: FY2032E | L3: FY2033E | M3: FY2034E | N3: FY2035E | P3: Source / basis
A5: 0. DRIVERS IMPORTED FROM THE REVENUE MODEL
A6: Revenue from operations | B6: INR mn | C6: =Revenue_Model!C53 -> 14651.78 | D6: =Revenue_Model!D53 -> 16945.7 | E6: =Revenue_Model!E53 -> 21924.92 | F6: =Revenue_Model!F53 -> 25155.942 | G6: =Revenue_Model!G53 -> 28557.44 | H6: =Revenue_Model!H53 -> 32501.745 | I6: =Revenue_Model!I53 -> 36659.531 | J6: =Revenue_Model!J53 -> 41035.764 | ... N6: =Revenue_Model!N53 -> 62332.848
A7: CRO / Discovery revenue | B7: INR mn | C7: =Revenue_Model!C17 -> 4970 | D7: =Revenue_Model!D17 -> 6260 | E7: =Revenue_Model!E17 -> 7750 | F7: =Revenue_Model!F17 -> 8900.6064 | G7: =Revenue_Model!G17 -> 10058.487 | H7: =Revenue_Model!H17 -> 11261.4 | I7: =Revenue_Model!I17 -> 12449.618 | J7: =Revenue_Model!J17 -> 13635.75 | ... N7: =Revenue_Model!N17 -> 18008.098
A8: CDMO / CMC revenue | B8: INR mn | C8: =Revenue_Model!C39 -> 9680 | D8: =Revenue_Model!D39 -> 10680 | E8: =Revenue_Model!E39 -> 14170 | F8: =Revenue_Model!F39 -> 16255.335 | G8: =Revenue_Model!G39 -> 18498.952 | H8: =Revenue_Model!H39 -> 21240.345 | I8: =Revenue_Model!I39 -> 24209.913 | J8: =Revenue_Model!J39 -> 27400.015 | ... N8: =Revenue_Model!N39 -> 44324.749
A9: Net group headcount additions <-- INPUT | B9: count | F9: 320 | G9: 300 | H9: 280 | I9: 260 | J9: 240 | K9: 220 | L9: 200 | M9: 180 | N9: 160 | P9: FY26 net addition was approximately +400. Additions taper so headcount growth runs below revenue growth - that is what produces employee-cost operating leverage.
A10: Total employees (period end) | B10: count | C10: 3345 | D10: 3401 | E10: 3800 | F10: =E10+F9 -> 4120 | G10: =F10+G9 -> 4420 | H10: =G10+H9 -> 4700 | I10: =H10+I9 -> 4960 | J10: =I10+J9 -> 5200 | K10: =J10+K9 -> 5420 | L10: =K10+L9 -> 5620 | M10: =L10+M9 -> 5800 | N10: =M10+N9 -> 5960 | P10: FY25: 3,401 permanent employees (FY25 Annual Report p.33). FY26: 3,800+ (Q4FY26 deck p.15). FY24: ANALYST ESTIMATE derived from FY24 employee cost divided by FY25 average cost deflated by the disclosed 9.12% salary increase.
A11: Installed GMP capacity | B11: KL | C11: =Revenue_Model!C46 -> 475 | D11: =Revenue_Model!D46 -> 609 | E11: =Revenue_Model!E46 -> 700 | F11: =Revenue_Model!F46 -> 925 | G11: =Revenue_Model!G46 -> 1150 | H11: =Revenue_Model!H46 -> 1250 | I11: =Revenue_Model!I46 -> 1400 | J11: =Revenue_Model!J46 -> 1500 | ... N11: =Revenue_Model!N46 -> 2100
A12: Capacity commissioned in year | B12: KL | C12: =Revenue_Model!C45 -> 0 | D12: =Revenue_Model!D45 -> 134 | E12: =Revenue_Model!E45 -> 91 | F12: =Revenue_Model!F45 -> 225 | G12: =Revenue_Model!G45 -> 225 | H12: =Revenue_Model!H45 -> 100 | I12: =Revenue_Model!I45 -> 150 | J12: =Revenue_Model!J45 -> 100 | ... N12: =Revenue_Model!N45 -> 100
A14: 1. COST AND MARGIN SCHEDULE
A15: 1a. Material, chemicals and reagents (net of change in WIP)
A16: Reported material cost, net of WIP movement | B16: INR mn | C16: 4457.3 | D16: 4657.64 | E16: 5708.92 | P16: FY25 AR p.179 and FY26 audited results: cost of material, chemicals & reagents consumed plus changes in inventories of WIP. REPORTED FACT.
A17: CRO consumables ratio (% of CRO revenue) | B17: % | C17: 0.08 | D17: 0.08 | E17: 0.08 | F17: 0.08 | G17: 0.08 | H17: 0.08 | I17: 0.08 | J17: 0.08 | K17: 0.08 | L17: 0.08 | M17: 0.08 | N17: 0.08 | P17: ANALYST ASSUMPTION - discovery work is labour-intensive; reagents and consumables run at a high single-digit percentage of revenue.
A18: CDMO material ratio (% of CDMO revenue) | B18: % | C18: =(C16-C7*C17)/C8 -> 0.4193905 | D18: =(D16-D7*D17)/D8 -> 0.38921723 | E18: =(E16-E7*E17)/E8 -> 0.35913338 | F18: 0.37 | G18: 0.365 | H18: 0.36 | I18: 0.358 | J18: 0.356 | K18: 0.355 | L18: 0.354 | M18: 0.353 | N18: 0.352 | P18: History derived so total material cost ties to the audited number: 41.9% FY24, 38.9% FY25, 35.9% FY26. FY27 normalises upward because FY26 benefited from a Rs 34 Cr destocking provision reversal; thereafter mix and scale drive a slow decline.
A19: Material cost | B19: INR mn | C19: =C8*C18+C7*C17 -> 4457.3 | D19: =D8*D18+D7*D17 -> 4657.64 | E19: =E8*E18+E7*E17 -> 5708.92 | F19: =F8*F18+F7*F17 -> 6726.5226 | G19: =G8*G18+G7*G17 -> 7556.7966 | H19: =H8*H18+H7*H17 -> 8547.4362 | I19: =I8*I18+I7*I17 -> 9663.1183 | J19: =J8*J18+J7*J17 -> 10845.265 | ... N19: =N8*N18+N7*N17 -> 17042.96
A20: check: vs reported (history) - must be nil | B20: INR mn | C20: =C19-C16 -> 0 | D20: =D19-D16 -> 0 | E20: =E19-E16 -> 0
A21: Material margin | B21: INR mn | C21: =C6-C19 -> 10194.48 | D21: =D6-D19 -> 12288.06 | E21: =E6-E19 -> 16216 | F21: =F6-F19 -> 18429.419 | G21: =G6-G19 -> 21000.643 | H21: =H6-H19 -> 23954.309 | I21: =I6-I19 -> 26996.413 | J21: =J6-J19 -> 30190.499 | ... N21: =N6-N19 -> 45289.888
A22: Material margin (%) | B22: % | C22: =C21/C6 -> 0.6957844 | D22: =D21/D6 -> 0.72514325 | E22: =E21/E6 -> 0.73961501 | F22: =F21/F6 -> 0.73260701 | G22: =G21/G6 -> 0.73538256 | H22: =H21/H6 -> 0.73701608 | I22: =I21/I6 -> 0.73640911 | J22: =J21/J6 -> 0.73571187 | ... N22: =N21/N6 -> 0.72658141 | P22: Company discloses material margin of 72.5% in FY25 and 74.0% in FY26 (Q4FY26 deck p.10) - the build reproduces both.
A23: 1b. Employee benefits expense
A24: Reported employee benefits expense | B24: INR mn | C24: 4949.05 | D24: 5491.18 | E24: 6830.55 | P24: FY25 AR p.179 note 31; FY26 audited results. REPORTED FACT.
A25: Average cost per employee - growth (%) | B25: % | F25: 0.075 | G25: 0.072 | H25: 0.07 | I25: 0.068 | J25: 0.065 | K25: 0.062 | L25: 0.06 | M25: 0.058 | N25: 0.055 | P25: ANALYST ASSUMPTION. FY25 average salary increase for non-managerial staff was 9.12% (FY25 AR p.60); mix effects from senior scientific and leadership hiring add to base wage inflation.
A26: Average cost per employee | B26: INR mn | C26: =C24/C10 -> 1.4795366 | D26: =D24/D10 -> 1.6145781 | E26: =E24/E10 -> 1.7975132 | F26: =E26*(1+F25) -> 1.9323266 | G26: =F26*(1+G25) -> 2.0714542 | H26: =G26*(1+H25) -> 2.216456 | I26: =H26*(1+I25) -> 2.367175 | J26: =I26*(1+J25) -> 2.5210413 | K26: =J26*(1+K25) -> 2.6773459 | L26: =K26*(1+L25) -> 2.8379866 | M26: =L26*(1+M25) -> 3.0025899 | N26: =M26*(1+N25) -> 3.1677323 | P26: History derived. FY24 1.48, FY25 1.61, FY26 1.80 INR mn per employee.
A27: Employee benefits expense | B27: INR mn | C27: =C10*C26 -> 4949.05 | D27: =D10*D26 -> 5491.18 | E27: =E10*E26 -> 6830.55 | F27: =F10*F26 -> 7961.1858 | G27: =G10*G26 -> 9155.8274 | H27: =H10*H26 -> 10417.343 | I27: =I10*I26 -> 11741.188 | J27: =J10*J26 -> 13109.415 | ... N27: =N10*N26 -> 18879.685
A28: check: vs reported (history) - must be nil | B28: INR mn | C28: =C27-C24 -> 0 | D28: =D27-D24 -> 0 | E28: =E27-E24 -> 0
A29: Employee cost (% of revenue) | B29: % | C29: =C27/C6 -> 0.33777807 | D29: =D27/D6 -> 0.32404563 | E29: =E27/E6 -> 0.31154276 | F29: =F27/F6 -> 0.31647337 | G29: =G27/G6 -> 0.32061093 | H29: =H27/H6 -> 0.32051642 | I29: =I27/I6 -> 0.32027654 | J29: =J27/J6 -> 0.31946316 | ... N29: =N27/N6 -> 0.302885
A30: 1c. Other operating expenses
A31: Reported other expenses | B31: INR mn | C31: 2390.54 | D31: 2740.27 | E31: 3073.86 | P31: FY25 AR p.179 note 34; FY26 audited results. REPORTED FACT.
A32: Production & facility overhead - reported / estimated (history) | B32: INR mn | C32: 1322.67 | D32: 1404.59 | E32: 1942.5 | P32: FY24 and FY25 are the sum of power and fuel, stores and spares and repairs and maintenance per note 34. FY26 is apportioned pro-rata to the growth in other expenses excluding credit losses, because the FY26 annual report is not yet published. ANALYST ESTIMATE for FY26.
A33: Production & facility overhead - variable (% of CDMO revenue) | B33: % | C33: 0.0888 | D33: 0.0855 | E33: 0.0891 | F33: 0.0891 | G33: 0.0891 | H33: 0.0891 | I33: 0.0891 | J33: 0.0891 | K33: 0.0891 | L33: 0.0891 | M33: 0.0891 | N33: 0.0891 | P33: Variable element of site overhead - power, fuel and consumable spares that flow with production volume.
A34: Production & facility overhead - fixed (INR mn per installed KL) | B34: INR mn/KL | C34: =(C32-C8*C33)/(C11-C12/2) -> 0.97491789 | D34: =(D32-D8*D33)/(D11-D12/2) -> 0.90673432 | E34: =(E32-E8*E33)/(E11-E12/2) -> 1.0388892 | F34: =E34*1.01 -> 1.0492781 | G34: =F34*1.01 -> 1.0597709 | H34: =G34*1.01 -> 1.0703686 | I34: =H34*1.01 -> 1.0810723 | J34: =I34*1.01 -> 1.091883 | K34: =J34*1.01 -> 1.1028019 | L34: =K34*1.01 -> 1.1138299 | M34: =L34*1.01 -> 1.1249682 | N34: =M34*1.01 -> 1.1362178 | P34: Derived for history so the bucket ties exactly. Fixed site overhead - minimum demand charges, plant maintenance, EHS. Captures under-absorption when new blocks are commissioned ahead of revenue. Escalated 1% p.a., reflecting scale efficiency and the shift of the Bidar site to 100% renewable power.
A35: Production & facility overhead | B35: INR mn | C35: =C8*C33+(C11-C12/2)*C34 -> 1322.67 | D35: =D8*D33+(D11-D12/2)*D34 -> 1404.59 | E35: =E8*E33+(E11-E12/2)*E34 -> 1942.5 | F35: =F8*F33+(F11-F12/2)*F34 -> 2300.8888 | G35: =G8*G33+(G11-G12/2)*G34 -> 2747.769 | H35: =H8*H33+(H11-H12/2)*H34 -> 3176.9571 | I35: =I8*I33+(I11-I12/2)*I34 -> 3589.5241 | J35: =J8*J33+(J11-J12/2)*J34 -> 4024.5717 | ... N35: =N8*N33+(N11-N12/2)*N34 -> 6278.5817 | P35: Fixed overhead is charged on AVERAGE installed capacity for the year, so a block commissioned mid-year carries only half a year of site cost.
A36: Corporate, selling, freight, travel & technology (% of revenue) | B36: % | C36: =(C31-C35-C38)/C6 -> 0.06167783 | D36: =(D31-D35-D38)/D6 -> 0.058497436 | E36: =(E31-E35-E38)/E6 -> 0.062512885 | F36: 0.0605 | G36: 0.0595 | H36: 0.0585 | I36: 0.0575 | J36: 0.057 | K36: 0.0565 | L36: 0.056 | M36: 0.0555 | N36: 0.055 | P36: Legal and professional, travel, freight, insurance, membership, communication and IT. Derived for history so the build ties exactly (6.2% FY24, 5.9% FY25, 6.3% FY26). Scenario lever L_opex is added to this ratio in the forecast.
A37: Corporate, selling and other expenses | B37: INR mn | C37: =C6*C36 -> 903.69 | D37: =D6*D36 -> 991.28 | E37: =E6*E36 -> 1370.59 | F37: =F6*F36 -> 1521.9345 | G37: =G6*G36 -> 1699.1677 | H37: =H6*H36 -> 1901.3521 | I37: =I6*I36 -> 2107.923 | J37: =J6*J36 -> 2339.0386 | ... N37: =N6*N36 -> 3428.3066
A38: Credit loss allowance / bad debts (net) | B38: INR mn | C38: 164.18 | D38: 344.4 | E38: -239.23 | P38: FY24 and FY25 from note 34 (loss allowance on receivables and contract assets, bad debts, CWIP written off). FY26 is a NET REVERSAL as the destocked commercial product resumed shipment. REPORTED / DERIVED.
A39: Normalised credit loss (% of revenue) | B39: % | F39: 0.0045 | G39: 0.0045 | H39: 0.0045 | I39: 0.0045 | J39: 0.0045 | K39: 0.0045 | L39: 0.0045 | M39: 0.0045 | N39: 0.0045 | P39: ANALYST ASSUMPTION - normalised through the cycle. FY24 1.1%, FY25 2.0%, FY26 (1.1)% actual.
A40: Other operating expenses | B40: INR mn | C40: =C35+C37+C38 -> 2390.54 | D40: =D35+D37+D38 -> 2740.27 | E40: =E35+E37+E38 -> 3073.86 | F40: =F35+F37+F6*F39 -> 3936.0251 | G40: =G35+G37+G6*G39 -> 4575.4451 | H40: =H35+H37+H6*H39 -> 5224.567 | I40: =I35+I37+I6*I39 -> 5862.415 | J40: =J35+J37+J6*J39 -> 6548.2712 | K40: =K35+K37+K6*K39 -> 7322.2269 | L40: =L35+L37+L6*L39 -> 8196.7588 | M40: =M35+M37+M6*M39 -> 9105.6238 | N40: =N35+N37+N6*N39 -> 9987.3862
A41: check: vs reported (history) - must be nil | B41: INR mn | C41: =C40-C31 -> 0 | D41: =D40-D31 -> 0 | E41: =E40-E31 -> 0
A42: 1d. EBITDA
...

Sheet Sources_Checks
A1: SHEET 5 | SOURCES, ASSUMPTION LOG, MOLECULE TABLE AND MODEL CHECKS
A3: A. MODEL INTEGRITY CHECKS (every check must read OK)
A4: Check | B4: What it tests | C4: Worst absolute value | D4: Status
A5: Balance sheet balances | B5: Total assets less total equity and liabilities, every year | C5: =MAX(ABS(Statements!C67),ABS(Statements!D67),ABS(Statements!E67),ABS(Statements!F67),ABS(Statements!G67),ABS(Statements!H67),ABS(Statements!I67),ABS(Statements!J67),ABS(Statements!K67),ABS(Statements!L67),ABS(Statements!M67),ABS(Statements!N67)) -> 0 | D5: =IF(ABS(C5)<0.05,"OK","FAIL") -> OK
A6: Cash flow reconciliation | B6: Cash flow closing cash less balance sheet cash, forecast years | C6: =MAX(ABS(Statements!F102),ABS(Statements!G102),ABS(Statements!H102),ABS(Statements!I102),ABS(Statements!J102),ABS(Statements!K102),ABS(Statements!L102),ABS(Statements!M102),ABS(Statements!N102)) -> 0 | D6: =IF(ABS(C6)<0.05,"OK","FAIL") -> OK
A7: Historical CFO ties to filings | B7: Modelled CFO less reported CFO, FY24-FY26 | C7: =MAX(ABS(Statements!C81),ABS(Statements!D81),ABS(Statements!E81)) -> 0 | D7: =IF(ABS(C7)<0.05,"OK","FAIL") -> OK
A8: Historical PAT ties to filings | B8: Modelled PAT less audited PAT, FY24-FY26 | C8: =MAX(ABS(Statements!C31),ABS(Statements!D31),ABS(Statements!E31)) -> 0 | D8: =IF(ABS(C8)<0.05,"OK","FAIL") -> OK
A9: Historical PBT ties to filings | B9: Cost build reproduces audited PBT, FY24-FY26 | C9: =MAX(ABS(Schedules!C145),ABS(Schedules!D145),ABS(Schedules!E145)) -> 0 | D9: =IF(ABS(C9)<0.05,"OK","FAIL") -> OK
A10: Total revenue reconciliation | B10: CRO plus CDMO plus rounding less audited revenue, FY24-FY26 | C10: =MAX(ABS(Revenue_Model!C57),ABS(Revenue_Model!D57),ABS(Revenue_Model!E57)) -> 0 | D10: =IF(ABS(C10)<0.05,"OK","FAIL") -> OK
A11: CRO engine reconciliation | B11: FTE engine reproduces reported CRO revenue, FY24-FY26 | C11: =MAX(ABS(Revenue_Model!C18),ABS(Revenue_Model!D18),ABS(Revenue_Model!E18)) -> 0 | D11: =IF(ABS(C11)<0.05,"OK","FAIL") -> OK
A12: CDMO bucket reconciliation | B12: Molecule and pipeline buckets sum to reported CDMO revenue, FY24-FY26 | C12: =MAX(ABS(Revenue_Model!C40),ABS(Revenue_Model!D40),ABS(Revenue_Model!E40)) -> 0 | D12: =IF(ABS(C12)<0.05,"OK","FAIL") -> OK
A13: CRO revenue bridge | B13: Volume, utilisation and price bridge foots to CRO revenue, all years | C13: =MAX(ABS(Revenue_Model!D25),ABS(Revenue_Model!E25),ABS(Revenue_Model!F25),ABS(Revenue_Model!J25),ABS(Revenue_Model!N25)) -> 0 | D13: =IF(ABS(C13)<0.05,"OK","FAIL") -> OK
A14: Segment shares sum to 100% | B14: CRO share plus CDMO share of total revenue | C14: =MAX(ABS(Revenue_Model!E55+Revenue_Model!E56-1),ABS(Revenue_Model!J55+Revenue_Model!J56-1),ABS(Revenue_Model!N55+Revenue_Model!N56-1)) -> 0.00022440219 | D14: =IF(ABS(C14)<0.05,"OK","FAIL") -> OK
A15: Capacity feasibility | B15: No forecast year grows commercial revenue per effective KL by more than 10% | C15: =MAX(0,MAX(Revenue_Model!F49,Revenue_Model!G49,Revenue_Model!H49,Revenue_Model!I49,Revenue_Model!J49,Revenue_Model!K49,Revenue_Model!L49,Revenue_Model!M49,Revenue_Model!N49)-0.1) -> 0 | D15: =IF(ABS(C15)<0.05,"OK","FAIL") -> OK
A16: Material cost ties to filings | B16: Driver build reproduces reported material cost | C16: =MAX(ABS(Schedules!C20),ABS(Schedules!D20),ABS(Schedules!E20)) -> 0 | D16: =IF(ABS(C16)<0.05,"OK","FAIL") -> OK
A17: Employee cost ties to filings | B17: Headcount times average cost reproduces reported expense | C17: =MAX(ABS(Schedules!C28),ABS(Schedules!D28),ABS(Schedules!E28)) -> 0 | D17: =IF(ABS(C17)<0.05,"OK","FAIL") -> OK
A18: Other expenses tie to filings | B18: Three-bucket build reproduces reported other expenses | C18: =MAX(ABS(Schedules!C41),ABS(Schedules!D41),ABS(Schedules!E41)) -> 0 | D18: =IF(ABS(C18)<0.05,"OK","FAIL") -> OK
A19: D&A ties to filings | B19: PP&E, ROU and intangible charges sum to reported D&A | C19: =MAX(ABS(Schedules!C90),ABS(Schedules!D90),ABS(Schedules!E90)) -> 0 | D19: =IF(ABS(C19)<0.05,"OK","FAIL") -> OK
A20: Retained earnings roll-forward | B20: Opening equity plus PAT and reserves equals closing equity | C20: =MAX(ABS(Schedules!F168),ABS(Schedules!I168),ABS(Schedules!N168)) -> 1.8189894e-12 | D20: =IF(ABS(C20)<0.05,"OK","FAIL") -> OK
A21: Diluted EPS ties to filings | B21: Modelled EPS less reported diluted EPS, FY24-FY26 | C21: =MAX(ABS(Schedules!C171),ABS(Schedules!D171),ABS(Schedules!E171)) -> 0.00011866642 | D21: =IF(ABS(C21)<0.05,"OK","FAIL") -> OK
A22: MASTER CHECK | B22: All integrity checks pass | C22: =MAX(MAX(C5:C21),-MIN(C5:C21)) -> 0.00022440219 | D22: =IF(COUNTIF(D5:D21,"FAIL")=0,"ALL CHECKS OK","REVIEW FAILURES") -> ALL CHECKS OK
A24: A formula-error sweep is also run outside the workbook: the model is recalculated in full and every cell is scanned for reference, divide-by-zero, value, not-available and undefined-name errors, and for circular references. The model contains no circular references by design - see the note on interest in the Schedules sheet, section 4.
A26: B. MOLECULE TABLE - IDENTIFIED COMMERCIAL AND LATE-STAGE PROGRAMMES
A27: Sai Life Sciences does not disclose molecule names, innovator customers, indications or molecule-level economics, and management explicitly declined to name molecules or clients on the Q4FY26 earnings call. No name has been invented. The revenue model therefore does NOT attempt a bottom-up build of individual molecules - it uses the four portfolio buckets the company actually reports counts for, each as count x revenue per programme, with a single memo line for top-4 concentration. The table below records what IS disclosed and states plainly what is not.
A28: Bucket | B28: Innovator / customer | C28: Indication | D28: Stage | E28: Regulatory status | F28: Innovator sales / TAM | G28: Basis of the estimate in this model | H28: Confidence
A29: Bucket 1 - Base commercial portfolio | B29: 19 of the top 25 global pharma companies are customers; no customer is named | C29: Oncology 15%, metabolic 15%, infectious disease 16%, CNS 25% of CDMO revenue in FY26 | D29: Commercial - the 34 molecules already commercial at FY2026 | E29: USFDA and PMDA approved sites; 100% inspection track record | F29: Not identifiable | G29: Modelled as molecule count x revenue per molecule. Implied FY26 revenue per molecule of ~INR 243mn (FY24 220, FY25 201 - the FY25 dip is the disclosed destocking on a commercial intermediate). The pool rolls forward on exits only. The top-4 share is carried as a single memo line at 40% of commercial revenue, anchored on disclosed FY26 concentration: top-1 customer 12% of group revenue, top-5 37%, top-10 54%. | H29: MEDIUM on the bucket / LOW on the top-4 split
A30: Bucket 2 - New commercial launches | B30: Two additional large-pharma commercial supply qualifications received in FY26 | C30: Predominantly small molecule; management identified one new-modality asset in validation | D30: Commercial - molecules qualified from FY2027 onward | E30: Validation batches then commercial campaigns | F30: Not identifiable | G30: Modelled as cumulative launches x a blended revenue per new molecule that rises as the cohort seasons (INR ~130mn in year one to INR ~540mn at maturity). Management: of the four molecules added in FY26, three should show a 'pretty decent revenue growth trajectory' from FY27. | H30: MEDIUM
A31: Bucket 3 - Late-stage development | B31: Includes large-pharma late-phase work newly transferred to India | C31: Broad; mostly small molecule | D31: Phase III / pre-registration - 11 molecules at FY26, 6 at FY25 | E31: Validation and registration activity underway | F31: Not identifiable | G31: Modelled as programme count x INR 130mn per programme in FY26, escalating 6% p.a. Covers late-phase process development, validation batches, registration and pre-launch supply. | H31: MEDIUM
A32: Bucket 4 - Early phase, process R&D and tech transfer | B32: 300+ active customers; 200+ discovery clients | C32: Broad; 10+ therapy areas | D32: Pre-clinical, Phase I and Phase II - 155 programmes at FY26, 160 at FY25 | E32: Clinical supply under GMP where applicable | F32: Not identifiable | G32: Modelled as programme count x INR ~28.8mn per programme in FY26, escalating 7.5% p.a. Also carries site-to-site technology transfer and the dedicated large-pharma development FTE teams management flagged on the Q4FY26 call. | H32: MEDIUM
A33: New modalities (memo only) | B33: Not disclosed | C33: Peptides, ADC payloads and linkers, oligonucleotide amidites, lipids | D33: Mostly discovery and clinical, not commercial | E33: Peptide process and pilot plants commissioning Sep-26; OEB-6 labs for ADCs | F33: Not identifiable | G33: Tracked as a memo percentage of group revenue: 4% FY22, 3% FY23, 3% FY24, 7% FY25, 4% FY26. Lumpy because the work is campaign-driven. Does NOT drive revenue in the model. | H33: REPORTED (percentage only)
A35: C. ASSUMPTION LOG (classification of every material input)
A36: Area | B36: Assumption | C36: Classification | D36: Basis
A37: Historical financials | B37: FY2024, FY2025 and FY2026 consolidated P&L, balance sheet and cash flow | C37: REPORTED FACT | D37: FY25 Annual Report; audited FY26 consolidated results filed 14-May-2026
A38: Segment revenue | B38: CRO and CDMO revenue for FY2022-FY2026 | C38: REPORTED FACT | D38: Q4FY26 investor presentation pages 21 and 24
A39: Employees | B39: FY2025 3,401 employees and 2,605 scientists; FY2026 3,800+ | C39: REPORTED FACT | D39: FY25 Annual Report pages 6, 33 and 60; Q4FY26 deck page 15
A40: Employees | B40: FY2024 headcount of 3,345 | C40: ANALYST ESTIMATE | D40: Derived from FY24 employee cost divided by FY25 average cost deflated by the disclosed 9.12% salary increase
A41: Scientist allocation | B41: 55% of scientists allocated to Discovery | C41: ANALYST ASSUMPTION | D41: Not disclosed; management declined the split on the Q4FY26 call. Calibrated to a credible FTE rate card
A42: CRO utilisation | B42: 80% to 85% billable ratio | C42: ANALYST ASSUMPTION | D42: Not disclosed. Implies a revenue per billable FTE of ~USD 70k in FY26, inside observed Indian rate cards
A43: Capacity | B43: 700 KL at FY2026, 925 KL at FY2027, 1,150 KL at FY2028 | C43: REPORTED / GUIDED | D43: Q3FY26 deck page 27; Q4FY26 call - 225 KL this year and 225 KL next year
A44: Capacity | B44: Second Hyderabad site adds 200 KL in FY2030 and 250 KL in FY2033 | C44: ANALYST ASSUMPTION | D44: Management has confirmed a second Hyderabad site but has not sized or dated it
...
