Workbook

Sheet Revenue Model
A2: Pfizer Limited bottoms-up revenue model
A3: INR million. FY23-FY26 are historical estimates reconciled to reported totals. FY27 Q1 is reported at company level and estimated by product.
S4: Blue: hardcodes | T4: Black: formulas | U4: Green: cross-sheet
A6: Company revenue summary
A7: Therapy / line item | B7: Brand | C7: FY23A | D7: FY24A | E7: FY25A | F7: FY26A | G7: Q1 FY27 | H7: Q2 FY27E | I7: Q3 FY27E | J7: Q4 FY27E | K7: FY27E | L7: Q1 FY28E | M7: Q2 FY28E | N7: Q3 FY28E | O7: Q4 FY28E | P7: FY28E | Q7: FY29E | R7: FY30E | S7: FY31E | T7: FY32E | U7: FY33E | V7: FY34E | W7: FY35E
A8: Product revenue | C8: =C81 -> 23376.3 | D8: =D81 -> 20810.4 | E8: =E81 -> 21283.6 | F8: =F81 -> 23771.1 | G8: =G81 -> 6175.35 | H8: =H81 -> 6277.5878 | I8: =I81 -> 6016.672 | J8: =J81 -> 6142.8538 | ... W8: =W81 -> 44680.883
A9: Service revenue | C9: =C83 -> 846.9 | D9: =D83 -> 1116.5 | E9: =E83 -> 1526.4 | F9: =F83 -> 1421.6 | G9: =G83 -> 355.4 | H9: =H83 -> 355.4 | I9: =I83 -> 355.4 | J9: =J83 -> 355.4 | ... W9: =W83 -> 1421.6
A10: Other operating revenue | C10: =C84 -> 24.4 | D10: =D84 -> 4.8 | E10: =E84 -> 3.5 | F10: =F84 -> 3.8 | G10: =G84 -> 0.95 | H10: =H84 -> 0.95 | I10: =I84 -> 0.95 | J10: =J84 -> 0.95 | ... W10: =W84 -> 3.8
A11: Revenue from operations | C11: =C85 -> 24247.6 | D11: =D85 -> 21931.7 | E11: =E85 -> 22813.5 | F11: =F85 -> 25196.5 | G11: =G85 -> 6531.7 | H11: =H85 -> 6633.9378 | I11: =I85 -> 6373.022 | J11: =J85 -> 6499.2038 | ... W11: =W85 -> 46106.283
A12: Growth | D12: =D11/C11-1 -> -0.095510484 | E12: =E11/D11-1 -> 0.040206642 | F12: =F11/E11-1 -> 0.1044557 | K12: =K11/F11-1 -> 0.033392081 | P12: =P11/K11-1 -> 0.05652046 | Q12: =Q11/P11-1 -> 0.10384958 | R12: =R11/Q11-1 -> 0.11444217 | S12: =S11/R11-1 -> 0.063270599 | T12: =T11/S11-1 -> 0.063624621 | U12: =U11/T11-1 -> 0.063215444 | V12: =V11/U11-1 -> 0.063274806 | W12: =W11/V11-1 -> 0.065639787
A15: Product revenue by therapy and brand
A16: Therapy / line item | B16: Brand | C16: FY23A | D16: FY24A | E16: FY25A | F16: FY26A | G16: Q1 FY27 | H16: Q2 FY27E | I16: Q3 FY27E | J16: Q4 FY27E | K16: FY27E | L16: Q1 FY28E | M16: Q2 FY28E | N16: Q3 FY28E | O16: Q4 FY28E | P16: FY28E | Q16: FY29E | R16: FY30E | S16: FY31E | T16: FY32E | U16: FY33E | V16: FY34E | W16: FY35E
A17: Vaccines
B18: Prevenar 13 | C18: 2350 | D18: 2450 | E18: 2600 | F18: 2760 | G18: =Assumptions!$G$16 -> 681.46069 | H18: =(($F18*(1+Assumptions!$C$16)*Assumptions!$E$16)-$G18)*Assumptions!$J$16/SUM(Assumptions!$J$16:$L$16) -> 636.88311 | I18: =(($F18*(1+Assumptions!$C$16)*Assumptions!$E$16)-$G18)*Assumptions!$K$16/SUM(Assumptions!$J$16:$L$16) -> 692.26425 | J18: =(($F18*(1+Assumptions!$C$16)*Assumptions!$E$16)-$G18)*Assumptions!$L$16/SUM(Assumptions!$J$16:$L$16) -> 775.33596 | K18: =SUM(G18:J18) -> 2785.944 | L18: =($K18*(1+Assumptions!$C$16)*Assumptions!$F$16)*Assumptions!$I$16 -> 674.91165 | M18: =($K18*(1+Assumptions!$C$16)*Assumptions!$F$16)*Assumptions!$J$16 -> 646.79033 | N18: =($K18*(1+Assumptions!$C$16)*Assumptions!$F$16)*Assumptions!$K$16 -> 703.03297 | O18: =($K18*(1+Assumptions!$C$16)*Assumptions!$F$16)*Assumptions!$L$16 -> 787.39692 | P18: =SUM(L18:O18) -> 2812.1319 | Q18: =$P18*(1+Assumptions!$C$16)*Assumptions!$F$16 -> 2838.5659 | R18: =$Q18*(1+Assumptions!$C$16)*Assumptions!$F$16 -> 2865.2484 | S18: =$R18*(1+Assumptions!$D$16)*Assumptions!$F$16 -> 2819.4045 | T18: =$S18*(1+Assumptions!$D$16)*Assumptions!$F$16 -> 2774.294 | U18: =$T18*(1+Assumptions!$D$16)*Assumptions!$F$16 -> 2729.9053 | V18: =$U18*(1+Assumptions!$D$16)*Assumptions!$F$16 -> 2686.2268 | W18: =$V18*(1+Assumptions!$D$16)*Assumptions!$F$16 -> 2643.2472
B19: Prevenar 20 | C19: 0 | D19: 0 | E19: 0 | F19: 820 | G19: =Assumptions!$G$17 -> 278.90306 | H19: =(($F19*(1+Assumptions!$C$17)*Assumptions!$E$17)-$G19)*Assumptions!$J$17/SUM(Assumptions!$J$17:$L$17) -> 260.65868 | I19: =(($F19*(1+Assumptions!$C$17)*Assumptions!$E$17)-$G19)*Assumptions!$K$17/SUM(Assumptions!$J$17:$L$17) -> 283.32465 | J19: =(($F19*(1+Assumptions!$C$17)*Assumptions!$E$17)-$G19)*Assumptions!$L$17/SUM(Assumptions!$J$17:$L$17) -> 317.32361 | K19: =SUM(G19:J19) -> 1140.21 | L19: =($K19*(1+Assumptions!$C$17)*Assumptions!$F$17)*Assumptions!$I$17 -> 380.51088 | M19: =($K19*(1+Assumptions!$C$17)*Assumptions!$F$17)*Assumptions!$J$17 -> 364.65626 | N19: =($K19*(1+Assumptions!$C$17)*Assumptions!$F$17)*Assumptions!$K$17 -> 396.3655 | O19: =($K19*(1+Assumptions!$C$17)*Assumptions!$F$17)*Assumptions!$L$17 -> 443.92936 | P19: =SUM(L19:O19) -> 1585.462 | Q19: =$P19*(1+Assumptions!$C$17)*Assumptions!$F$17 -> 2204.5849 | R19: =$Q19*(1+Assumptions!$C$17)*Assumptions!$F$17 -> 3065.4753 | S19: =$R19*(1+Assumptions!$D$17)*Assumptions!$F$17 -> 3519.1657 | T19: =$S19*(1+Assumptions!$D$17)*Assumptions!$F$17 -> 4040.0022 | U19: =$T19*(1+Assumptions!$D$17)*Assumptions!$F$17 -> 4637.9225 | V19: =$U19*(1+Assumptions!$D$17)*Assumptions!$F$17 -> 5324.3351 | W19: =$V19*(1+Assumptions!$D$17)*Assumptions!$F$17 -> 6112.3366
B20: Other vaccines | C20: 130 | D20: 125 | E20: 120 | F20: 120 | G20: =Assumptions!$G$18 -> 30.838061 | H20: =(($F20*(1+Assumptions!$C$18)*Assumptions!$E$18)-$G20)*Assumptions!$J$18/SUM(Assumptions!$J$18:$L$18) -> 28.820797 | I20: =(($F20*(1+Assumptions!$C$18)*Assumptions!$E$18)-$G20)*Assumptions!$K$18/SUM(Assumptions!$J$18:$L$18) -> 31.326953 | J20: =(($F20*(1+Assumptions!$C$18)*Assumptions!$E$18)-$G20)*Assumptions!$L$18/SUM(Assumptions!$J$18:$L$18) -> 35.086188 | K20: =SUM(G20:J20) -> 126.072 | L20: =($K20*(1+Assumptions!$C$18)*Assumptions!$F$18)*Assumptions!$I$18 -> 31.788298 | M20: =($K20*(1+Assumptions!$C$18)*Assumptions!$F$18)*Assumptions!$J$18 -> 30.463786 | N20: =($K20*(1+Assumptions!$C$18)*Assumptions!$F$18)*Assumptions!$K$18 -> 33.112811 | O20: =($K20*(1+Assumptions!$C$18)*Assumptions!$F$18)*Assumptions!$L$18 -> 37.086348 | P20: =SUM(L20:O20) -> 132.45124 | Q20: =$P20*(1+Assumptions!$C$18)*Assumptions!$F$18 -> 139.15328 | R20: =$Q20*(1+Assumptions!$C$18)*Assumptions!$F$18 -> 146.19443 | S20: =$R20*(1+Assumptions!$D$18)*Assumptions!$F$18 -> 151.34779 | T20: =$S20*(1+Assumptions!$D$18)*Assumptions!$F$18 -> 156.6828 | U20: =$T20*(1+Assumptions!$D$18)*Assumptions!$F$18 -> 162.20586 | V20: =$U20*(1+Assumptions!$D$18)*Assumptions!$F$18 -> 167.92362 | W20: =$V20*(1+Assumptions!$D$18)*Assumptions!$F$18 -> 173.84293
B21: Abrysvo (pipeline) | C21: 0 | D21: 0 | E21: 0 | F21: 0 | G21: 0 | H21: 0 | I21: 0 | J21: 0 | K21: 0 | L21: 0 | M21: 0 | N21: 0 | O21: 0 | P21: 0 | Q21: =Assumptions!$C$72*Assumptions!$D$72 -> 162 | R21: =Assumptions!$C$72*Assumptions!$E$72 -> 364.5 | S21: =Assumptions!$C$72*Assumptions!$F$72 -> 567 | T21: =Assumptions!$C$72*Assumptions!$G$72 -> 729 | U21: =Assumptions!$C$72*Assumptions!$H$72 -> 810 | V21: =Assumptions!$C$72*Assumptions!$I$72 -> 810 | W21: =Assumptions!$C$72*Assumptions!$J$72 -> 810
A22: Vaccines | B22: Subtotal | C22: =SUM(C18:C21) -> 2480 | D22: =SUM(D18:D21) -> 2575 | E22: =SUM(E18:E21) -> 2720 | F22: =SUM(F18:F21) -> 3700 | G22: =SUM(G18:G21) -> 991.20181 | H22: =SUM(H18:H21) -> 926.36258 | I22: =SUM(I18:I21) -> 1006.9159 | J22: =SUM(J18:J21) -> 1127.7458 | ... W22: =SUM(W18:W21) -> 9739.4267
A24: Anti-infectives and hospital products
B25: Magnex | C25: 1700 | D25: 650 | E25: 1050 | F25: 1400 | G25: =Assumptions!$G$20 -> 379.09153 | H25: =(($F25*(1+Assumptions!$C$20)*Assumptions!$E$20)-$G25)*Assumptions!$J$20/SUM(Assumptions!$J$20:$L$20) -> 385.10147 | I25: =(($F25*(1+Assumptions!$C$20)*Assumptions!$E$20)-$G25)*Assumptions!$K$20/SUM(Assumptions!$J$20:$L$20) -> 385.10147 | J25: =(($F25*(1+Assumptions!$C$20)*Assumptions!$E$20)-$G25)*Assumptions!$L$20/SUM(Assumptions!$J$20:$L$20) -> 400.50553 | K25: =SUM(G25:J25) -> 1549.8 | L25: =($K25*(1+Assumptions!$C$20)*Assumptions!$F$20)*Assumptions!$I$20 -> 411.75086 | M25: =($K25*(1+Assumptions!$C$20)*Assumptions!$F$20)*Assumptions!$J$20 -> 428.90715 | N25: =($K25*(1+Assumptions!$C$20)*Assumptions!$F$20)*Assumptions!$K$20 -> 428.90715 | O25: =($K25*(1+Assumptions!$C$20)*Assumptions!$F$20)*Assumptions!$L$20 -> 446.06344 | P25: =SUM(L25:O25) -> 1715.6286 | Q25: =$P25*(1+Assumptions!$C$20)*Assumptions!$F$20 -> 1899.2009 | R25: =$Q25*(1+Assumptions!$C$20)*Assumptions!$F$20 -> 2102.4154 | S25: =$R25*(1+Assumptions!$D$20)*Assumptions!$F$20 -> 2251.6868 | T25: =$S25*(1+Assumptions!$D$20)*Assumptions!$F$20 -> 2411.5566 | U25: =$T25*(1+Assumptions!$D$20)*Assumptions!$F$20 -> 2582.7771 | V25: =$U25*(1+Assumptions!$D$20)*Assumptions!$F$20 -> 2766.1543 | W25: =$V25*(1+Assumptions!$D$20)*Assumptions!$F$20 -> 2962.5513
B26: Meronem | C26: 880 | D26: 820 | E26: 870 | F26: 920 | G26: =Assumptions!$G$21 -> 242.19737 | H26: =(($F26*(1+Assumptions!$C$21)*Assumptions!$E$21)-$G26)*Assumptions!$J$21/SUM(Assumptions!$J$21:$L$21) -> 246.03705 | I26: =(($F26*(1+Assumptions!$C$21)*Assumptions!$E$21)-$G26)*Assumptions!$K$21/SUM(Assumptions!$J$21:$L$21) -> 246.03705 | J26: =(($F26*(1+Assumptions!$C$21)*Assumptions!$E$21)-$G26)*Assumptions!$L$21/SUM(Assumptions!$J$21:$L$21) -> 255.87853 | K26: =SUM(G26:J26) -> 990.15 | L26: =($K26*(1+Assumptions!$C$21)*Assumptions!$F$21)*Assumptions!$I$21 -> 255.75575 | M26: =($K26*(1+Assumptions!$C$21)*Assumptions!$F$21)*Assumptions!$J$21 -> 266.41223 | N26: =($K26*(1+Assumptions!$C$21)*Assumptions!$F$21)*Assumptions!$K$21 -> 266.41223 | O26: =($K26*(1+Assumptions!$C$21)*Assumptions!$F$21)*Assumptions!$L$21 -> 277.06872 | P26: =SUM(L26:O26) -> 1065.6489 | Q26: =$P26*(1+Assumptions!$C$21)*Assumptions!$F$21 -> 1146.9047 | R26: =$Q26*(1+Assumptions!$C$21)*Assumptions!$F$21 -> 1234.3561 | S26: =$R26*(1+Assumptions!$D$21)*Assumptions!$F$21 -> 1296.8146 | T26: =$S26*(1+Assumptions!$D$21)*Assumptions!$F$21 -> 1362.4334 | U26: =$T26*(1+Assumptions!$D$21)*Assumptions!$F$21 -> 1431.3725 | V26: =$U26*(1+Assumptions!$D$21)*Assumptions!$F$21 -> 1503.8 | W26: =$V26*(1+Assumptions!$D$21)*Assumptions!$F$21 -> 1579.8922
B27: Zavicefta | C27: 650 | D27: 720 | E27: 800 | F27: 880 | G27: =Assumptions!$G$22 -> 238.28611 | H27: =(($F27*(1+Assumptions!$C$22)*Assumptions!$E$22)-$G27)*Assumptions!$J$22/SUM(Assumptions!$J$22:$L$22) -> 242.06378 | I27: =(($F27*(1+Assumptions!$C$22)*Assumptions!$E$22)-$G27)*Assumptions!$K$22/SUM(Assumptions!$J$22:$L$22) -> 242.06378 | J27: =(($F27*(1+Assumptions!$C$22)*Assumptions!$E$22)-$G27)*Assumptions!$L$22/SUM(Assumptions!$J$22:$L$22) -> 251.74633 | K27: =SUM(G27:J27) -> 974.16 | L27: =($K27*(1+Assumptions!$C$22)*Assumptions!$F$22)*Assumptions!$I$22 -> 258.81483 | M27: =($K27*(1+Assumptions!$C$22)*Assumptions!$F$22)*Assumptions!$J$22 -> 269.59878 | N27: =($K27*(1+Assumptions!$C$22)*Assumptions!$F$22)*Assumptions!$K$22 -> 269.59878 | O27: =($K27*(1+Assumptions!$C$22)*Assumptions!$F$22)*Assumptions!$L$22 -> 280.38273 | P27: =SUM(L27:O27) -> 1078.3951 | Q27: =$P27*(1+Assumptions!$C$22)*Assumptions!$F$22 -> 1193.7834 | R27: =$Q27*(1+Assumptions!$C$22)*Assumptions!$F$22 -> 1321.5182 | S27: =$R27*(1+Assumptions!$D$22)*Assumptions!$F$22 -> 1415.346 | T27: =$S27*(1+Assumptions!$D$22)*Assumptions!$F$22 -> 1515.8356 | U27: =$T27*(1+Assumptions!$D$22)*Assumptions!$F$22 -> 1623.4599 | V27: =$U27*(1+Assumptions!$D$22)*Assumptions!$F$22 -> 1738.7256 | W27: =$V27*(1+Assumptions!$D$22)*Assumptions!$F$22 -> 1862.1751
B28: Zithromax | C28: 350 | D28: 330 | E28: 315 | F28: 300 | G28: =Assumptions!$G$23 -> 75.216574 | H28: =(($F28*(1+Assumptions!$C$23)*Assumptions!$E$23)-$G28)*Assumptions!$J$23/SUM(Assumptions!$J$23:$L$23) -> 76.409022 | I28: =(($F28*(1+Assumptions!$C$23)*Assumptions!$E$23)-$G28)*Assumptions!$K$23/SUM(Assumptions!$J$23:$L$23) -> 76.409022 | J28: =(($F28*(1+Assumptions!$C$23)*Assumptions!$E$23)-$G28)*Assumptions!$L$23/SUM(Assumptions!$J$23:$L$23) -> 79.465383 | K28: =SUM(G28:J28) -> 307.5 | L28: =($K28*(1+Assumptions!$C$23)*Assumptions!$F$23)*Assumptions!$I$23 -> 75.645 | M28: =($K28*(1+Assumptions!$C$23)*Assumptions!$F$23)*Assumptions!$J$23 -> 78.796875 | N28: =($K28*(1+Assumptions!$C$23)*Assumptions!$F$23)*Assumptions!$K$23 -> 78.796875 | O28: =($K28*(1+Assumptions!$C$23)*Assumptions!$F$23)*Assumptions!$L$23 -> 81.94875 | P28: =SUM(L28:O28) -> 315.1875 | Q28: =$P28*(1+Assumptions!$C$23)*Assumptions!$F$23 -> 323.06719 | R28: =$Q28*(1+Assumptions!$C$23)*Assumptions!$F$23 -> 331.14387 | S28: =$R28*(1+Assumptions!$D$23)*Assumptions!$F$23 -> 331.01141 | T28: =$S28*(1+Assumptions!$D$23)*Assumptions!$F$23 -> 330.87901 | U28: =$T28*(1+Assumptions!$D$23)*Assumptions!$F$23 -> 330.74665 | V28: =$U28*(1+Assumptions!$D$23)*Assumptions!$F$23 -> 330.61435 | W28: =$V28*(1+Assumptions!$D$23)*Assumptions!$F$23 -> 330.48211
B29: Emblaveo | C29: 0 | D29: 0 | E29: 0 | F29: 180 | G29: =Assumptions!$G$24 -> 65.438419 | H29: =(($F29*(1+Assumptions!$C$24)*Assumptions!$E$24)-$G29)*Assumptions!$J$24/SUM(Assumptions!$J$24:$L$24) -> 66.475849 | I29: =(($F29*(1+Assumptions!$C$24)*Assumptions!$E$24)-$G29)*Assumptions!$K$24/SUM(Assumptions!$J$24:$L$24) -> 66.475849 | J29: =(($F29*(1+Assumptions!$C$24)*Assumptions!$E$24)-$G29)*Assumptions!$L$24/SUM(Assumptions!$J$24:$L$24) -> 69.134883 | K29: =SUM(G29:J29) -> 267.525 | L29: =($K29*(1+Assumptions!$C$24)*Assumptions!$F$24)*Assumptions!$I$24 -> 95.426167 | M29: =($K29*(1+Assumptions!$C$24)*Assumptions!$F$24)*Assumptions!$J$24 -> 99.402258 | N29: =($K29*(1+Assumptions!$C$24)*Assumptions!$F$24)*Assumptions!$K$24 -> 99.402258 | O29: =($K29*(1+Assumptions!$C$24)*Assumptions!$F$24)*Assumptions!$L$24 -> 103.37835 | P29: =SUM(L29:O29) -> 397.60903 | Q29: =$P29*(1+Assumptions!$C$24)*Assumptions!$F$24 -> 590.94642 | R29: =$Q29*(1+Assumptions!$C$24)*Assumptions!$F$24 -> 878.29412 | S29: =$R29*(1+Assumptions!$D$24)*Assumptions!$F$24 -> 1030.239 | T29: =$S29*(1+Assumptions!$D$24)*Assumptions!$F$24 -> 1208.4704 | U29: =$T29*(1+Assumptions!$D$24)*Assumptions!$F$24 -> 1417.5357 | V29: =$U29*(1+Assumptions!$D$24)*Assumptions!$F$24 -> 1662.7694 | W29: =$V29*(1+Assumptions!$D$24)*Assumptions!$F$24 -> 1950.4285
B30: Other hospital and anti-infective products | C30: 680 | D30: 480 | E30: 540 | F30: 600 | G30: =Assumptions!$G$25 -> 154.94614 | H30: =(($F30*(1+Assumptions!$C$25)*Assumptions!$E$25)-$G30)*Assumptions!$J$25/SUM(Assumptions!$J$25:$L$25) -> 157.40258 | I30: =(($F30*(1+Assumptions!$C$25)*Assumptions!$E$25)-$G30)*Assumptions!$K$25/SUM(Assumptions!$J$25:$L$25) -> 157.40258 | J30: =(($F30*(1+Assumptions!$C$25)*Assumptions!$E$25)-$G30)*Assumptions!$L$25/SUM(Assumptions!$J$25:$L$25) -> 163.69869 | K30: =SUM(G30:J30) -> 633.45 | L30: =($K30*(1+Assumptions!$C$25)*Assumptions!$F$25)*Assumptions!$I$25 -> 160.50356 | M30: =($K30*(1+Assumptions!$C$25)*Assumptions!$F$25)*Assumptions!$J$25 -> 167.19121 | N30: =($K30*(1+Assumptions!$C$25)*Assumptions!$F$25)*Assumptions!$K$25 -> 167.19121 | O30: =($K30*(1+Assumptions!$C$25)*Assumptions!$F$25)*Assumptions!$L$25 -> 173.87886 | P30: =SUM(L30:O30) -> 668.76484 | Q30: =$P30*(1+Assumptions!$C$25)*Assumptions!$F$25 -> 706.04848 | R30: =$Q30*(1+Assumptions!$C$25)*Assumptions!$F$25 -> 745.41068 | S30: =$R30*(1+Assumptions!$D$25)*Assumptions!$F$25 -> 775.52527 | T30: =$S30*(1+Assumptions!$D$25)*Assumptions!$F$25 -> 806.85649 | U30: =$T30*(1+Assumptions!$D$25)*Assumptions!$F$25 -> 839.45349 | V30: =$U30*(1+Assumptions!$D$25)*Assumptions!$F$25 -> 873.36742 | W30: =$V30*(1+Assumptions!$D$25)*Assumptions!$F$25 -> 908.65146
A31: Anti-infectives and hospital products | B31: Subtotal | C31: =SUM(C25:C30) -> 4260 | D31: =SUM(D25:D30) -> 3000 | E31: =SUM(E25:E30) -> 3575 | F31: =SUM(F25:F30) -> 4280 | G31: =SUM(G25:G30) -> 1155.1761 | H31: =SUM(H25:H30) -> 1173.4898 | I31: =SUM(I25:I30) -> 1173.4898 | J31: =SUM(J25:J30) -> 1220.4293 | ... W31: =SUM(W25:W30) -> 9594.1807
A33: Cardiovascular and anticoagulation
B34: Eliquis | C34: 1150 | D34: 1300 | E34: 1446 | F34: 1880 | G34: =Assumptions!$G$26 -> 527.92006 | H34: =(($F34*(1+Assumptions!$C$26)*Assumptions!$E$26)-$G34)*Assumptions!$J$26/SUM(Assumptions!$J$26:$L$26) -> 536.28945 | I34: =(($F34*(1+Assumptions!$C$26)*Assumptions!$E$26)-$G34)*Assumptions!$K$26/SUM(Assumptions!$J$26:$L$26) -> 536.28945 | J34: =(($F34*(1+Assumptions!$C$26)*Assumptions!$E$26)-$G34)*Assumptions!$L$26/SUM(Assumptions!$J$26:$L$26) -> 557.74103 | K34: =SUM(G34:J34) -> 2158.24 | L34: =($K34*(1+Assumptions!$C$26)*Assumptions!$F$26)*Assumptions!$I$26 -> 594.63828 | M34: =($K34*(1+Assumptions!$C$26)*Assumptions!$F$26)*Assumptions!$J$26 -> 619.41488 | N34: =($K34*(1+Assumptions!$C$26)*Assumptions!$F$26)*Assumptions!$K$26 -> 619.41488 | O34: =($K34*(1+Assumptions!$C$26)*Assumptions!$F$26)*Assumptions!$L$26 -> 644.19148 | P34: =SUM(L34:O34) -> 2477.6595 | Q34: =$P34*(1+Assumptions!$C$26)*Assumptions!$F$26 -> 2844.3531 | R34: =$Q34*(1+Assumptions!$C$26)*Assumptions!$F$26 -> 3265.3174 | S34: =$R34*(1+Assumptions!$D$26)*Assumptions!$F$26 -> 3530.4612 | T34: =$S34*(1+Assumptions!$D$26)*Assumptions!$F$26 -> 3817.1346 | U34: =$T34*(1+Assumptions!$D$26)*Assumptions!$F$26 -> 4127.0859 | V34: =$U34*(1+Assumptions!$D$26)*Assumptions!$F$26 -> 4462.2053 | W34: =$V34*(1+Assumptions!$D$26)*Assumptions!$F$26 -> 4824.5364
B35: Minipress XL | C35: 1400 | D35: 1500 | E35: 1600 | F35: 1725 | G35: =Assumptions!$G$27 -> 445.47016 | H35: =(($F35*(1+Assumptions!$C$27)*Assumptions!$E$27)-$G35)*Assumptions!$J$27/SUM(Assumptions!$J$27:$L$27) -> 341.46914 | I35: =(($F35*(1+Assumptions!$C$27)*Assumptions!$E$27)-$G35)*Assumptions!$K$27/SUM(Assumptions!$J$27:$L$27) -> 0 | J35: =(($F35*(1+Assumptions!$C$27)*Assumptions!$E$27)-$G35)*Assumptions!$L$27/SUM(Assumptions!$J$27:$L$27) -> 0 | K35: =SUM(G35:J35) -> 786.9393 | L35: =($K35*(1+Assumptions!$C$27)*Assumptions!$F$27)*Assumptions!$I$27 -> 0 | M35: =($K35*(1+Assumptions!$C$27)*Assumptions!$F$27)*Assumptions!$J$27 -> 0 | N35: =($K35*(1+Assumptions!$C$27)*Assumptions!$F$27)*Assumptions!$K$27 -> 0 | O35: =($K35*(1+Assumptions!$C$27)*Assumptions!$F$27)*Assumptions!$L$27 -> 0 | P35: =SUM(L35:O35) -> 0 | Q35: =$P35*(1+Assumptions!$C$27)*Assumptions!$F$27 -> 0 | R35: =$Q35*(1+Assumptions!$C$27)*Assumptions!$F$27 -> 0 | S35: =$R35*(1+Assumptions!$D$27)*Assumptions!$F$27 -> 0 | T35: =$S35*(1+Assumptions!$D$27)*Assumptions!$F$27 -> 0 | U35: =$T35*(1+Assumptions!$D$27)*Assumptions!$F$27 -> 0 | V35: =$U35*(1+Assumptions!$D$27)*Assumptions!$F$27 -> 0 | W35: =$V35*(1+Assumptions!$D$27)*Assumptions!$F$27 -> 0
B36: Amlogard | C36: 250 | D36: 0 | E36: 0 | F36: 0 | G36: =Assumptions!$G$28 -> 0 | H36: =(($F36*(1+Assumptions!$C$28)*Assumptions!$E$28)-$G36)*Assumptions!$J$28/SUM(Assumptions!$J$28:$L$28) -> 0 | I36: =(($F36*(1+Assumptions!$C$28)*Assumptions!$E$28)-$G36)*Assumptions!$K$28/SUM(Assumptions!$J$28:$L$28) -> 0 | J36: =(($F36*(1+Assumptions!$C$28)*Assumptions!$E$28)-$G36)*Assumptions!$L$28/SUM(Assumptions!$J$28:$L$28) -> 0 | K36: =SUM(G36:J36) -> 0 | L36: =($K36*(1+Assumptions!$C$28)*Assumptions!$F$28)*Assumptions!$I$28 -> 0 | M36: =($K36*(1+Assumptions!$C$28)*Assumptions!$F$28)*Assumptions!$J$28 -> 0 | N36: =($K36*(1+Assumptions!$C$28)*Assumptions!$F$28)*Assumptions!$K$28 -> 0 | O36: =($K36*(1+Assumptions!$C$28)*Assumptions!$F$28)*Assumptions!$L$28 -> 0 | P36: =SUM(L36:O36) -> 0 | Q36: =$P36*(1+Assumptions!$C$28)*Assumptions!$F$28 -> 0 | R36: =$Q36*(1+Assumptions!$C$28)*Assumptions!$F$28 -> 0 | S36: =$R36*(1+Assumptions!$D$28)*Assumptions!$F$28 -> 0 | T36: =$S36*(1+Assumptions!$D$28)*Assumptions!$F$28 -> 0 | U36: =$T36*(1+Assumptions!$D$28)*Assumptions!$F$28 -> 0 | V36: =$U36*(1+Assumptions!$D$28)*Assumptions!$F$28 -> 0 | W36: =$V36*(1+Assumptions!$D$28)*Assumptions!$F$28 -> 0
B37: Other cardiovascular products | C37: 350 | D37: 320 | E37: 310 | F37: 300 | G37: =Assumptions!$G$29 -> 76.720905 | H37: =(($F37*(1+Assumptions!$C$29)*Assumptions!$E$29)-$G37)*Assumptions!$J$29/SUM(Assumptions!$J$29:$L$29) -> 77.937202 | I37: =(($F37*(1+Assumptions!$C$29)*Assumptions!$E$29)-$G37)*Assumptions!$K$29/SUM(Assumptions!$J$29:$L$29) -> 77.937202 | J37: =(($F37*(1+Assumptions!$C$29)*Assumptions!$E$29)-$G37)*Assumptions!$L$29/SUM(Assumptions!$J$29:$L$29) -> 81.05469 | K37: =SUM(G37:J37) -> 313.65 | L37: =($K37*(1+Assumptions!$C$29)*Assumptions!$F$29)*Assumptions!$I$29 -> 78.701058 | M37: =($K37*(1+Assumptions!$C$29)*Assumptions!$F$29)*Assumptions!$J$29 -> 81.980269 | N37: =($K37*(1+Assumptions!$C$29)*Assumptions!$F$29)*Assumptions!$K$29 -> 81.980269 | O37: =($K37*(1+Assumptions!$C$29)*Assumptions!$F$29)*Assumptions!$L$29 -> 85.259479 | P37: =SUM(L37:O37) -> 327.92107 | Q37: =$P37*(1+Assumptions!$C$29)*Assumptions!$F$29 -> 342.84148 | R37: =$Q37*(1+Assumptions!$C$29)*Assumptions!$F$29 -> 358.44077 | S37: =$R37*(1+Assumptions!$D$29)*Assumptions!$F$29 -> 369.26568 | T37: =$S37*(1+Assumptions!$D$29)*Assumptions!$F$29 -> 380.41751 | U37: =$T37*(1+Assumptions!$D$29)*Assumptions!$F$29 -> 391.90612 | V37: =$U37*(1+Assumptions!$D$29)*Assumptions!$F$29 -> 403.74168 | W37: =$V37*(1+Assumptions!$D$29)*Assumptions!$F$29 -> 415.93468
A38: Cardiovascular and anticoagulation | B38: Subtotal | C38: =SUM(C34:C37) -> 3150 | D38: =SUM(D34:D37) -> 3120 | E38: =SUM(E34:E37) -> 3356 | F38: =SUM(F34:F37) -> 3905 | G38: =SUM(G34:G37) -> 1050.1111 | H38: =SUM(H34:H37) -> 955.6958 | I38: =SUM(I34:I37) -> 614.22666 | J38: =SUM(J34:J37) -> 638.79572 | ... W38: =SUM(W34:W37) -> 5240.4711
A40: Vitamins and nutritional products
B41: Becosules | C41: 1900 | D41: 1980 | E41: 2100 | F41: 2230 | G41: =Assumptions!$G$30 -> 565.34871 | H41: =(($F41*(1+Assumptions!$C$30)*Assumptions!$E$30)-$G41)*Assumptions!$J$30/SUM(Assumptions!$J$30:$L$30) -> 623.45849 | I41: =(($F41*(1+Assumptions!$C$30)*Assumptions!$E$30)-$G41)*Assumptions!$K$30/SUM(Assumptions!$J$30:$L$30) -> 623.45849 | J41: =(($F41*(1+Assumptions!$C$30)*Assumptions!$E$30)-$G41)*Assumptions!$L$30/SUM(Assumptions!$J$30:$L$30) -> 599.47931 | K41: =SUM(G41:J41) -> 2411.745 | L41: =($K41*(1+Assumptions!$C$30)*Assumptions!$F$30)*Assumptions!$I$30 -> 599.90951 | M41: =($K41*(1+Assumptions!$C$30)*Assumptions!$F$30)*Assumptions!$J$30 -> 678.15858 | N41: =($K41*(1+Assumptions!$C$30)*Assumptions!$F$30)*Assumptions!$K$30 -> 678.15858 | O41: =($K41*(1+Assumptions!$C$30)*Assumptions!$F$30)*Assumptions!$L$30 -> 652.07555 | P41: =SUM(L41:O41) -> 2608.3022 | Q41: =$P41*(1+Assumptions!$C$30)*Assumptions!$F$30 -> 2820.8788 | R41: =$Q41*(1+Assumptions!$C$30)*Assumptions!$F$30 -> 3050.7805 | S41: =$R41*(1+Assumptions!$D$30)*Assumptions!$F$30 -> 3220.8615 | T41: =$S41*(1+Assumptions!$D$30)*Assumptions!$F$30 -> 3400.4245 | U41: =$T41*(1+Assumptions!$D$30)*Assumptions!$F$30 -> 3589.9982 | V41: =$U41*(1+Assumptions!$D$30)*Assumptions!$F$30 -> 3790.1406 | W41: =$V41*(1+Assumptions!$D$30)*Assumptions!$F$30 -> 4001.4409
B42: Other nutritional products | C42: 170 | D42: 160 | E42: 155 | F42: 150 | G42: =Assumptions!$G$31 -> 36.941428 | H42: =(($F42*(1+Assumptions!$C$31)*Assumptions!$E$31)-$G42)*Assumptions!$J$31/SUM(Assumptions!$J$31:$L$31) -> 40.738479 | I42: =(($F42*(1+Assumptions!$C$31)*Assumptions!$E$31)-$G42)*Assumptions!$K$31/SUM(Assumptions!$J$31:$L$31) -> 40.738479 | J42: =(($F42*(1+Assumptions!$C$31)*Assumptions!$E$31)-$G42)*Assumptions!$L$31/SUM(Assumptions!$J$31:$L$31) -> 39.171614 | K42: =SUM(G42:J42) -> 157.59 | L42: =($K42*(1+Assumptions!$C$31)*Assumptions!$F$31)*Assumptions!$I$31 -> 38.079732 | M42: =($K42*(1+Assumptions!$C$31)*Assumptions!$F$31)*Assumptions!$J$31 -> 43.046654 | N42: =($K42*(1+Assumptions!$C$31)*Assumptions!$F$31)*Assumptions!$K$31 -> 43.046654 | O42: =($K42*(1+Assumptions!$C$31)*Assumptions!$F$31)*Assumptions!$L$31 -> 41.391014 | P42: =SUM(L42:O42) -> 165.56405 | Q42: =$P42*(1+Assumptions!$C$31)*Assumptions!$F$31 -> 173.9416 | R42: =$Q42*(1+Assumptions!$C$31)*Assumptions!$F$31 -> 182.74304 | S42: =$R42*(1+Assumptions!$D$31)*Assumptions!$F$31 -> 189.18473 | T42: =$S42*(1+Assumptions!$D$31)*Assumptions!$F$31 -> 195.85349 | U42: =$T42*(1+Assumptions!$D$31)*Assumptions!$F$31 -> 202.75733 | V42: =$U42*(1+Assumptions!$D$31)*Assumptions!$F$31 -> 209.90453 | W42: =$V42*(1+Assumptions!$D$31)*Assumptions!$F$31 -> 217.30366
A43: Vitamins and nutritional products | B43: Subtotal | C43: =SUM(C41:C42) -> 2070 | D43: =SUM(D41:D42) -> 2140 | E43: =SUM(E41:E42) -> 2255 | F43: =SUM(F41:F42) -> 2380 | G43: =SUM(G41:G42) -> 602.29014 | H43: =SUM(H41:H42) -> 664.19697 | I43: =SUM(I41:I42) -> 664.19697 | J43: =SUM(J41:J42) -> 638.65093 | ... W43: =SUM(W41:W42) -> 4218.7446
A45: Gastrointestinal
B46: Mucaine | C46: 1100 | D46: 1150 | E46: 1220 | F46: 1310 | G46: =Assumptions!$G$32 -> 332.11068 | H46: =(($F46*(1+Assumptions!$C$32)*Assumptions!$E$32)-$G46)*Assumptions!$J$32/SUM(Assumptions!$J$32:$L$32) -> 366.24691 | I46: =(($F46*(1+Assumptions!$C$32)*Assumptions!$E$32)-$G46)*Assumptions!$K$32/SUM(Assumptions!$J$32:$L$32) -> 366.24691 | J46: =(($F46*(1+Assumptions!$C$32)*Assumptions!$E$32)-$G46)*Assumptions!$L$32/SUM(Assumptions!$J$32:$L$32) -> 352.16049 | K46: =SUM(G46:J46) -> 1416.765 | L46: =($K46*(1+Assumptions!$C$32)*Assumptions!$F$32)*Assumptions!$I$32 -> 352.41321 | M46: =($K46*(1+Assumptions!$C$32)*Assumptions!$F$32)*Assumptions!$J$32 -> 398.38015 | N46: =($K46*(1+Assumptions!$C$32)*Assumptions!$F$32)*Assumptions!$K$32 -> 398.38015 | O46: =($K46*(1+Assumptions!$C$32)*Assumptions!$F$32)*Assumptions!$L$32 -> 383.05784 | P46: =SUM(L46:O46) -> 1532.2313 | Q46: =$P46*(1+Assumptions!$C$32)*Assumptions!$F$32 -> 1657.1082 | R46: =$Q46*(1+Assumptions!$C$32)*Assumptions!$F$32 -> 1792.1625 | S46: =$R46*(1+Assumptions!$D$32)*Assumptions!$F$32 -> 1892.0756 | T46: =$S46*(1+Assumptions!$D$32)*Assumptions!$F$32 -> 1997.5588 | U46: =$T46*(1+Assumptions!$D$32)*Assumptions!$F$32 -> 2108.9227 | V46: =$U46*(1+Assumptions!$D$32)*Assumptions!$F$32 -> 2226.4951 | W46: =$V46*(1+Assumptions!$D$32)*Assumptions!$F$32 -> 2350.6222
B47: Gelusil-MPS | C47: 800 | D47: 820 | E47: 850 | F47: 900 | G47: =Assumptions!$G$33 -> 225.99462 | H47: =(($F47*(1+Assumptions!$C$33)*Assumptions!$E$33)-$G47)*Assumptions!$J$33/SUM(Assumptions!$J$33:$L$33) -> 249.22364 | I47: =(($F47*(1+Assumptions!$C$33)*Assumptions!$E$33)-$G47)*Assumptions!$K$33/SUM(Assumptions!$J$33:$L$33) -> 249.22364 | J47: =(($F47*(1+Assumptions!$C$33)*Assumptions!$E$33)-$G47)*Assumptions!$L$33/SUM(Assumptions!$J$33:$L$33) -> 239.63811 | K47: =SUM(G47:J47) -> 964.08 | L47: =($K47*(1+Assumptions!$C$33)*Assumptions!$F$33)*Assumptions!$I$33 -> 237.52617 | M47: =($K47*(1+Assumptions!$C$33)*Assumptions!$F$33)*Assumptions!$J$33 -> 268.50785 | N47: =($K47*(1+Assumptions!$C$33)*Assumptions!$F$33)*Assumptions!$K$33 -> 268.50785 | O47: =($K47*(1+Assumptions!$C$33)*Assumptions!$F$33)*Assumptions!$L$33 -> 258.18062 | P47: =SUM(L47:O47) -> 1032.7225 | Q47: =$P47*(1+Assumptions!$C$33)*Assumptions!$F$33 -> 1106.2523 | R47: =$Q47*(1+Assumptions!$C$33)*Assumptions!$F$33 -> 1185.0175 | S47: =$R47*(1+Assumptions!$D$33)*Assumptions!$F$33 -> 1238.9358 | T47: =$S47*(1+Assumptions!$D$33)*Assumptions!$F$33 -> 1295.3074 | U47: =$T47*(1+Assumptions!$D$33)*Assumptions!$F$33 -> 1354.2439 | V47: =$U47*(1+Assumptions!$D$33)*Assumptions!$F$33 -> 1415.862 | W47: =$V47*(1+Assumptions!$D$33)*Assumptions!$F$33 -> 1480.2837
B48: Neksium | C48: 360 | D48: 350 | E48: 345 | F48: 350 | G48: =Assumptions!$G$34 -> 83.053022 | H48: =(($F48*(1+Assumptions!$C$34)*Assumptions!$E$34)-$G48)*Assumptions!$J$34/SUM(Assumptions!$J$34:$L$34) -> 91.589686 | I48: =(($F48*(1+Assumptions!$C$34)*Assumptions!$E$34)-$G48)*Assumptions!$K$34/SUM(Assumptions!$J$34:$L$34) -> 91.589686 | J48: =(($F48*(1+Assumptions!$C$34)*Assumptions!$E$34)-$G48)*Assumptions!$L$34/SUM(Assumptions!$J$34:$L$34) -> 88.067006 | K48: =SUM(G48:J48) -> 354.2994 | L48: =($K48*(1+Assumptions!$C$34)*Assumptions!$F$34)*Assumptions!$I$34 -> 90.64821 | M48: =($K48*(1+Assumptions!$C$34)*Assumptions!$F$34)*Assumptions!$J$34 -> 102.47189 | N48: =($K48*(1+Assumptions!$C$34)*Assumptions!$F$34)*Assumptions!$K$34 -> 102.47189 | O48: =($K48*(1+Assumptions!$C$34)*Assumptions!$F$34)*Assumptions!$L$34 -> 98.530663 | P48: =SUM(L48:O48) -> 394.12265 | Q48: =$P48*(1+Assumptions!$C$34)*Assumptions!$F$34 -> 438.42204 | R48: =$Q48*(1+Assumptions!$C$34)*Assumptions!$F$34 -> 487.70068 | S48: =$R48*(1+Assumptions!$D$34)*Assumptions!$F$34 -> 519.88892 | T48: =$S48*(1+Assumptions!$D$34)*Assumptions!$F$34 -> 554.20159 | U48: =$T48*(1+Assumptions!$D$34)*Assumptions!$F$34 -> 590.77889 | V48: =$U48*(1+Assumptions!$D$34)*Assumptions!$F$34 -> 629.7703 | W48: =$V48*(1+Assumptions!$D$34)*Assumptions!$F$34 -> 671.33514
...

Sheet Assumptions
A2: Pfizer Limited revenue assumptions
A3: INR million unless stated. Blue font and pale-yellow fill are editable inputs. Black cells are same-sheet formulas.
A5: Legend | B5: Hardcode | C5: Formula | D5: Cross-sheet link
A7: Reported company revenue anchors
A8: Metric | B8: FY23A | C8: FY24A | D8: FY25A | E8: FY26A
A9: Product revenue | B9: 23376.3 | C9: 20810.4 | D9: 21283.6 | E9: 23771.1
A10: Service revenue | B10: 846.9 | C10: 1116.5 | D10: 1526.4 | E10: 1421.6
A11: Other operating revenue | B11: 24.4 | C11: 4.8 | D11: 3.5 | E11: 3.8
A12: Revenue from operations | B12: 24247.6 | C12: 21931.7 | D12: 22813.5 | E12: 25196.5
A14: Product forecast drivers
A15: Therapy | B15: Brand | C15: Net growth FY27-FY30 | D15: Net growth FY31-FY35 | E15: FY27 factor | F15: FY28+ factor | G15: FY27 Q1 estimate | H15: Quarterly profile | I15: Q1 % | J15: Q2 % | K15: Q3 % | L15: Q4 % | M15: Rationale
A16: Vaccines | B16: Prevenar 13 | C16: 0.0094 | D16: -0.016 | E16: 1 | F16: 1 | G16: 681.46069 | H16: Vaccines | I16: =$B$56 -> 0.24 | J16: =$C$56 -> 0.23 | K16: =$D$56 -> 0.25 | L16: =$E$56 -> 0.28 | M16: Mature PCV franchise; modelled with cannibalisation from Prevenar 20.
A17: Vaccines | B17: Prevenar 20 | C17: 0.3905 | D17: 0.148 | E17: 1 | F17: 1 | G17: 278.90306 | H17: Vaccines | I17: =$B$56 -> 0.24 | J17: =$C$56 -> 0.23 | K17: =$D$56 -> 0.25 | L17: =$E$56 -> 0.28 | M17: Launch ramp; adult immunisation, affordability and internal franchise cannibalisation.
A18: Vaccines | B18: Other vaccines | C18: 0.0506 | D18: 0.03525 | E18: 1 | F18: 1 | G18: 30.838061 | H18: Vaccines | I18: =$B$56 -> 0.24 | J18: =$C$56 -> 0.23 | K18: =$D$56 -> 0.25 | L18: =$E$56 -> 0.28 | M18: Residual vaccine portfolio.
A19: Vaccines | B19: Abrysvo (pipeline) | C19: 0.03 | D19: 0.025 | E19: 0 | F19: 0 | G19: 0 | H19: Vaccines | I19: =$B$56 -> 0.24 | J19: =$C$56 -> 0.23 | K19: =$D$56 -> 0.25 | L19: =$E$56 -> 0.28 | M19: Only future pipeline line included in the base case; linked to the pipeline assumptions below.
A20: Anti-infectives and hospital products | B20: Magnex | C20: 0.107 | D20: 0.071 | E20: 1 | F20: 1 | G20: 379.09153 | H20: Hospital | I20: =$B$57 -> 0.24 | J20: =$C$57 -> 0.25 | K20: =$D$57 -> 0.25 | L20: =$E$57 -> 0.26 | M20: FY24 historical estimate reflects voluntary recall/supply disruption; subsequent recovery.
A21: Anti-infectives and hospital products | B21: Meronem | C21: 0.07625 | D21: 0.0506 | E21: 1 | F21: 1 | G21: 242.19737 | H21: Hospital | I21: =$B$57 -> 0.24 | J21: =$C$57 -> 0.25 | K21: =$D$57 -> 0.25 | L21: =$E$57 -> 0.26 | M21: Hospital anti-infective; institutional exposure.
A22: Anti-infectives and hospital products | B22: Zavicefta | C22: 0.107 | D22: 0.071 | E22: 1 | F22: 1 | G22: 238.28611 | H22: Hospital | I22: =$B$57 -> 0.24 | J22: =$C$57 -> 0.25 | K22: =$D$57 -> 0.25 | L22: =$E$57 -> 0.26 | M22: 42% market share MAT Mar-26 in represented ceftazidime-avibactam market.
A23: Anti-infectives and hospital products | B23: Zithromax | C23: 0.025 | D23: -0.0004 | E23: 1 | F23: 1 | G23: 75.216574 | H23: Hospital | I23: =$B$57 -> 0.24 | J23: =$C$57 -> 0.25 | K23: =$D$57 -> 0.25 | L23: =$E$57 -> 0.26 | M23: Mature anti-infective; generic pressure. Azithromycin formulations are scheduled under NLEM 2022, limiting unrestricted price/mix.
A24: Anti-infectives and hospital products | B24: Emblaveo | C24: 0.48625 | D24: 0.173 | E24: 1 | F24: 1 | G24: 65.438419 | H24: Hospital | I24: =$B$57 -> 0.24 | J24: =$C$57 -> 0.25 | K24: =$D$57 -> 0.25 | L24: =$E$57 -> 0.26 | M24: ICU launch ramp; MDR Gram-negative infections.
A25: Anti-infectives and hospital products | B25: Other hospital and anti-infective products | C25: 0.05575 | D25: 0.0404 | E25: 1 | F25: 1 | G25: 154.94614 | H25: Hospital | I25: =$B$57 -> 0.24 | J25: =$C$57 -> 0.25 | K25: =$D$57 -> 0.25 | L25: =$E$57 -> 0.26 | M25: Residual hospital portfolio; includes smaller anti-infectives.
A26: Cardiovascular and anticoagulation | B26: Eliquis | C26: 0.148 | D26: 0.0812 | E26: 1 | F26: 1 | G26: 527.92006 | H26: Chronic | I26: =$B$58 -> 0.24 | J26: =$C$58 -> 0.25 | K26: =$D$58 -> 0.25 | L26: =$E$58 -> 0.26 | M26: FY26 estimate anchored to company-disclosed 30% YoY growth; post-2022 LOE/generic pressure incorporated in forecast.
A27: Cardiovascular and anticoagulation | B27: Minipress XL | C27: 0.05575 | D27: 0.02 | E27: 0.43210674 | F27: 0 | G27: 445.47016 | H27: Exit | I27: =$B$61 -> 0 | J27: =$C$61 -> 1 | K27: =$D$61 -> 0 | L27: =$E$61 -> 0 | M27: FY27 Q2 prorated to 7-Sep-26; zero from FY28. Compensation excluded from operating revenue.
A28: Cardiovascular and anticoagulation | B28: Amlogard | C28: 0.025 | D28: 0.02 | E28: 0 | F28: 0 | G28: 0 | H28: Chronic | I28: =$B$58 -> 0.24 | J28: =$C$58 -> 0.25 | K28: =$D$58 -> 0.25 | L28: =$E$58 -> 0.26 | M28: Historical FY23 estimate covers only Apr-Jul 2022 pre-transfer; no revenue thereafter.
A29: Cardiovascular and anticoagulation | B29: Other cardiovascular products | C29: 0.0455 | D29: 0.0302 | E29: 1 | F29: 1 | G29: 76.720905 | H29: Chronic | I29: =$B$58 -> 0.24 | J29: =$C$58 -> 0.25 | K29: =$D$58 -> 0.25 | L29: =$E$58 -> 0.26 | M29: Residual listed-company cardiovascular portfolio.
A30: Vitamins and nutritional products | B30: Becosules | C30: 0.0815 | D30: 0.05575 | E30: 1 | F30: 1 | G30: 565.34871 | H30: Primary | I30: =$B$59 -> 0.23 | J30: =$C$59 -> 0.26 | K30: =$D$59 -> 0.26 | L30: =$E$59 -> 0.25 | M30: Mature brand with distribution/packaging support; no innovation-like growth.
A31: Vitamins and nutritional products | B31: Other nutritional products | C31: 0.0506 | D31: 0.03525 | E31: 1 | F31: 1 | G31: 36.941428 | H31: Primary | I31: =$B$59 -> 0.23 | J31: =$C$59 -> 0.26 | K31: =$D$59 -> 0.26 | L31: =$E$59 -> 0.25 | M31: Residual nutritional portfolio.
A32: Gastrointestinal | B32: Mucaine | C32: 0.0815 | D32: 0.05575 | E32: 1 | F32: 1 | G32: 332.11068 | H32: Primary | I32: =$B$59 -> 0.23 | J32: =$C$59 -> 0.26 | K32: =$D$59 -> 0.26 | L32: =$E$59 -> 0.25 | M32: Mature GI franchise.
A33: Gastrointestinal | B33: Gelusil-MPS | C33: 0.0712 | D33: 0.0455 | E33: 1 | F33: 1 | G33: 225.99462 | H33: Primary | I33: =$B$59 -> 0.23 | J33: =$C$59 -> 0.26 | K33: =$D$59 -> 0.26 | L33: =$E$59 -> 0.25 | M33: Mature OTC-oriented GI brand.
A34: Gastrointestinal | B34: Neksium | C34: 0.1124 | D34: 0.066 | E34: 0.91 | F34: 1 | G34: 83.053022 | H34: Primary | I34: =$B$59 -> 0.23 | J34: =$C$59 -> 0.26 | K34: =$D$59 -> 0.26 | L34: =$E$59 -> 0.25 | M34: Cipla transition factor applied in FY27; volume growth assumption captures broader reach.
A35: Gastrointestinal | B35: Other gastrointestinal products | C35: 0.0506 | D35: 0.03525 | E35: 1 | F35: 1 | G35: 44.329713 | H35: Primary | I35: =$B$59 -> 0.23 | J35: =$C$59 -> 0.26 | K35: =$D$59 -> 0.26 | L35: =$E$59 -> 0.25 | M35: Residual listed-company GI portfolio.
A36: Respiratory and cough | B36: Corex DX | C36: 0.1124 | D36: 0.066 | E36: 0.91 | F36: 1 | G36: 118.64717 | H36: Primary | I36: =$B$59 -> 0.23 | J36: =$C$59 -> 0.26 | K36: =$D$59 -> 0.26 | L36: =$E$59 -> 0.25 | M36: Cipla transition factor applied in FY27.
A37: Respiratory and cough | B37: Corex LS | C37: 0.1124 | D37: 0.066 | E37: 0.91 | F37: 1 | G37: 94.917739 | H37: Primary | I37: =$B$59 -> 0.23 | J37: =$C$59 -> 0.26 | K37: =$D$59 -> 0.26 | L37: =$E$59 -> 0.25 | M37: Cipla transition factor applied in FY27.
A38: Respiratory and cough | B38: Other respiratory products | C38: 0.0506 | D38: 0.03525 | E38: 1 | F38: 1 | G38: 24.627618 | H38: Primary | I38: =$B$59 -> 0.23 | J38: =$C$59 -> 0.26 | K38: =$D$59 -> 0.26 | L38: =$E$59 -> 0.25 | M38: Residual respiratory portfolio.
A39: Pain, inflammation and immunology | B39: Dolonex | C39: 0.0865 | D39: 0.0506 | E39: 0.91 | F39: 1 | G39: 81.119299 | H39: Primary | I39: =$B$59 -> 0.23 | J39: =$C$59 -> 0.26 | K39: =$D$59 -> 0.26 | L39: =$E$59 -> 0.25 | M39: Cipla transition factor applied in FY27.
A40: Pain, inflammation and immunology | B40: Enbrel | C40: 0.0045 | D40: -0.0106 | E40: 1 | F40: 1 | G40: 135.13911 | H40: Chronic | I40: =$B$58 -> 0.24 | J40: =$C$58 -> 0.25 | K40: =$D$58 -> 0.25 | L40: =$E$58 -> 0.26 | M40: Mature TNF inhibitor with competitive/biosimilar pressure.
A41: Pain, inflammation and immunology | B41: Betrecep | C41: 0.148 | D41: 0.071 | E41: 1 | F41: 1 | G41: 70.202135 | H41: Chronic | I41: =$B$58 -> 0.24 | J41: =$C$58 -> 0.25 | K41: =$D$58 -> 0.25 | L41: =$E$58 -> 0.26 | M41: India-specific access launch; ranked #6 in >85-brand market MAT Mar-26.
A42: Pain, inflammation and immunology | B42: Other pain and immunology products | C42: 0.0865 | D42: 0.0506 | E42: 1 | F42: 1 | G42: 66.441307 | H42: Chronic | I42: =$B$58 -> 0.24 | J42: =$C$58 -> 0.25 | K42: =$D$58 -> 0.25 | L42: =$E$58 -> 0.26 | M42: Includes smaller listed-company I&I/pain products; Cibinqo is not separately material in available data.
A43: Women's health and endocrine | B43: Premarin franchise | C43: 0.03 | D43: 0.01475 | E43: 1 | F43: 1 | G43: 75.583484 | H43: Chronic | I43: =$B$58 -> 0.24 | J43: =$C$58 -> 0.25 | K43: =$D$58 -> 0.25 | L43: =$E$58 -> 0.26 | M43: Mature women’s-health franchise.
A44: Women's health and endocrine | B44: Folvite / folic-acid combinations | C44: 0.0815 | D44: 0.05575 | E44: 1 | F44: 1 | G44: 171.95243 | H44: Chronic | I44: =$B$58 -> 0.24 | J44: =$C$58 -> 0.25 | K44: =$D$58 -> 0.25 | L44: =$E$58 -> 0.26 | M44: Market-leading represented folic-acid category positioning.
...

Sheet Drug Primer
A2: Pfizer India drug primer
A3: Reference sheet only. It does not feed the revenue model. Listed and private-entity products are separated below.
A5: Products included in the listed-company model
A6: Therapy | B6: Brand | C6: Molecule | D6: What it is | E6: What it treats | F6: Typical prescriber / patient | G6: Use | H6: Channel | I6: Portfolio role | J6: Ownership note
A7: Vaccines | B7: Prevenar 13 | C7: 13-valent pneumococcal conjugate vaccine | D7: Conjugate vaccine covering 13 pneumococcal serotypes | E7: Pneumococcal disease prevention | F7: Paediatricians and physicians; children and adults | G7: Short vaccination schedule | H7: Private clinics and hospitals | I7: Mature vaccine franchise | J7: Listed Pfizer marketer
A8: Vaccines | B8: Prevenar 20 | C8: 20-valent pneumococcal conjugate vaccine | D8: Broader-valency pneumococcal conjugate vaccine | E8: Pneumococcal disease prevention | F8: Physicians; mainly adult private-pay patients | G8: Short vaccination schedule | H8: Private clinics and hospitals | I8: Core vaccine growth product | J8: Listed Pfizer launch
A9: Vaccines | B9: Other vaccines | C9: Multiple | D9: Portfolio line or residual grouping | E9: Products within Vaccines | F9: Varies by product | G9: Varies | H9: Retail and/or hospitals | I9: Residual portfolio | J9: Included in listed-company model
A10: Vaccines | B10: Abrysvo (pipeline) | C10: RSV prefusion F vaccine | D10: Bivalent RSV prefusion F protein vaccine | E10: RSV lower-respiratory-tract disease prevention | F10: Adult physicians; older and at-risk adults | G10: Single vaccination course | H10: Private clinics and hospitals | I10: Risk-adjusted pipeline | J10: Listed economics plausible but unconfirmed
A11: Anti-infectives and hospital products | B11: Magnex | C11: Cefoperazone + sulbactam | D11: Injectable cephalosporin plus beta-lactamase inhibitor | E11: Serious bacterial infections | F11: Hospital physicians; admitted patients | G11: Acute | H11: Hospitals | I11: Hospital growth franchise | J11: Listed Pfizer marketer
A12: Anti-infectives and hospital products | B12: Meronem | C12: Meropenem | D12: Broad-spectrum carbapenem antibiotic | E12: Serious and resistant bacterial infections | F12: Intensivists and hospital physicians | G12: Acute | H12: Hospitals | I12: Established hospital brand | J12: Listed Pfizer marketer
A13: Anti-infectives and hospital products | B13: Zavicefta | C13: Ceftazidime + avibactam | D13: Cephalosporin plus beta-lactamase inhibitor | E13: Resistant Gram-negative infections | F13: Intensivists and infectious-disease specialists | G13: Acute | H13: Hospitals | I13: Higher-value hospital growth brand | J13: Listed Pfizer marketer
A14: Anti-infectives and hospital products | B14: Zithromax | C14: Azithromycin | D14: Macrolide antibiotic | E14: Selected bacterial respiratory and other infections | F14: General physicians and specialists | G14: Acute | H14: Retail and hospitals | I14: Mature anti-infective | J14: Listed Pfizer marketer
A15: Anti-infectives and hospital products | B15: Emblaveo | C15: Aztreonam + avibactam | D15: Monobactam plus beta-lactamase inhibitor | E15: Difficult multidrug-resistant Gram-negative infections | F15: Infectious-disease specialists and intensivists | G15: Acute | H15: Tertiary hospitals | I15: New hospital launch | J15: Listed Pfizer launch
A16: Anti-infectives and hospital products | B16: Other hospital and anti-infective products | C16: Multiple | D16: Portfolio line or residual grouping | E16: Products within Anti-infectives and hospital products | F16: Varies by product | G16: Varies | H16: Retail and/or hospitals | I16: Residual portfolio | J16: Included in listed-company model
A17: Cardiovascular and anticoagulation | B17: Eliquis | C17: Apixaban | D17: Oral factor Xa anticoagulant | E17: Atrial fibrillation and venous thromboembolism | F17: Cardiologists and physicians; chronic patients | G17: Chronic | H17: Retail and hospitals | I17: Core cardiovascular growth brand | J17: Listed Pfizer marketer
... A40: Other established products | B40: Other established products | C40: Multiple | D40: Portfolio line or residual grouping | E40: Products within Other established products | F40: Varies by product | G40: Varies | H40: Retail and/or hospitals | I40: Residual portfolio | J40: Included in listed-company model
A43: Private-entity products excluded from the listed-company model
A44: Therapy | B44: Brand | C44: Molecule | D44: What it is | E44: What it treats | F44: Typical prescriber / patient | G44: Use | H44: Channel | I44: Portfolio role | J44: Ownership note
A45: Oncology | B45: Palbace | C45: Palbociclib | D45: Oral CDK4/6 inhibitor | E45: HR-positive, HER2-negative advanced breast cancer | F45: Oncologists; biomarker-selected patients | G45: Chronic cycles | H45: Oncology | I45: Established targeted therapy | J45: PPIPL; excluded
A46: Hospital / inflammation | B46: Solu-Medrol | C46: Methylprednisolone sodium succinate | D46: Intravenous corticosteroid | E46: Severe inflammatory, allergic and autoimmune conditions | F46: Hospital physicians | G46: Acute | H46: Hospitals | I46: Established hospital product | J46: PPIPL; excluded
A47: Rare disease | B47: Xyntha | C47: Recombinant factor VIII | D47: Clotting-factor replacement | E47: Haemophilia A | F47: Haematologists; haemophilia patients | G47: Repeated prophylaxis or on demand | H47: Specialty hospitals | I47: Rare-disease product | J47: PPIPL; excluded
A48: Anti-infectives | B48: Dalacin C | C48: Clindamycin | D48: Lincosamide antibiotic | E48: Susceptible bacterial infections | F48: General physicians and specialists | G48: Acute | H48: Retail and hospitals | I48: Cipla-commercialised private brand | J48: PPIPL; excluded
A49: Endocrine | B49: Genotropin | C49: Somatropin | D49: Recombinant human growth hormone | E49: Growth-hormone deficiency and related conditions | F49: Paediatric endocrinologists | G49: Chronic | H49: Specialty retail | I49: Rare endocrine product | J49: PPIPL; excluded
A50: Anti-infectives | B50: VFEND | C50: Voriconazole | D50: Triazole antifungal | E50: Serious invasive fungal infections | F50: Infectious-disease specialists | G50: Acute or extended | H50: Hospitals | I50: Specialty hospital product | J50: PPIPL; excluded
A51: Oncology | B51: Crizalk | C51: Crizotinib | D51: ALK and ROS1 tyrosine-kinase inhibitor | E51: Molecularly selected lung cancer | F51: Oncologists | G51: Chronic | H51: Oncology | I51: Targeted therapy | J51: PPIPL; excluded
A52: Oncology | B52: Inlyta | C52: Axitinib | D52: VEGFR tyrosine-kinase inhibitor | E52: Advanced renal-cell carcinoma | F52: Oncologists | G52: Chronic | H52: Oncology | I52: Targeted therapy | J52: PPIPL; excluded
A53: Inflammation | B53: Depo-Medrol | C53: Methylprednisolone acetate | D53: Depot corticosteroid injection | E53: Inflammatory and allergic conditions | F53: Physicians and specialists | G53: Acute or episodic | H53: Clinics and hospitals | I53: Established injectable | J53: PPIPL; excluded
A54: Rare disease / hospital | B54: Atgam | C54: Equine antithymocyte globulin | D54: Polyclonal immunosuppressive antibody | E54: Severe aplastic anaemia and selected transplant use | F54: Haematologists and transplant specialists | G54: Acute course | H54: Tertiary hospitals | I54: Rare hospital therapy | J54: PPIPL; excluded
