Workbook

Sheet Summary
A1: VAT GROUP AG — MODEL SUMMARY
A2: Simple three-statement support model | 2023A–2025A reported | 2026E–2030E analyst estimates | CHF m unless stated
A3: REFERENCE PRICE | C3: TARGET PRICE | E3: UPSIDE | G3: FY28 EBITDA
A4: ='Assumptions & Sources'!E45 -> 611.4 | C4: =Valuation!B16 -> 800.04764 | E4: =Valuation!B18 -> 0.30855028 | G4: ='3-Statement'!G8 -> 758.58236
A8: MODEL TAKEAWAY
A9: VAT is modeled as a backlog-conversion and WFE-outgrowth story, not a simple top-down growth rate. FY28 sales reach ~CHF2.05bn and EBITDA ~CHF759m at a 37% margin; 31.4x FY28 EV/EBITDA implies ~CHF800/share.
A11: KEY FINANCIALS
A12: CHF m except EPS | B12: 2023A | C12: 2024A | D12: 2025A | E12: 2026E | F12: 2027E | G12: 2028E | H12: 2029E | I12: 2030E
A13: Net sales | B13: ='3-Statement'!B6 -> 885.316 | C13: ='3-Statement'!C6 -> 942.2 | D13: ='3-Statement'!D6 -> 1073.516 | E13: ='3-Statement'!E6 -> 1309.4886 | F13: ='3-Statement'!F6 -> 1714.1898 | G13: ='3-Statement'!G6 -> 2050.2226 | H13: ='3-Statement'!H6 -> 2256.0831 | I13: ='3-Statement'!I6 -> 2293.2392
A14: YoY growth | B14: ='3-Statement'!B7 -> 0 | C14: ='3-Statement'!C7 -> 0.064252764 | D14: ='3-Statement'!D7 -> 0.13937168 | E14: ='3-Statement'!E7 -> 0.21981282 | F14: ='3-Statement'!F7 -> 0.30905292 | G14: ='3-Statement'!G7 -> 0.19603008 | H14: ='3-Statement'!H7 -> 0.10040885 | I14: ='3-Statement'!I7 -> 0.01646929
A15: EBITDA | B15: ='3-Statement'!B8 -> 270.911 | C15: ='3-Statement'!C8 -> 293.666 | D15: ='3-Statement'!D8 -> 321.577 | E15: ='3-Statement'!E8 -> 432.13123 | F15: ='3-Statement'!F8 -> 608.53739 | G15: ='3-Statement'!G8 -> 758.58236 | H15: ='3-Statement'!H8 -> 834.75074 | I15: ='3-Statement'!I8 -> 825.5661
A16: EBITDA margin | B16: ='3-Statement'!B9 -> 0.30600486 | C16: ='3-Statement'!C9 -> 0.31168117 | D16: ='3-Statement'!D9 -> 0.29955492 | E16: ='3-Statement'!E9 -> 0.33 | F16: ='3-Statement'!F9 -> 0.355 | G16: ='3-Statement'!G9 -> 0.37 | H16: ='3-Statement'!H9 -> 0.37 | I16: ='3-Statement'!I9 -> 0.36
A17: Net income | B17: ='3-Statement'!B15 -> 190.31 | C17: ='3-Statement'!C15 -> 211.799 | D17: ='3-Statement'!D15 -> 214.28 | E17: ='3-Statement'!E15 -> 307.61749 | F17: ='3-Statement'!F15 -> 439.61556 | G17: ='3-Statement'!G15 -> 554.55285 | H17: ='3-Statement'!H15 -> 612.49428 | I17: ='3-Statement'!I15 -> 605.1937
A18: Diluted EPS (CHF) | B18: ='3-Statement'!B16 -> 6.35 | C18: ='3-Statement'!C16 -> 7.06 | D18: ='3-Statement'!D16 -> 7.15 | E18: ='3-Statement'!E16 -> 10.253916 | F18: ='3-Statement'!F16 -> 14.653852 | G18: ='3-Statement'!G16 -> 18.485095 | H18: ='3-Statement'!H16 -> 20.416476 | I18: ='3-Statement'!I16 -> 20.173123
A19: Free cash flow | B19: ='3-Statement'!B61 -> 188.758 | C19: ='3-Statement'!C61 -> 183.248 | D19: ='3-Statement'!D61 -> 230.388 | E19: ='3-Statement'!E61 -> 117.21854 | F19: ='3-Statement'!F61 -> 403.27589 | G19: ='3-Statement'!G61 -> 539.21546 | H19: ='3-Statement'!H61 -> 588.62375 | I19: ='3-Statement'!I61 -> 591.54912
A22: REVENUE BUILD — BUSINESS UNIT MIX
A23: CHF m | B23: 2025A | C23: 2026E | D23: 2027E | E23: 2028E | F23: 2029E | G23: 2030E
A24: Semiconductors | B24: ='Revenue Build'!D13 -> 724.7 | C24: ='Revenue Build'!E13 -> 924.95029 | D24: ='Revenue Build'!F13 -> 1274.7731 | E24: ='Revenue Build'!G13 -> 1557.532 | F24: ='Revenue Build'!H13 -> 1719.5153 | G24: ='Revenue Build'!I13 -> 1719.5153
A25: Advanced Industrials | B25: ='Revenue Build'!D16 -> 149.9 | C25: ='Revenue Build'!E16 -> 149.9 | D25: ='Revenue Build'!F16 -> 164.89 | E25: ='Revenue Build'!G16 -> 179.7301 | F25: ='Revenue Build'!H16 -> 192.31121 | G25: ='Revenue Build'!I16 -> 201.92677
A26: Global Service | B26: ='Revenue Build'!D21 -> 198.846 | C26: ='Revenue Build'!E21 -> 234.63828 | D26: ='Revenue Build'!F21 -> 274.52679 | E26: ='Revenue Build'!G21 -> 312.96054 | F26: ='Revenue Build'!H21 -> 344.25659 | G26: ='Revenue Build'!I21 -> 371.79712
A27: Group net sales | B27: ='Revenue Build'!D24 -> 1073.516 | C27: ='Revenue Build'!E24 -> 1309.4886 | D27: ='Revenue Build'!F24 -> 1714.1898 | E27: ='Revenue Build'!G24 -> 2050.2226 | F27: ='Revenue Build'!H24 -> 2256.0831 | G27: ='Revenue Build'!I24 -> 2293.2392
A30: FY28 VARIANT VS CONSENSUS
A31: Metric | B31: Model | C31: Consensus | D31: Difference
A32: FY28 revenue | B32: ='3-Statement'!G6 -> 2050.2226 | C32: ='Assumptions & Sources'!G41 -> 1822 | D32: =B32/C32-1 -> 0.12525939
A33: FY28 EBITDA | B33: ='3-Statement'!G8 -> 758.58236 | C33: ='Assumptions & Sources'!G42 -> 664.5 | D33: =B33/C33-1 -> 0.14158369
A34: FY28 EBITDA margin | B34: ='3-Statement'!G9 -> 0.37 | C34: ='Assumptions & Sources'!G42/'Assumptions & Sources'!G41 -> 0.36470911 | D34: =B34-C34 -> 0.0052908891
A37: KEY CHECKS
A38: ✓ Forecast balance sheet check is zero.
A39: ✓ Revenue is built by Semiconductors, Advanced Industrials and Global Service; Semis is explicitly driven by WFE, structural outgrowth and backlog/capacity conversion.
A40: ! FY28 37% EBITDA margin is the top end of VAT's medium-term corridor and is the key profitability assumption.
A41: ! 2029–2030 WFE values are analyst assumptions, not company guidance or SEMI forecasts.

Sheet Assumptions & Sources
A1: VAT GROUP AG — ASSUMPTIONS & SOURCES
A2: Blue font = hardcoded input | Green = same-workbook link | Yellow = key forecast assumption | Forecasts are analyst estimates unless stated.
A4: MARKET / OPERATING ASSUMPTIONS
A5: CHF m unless stated | B5: 2023A | C5: 2024A | D5: 2025A | E5: 2026E | F5: 2027E | G5: 2028E | H5: 2029E | I5: 2030E
A6: WFE (US$bn) | B6: 96 | C6: 104.3 | D6: 116.9 | E6: 143.9 | F6: 175.3 | G6: 200 | H6: 216 | I6: 205.2
A7: WFE growth | C7: =C6/B6-1 -> 0.086458333 | D7: =D6/C6-1 -> 0.12080537 | E7: =E6/D6-1 -> 0.23096664 | F7: =F6/E6-1 -> 0.21820709 | G7: =G6/F6-1 -> 0.14090131 | H7: =H6/G6-1 -> 0.08 | I7: =I6/H6-1 -> -0.05
A8: Semis WFE sensitivity | E8: 0.85 | F8: 1 | G8: 0.9 | H8: 0.8 | I8: 0.8
A9: Vacuum intensity / share / content outgrowth | E9: 0.04 | F9: 0.06 | G9: 0.065 | H9: 0.04 | I9: 0.04
A10: Backlog / capacity conversion uplift | E10: 0.04 | F10: 0.1 | G10: 0.03 | H10: 0 | I10: 0
A11: Advanced Industrials growth | E11: 0 | F11: 0.1 | G11: 0.09 | H11: 0.07 | I11: 0.05
A12: Service installed-base contribution | E12: 0.06 | F12: 0.07 | G12: 0.07 | H12: 0.06 | I12: 0.05
A13: Service utilization / retrofit contribution | E13: 0.12 | F13: 0.1 | G13: 0.07 | H13: 0.04 | I13: 0.03
A14: EBITDA margin | E14: 0.33 | F14: 0.355 | G14: 0.37 | H14: 0.37 | I14: 0.36
A15: D&A as % of sales | E15: 0.042 | F15: 0.04 | G15: 0.04 | H15: 0.04 | I15: 0.04
A16: DSO (days) | E16: 45 | F16: 45 | G16: 44 | H16: 44 | I16: 44
A17: Inventory days | E17: 80 | F17: 72 | G17: 65 | H17: 62 | I17: 60
A18: Payables days | E18: 30 | F18: 30 | G18: 30 | H18: 30 | I18: 30
A19: Other assets as % sales | E19: 0.03 | F19: 0.03 | G19: 0.03 | H19: 0.03 | I19: 0.03
... A21: Capex as % sales | E21: 0.06 | F21: 0.05 | G21: 0.05 | H21: 0.05 | I21: 0.05
A22: Gross debt balance (CHF m) | B22: 207.306 | C22: 241.786 | D22: 248.282 | E22: 450 | F22: 375 | G22: 300 | H22: 225 | I22: 150
A23: Acquisition cash spend (CHF m) | E23: 110 | F23: 0 | G23: 0 | H23: 0 | I23: 0
A24: Interest rate on average debt | E24: 0.025 | F24: 0.025 | G24: 0.025 | H24: 0.025 | I24: 0.025
A25: Tax rate | E25: 0.165 | F25: 0.17 | G25: 0.17 | H25: 0.17 | I25: 0.17
A26: Dividend payout (% prior-year NI) | F26: 0.75 | G26: 0.75 | H26: 0.75 | I26: 0.75
A27: Diluted shares (m) | B27: 30 | C27: 30 | D27: 30 | E27: 30 | F27: 30 | G27: 30 | H27: 30 | I27: 30
A28: 2026 dividend cash paid (CHF m) | E28: 210
A29: FY28 target EV / EBITDA | G29: 31.4
A31: CURRENT SETUP / EXTERNAL BENCHMARKS
A32: H1 2026 order intake | E32: 856.359 | F32: H1 2026 is a checkpoint, not annualized mechanically. VAT says the 2027 CHF1.5–1.7bn sales target is under review after WFE expectations rose sharply.
A33: H1 2026 backlog | E33: 647.9
A34: H1 2026 sales | E34: 511.891
A35: H1 2026 EBITDA | E35: 148.228
A36: H1 2026 EBITDA margin | E36: 0.29
A37: Jun-26 factory run-rate / quarter | E37: 320
A38: YE26 factory run-rate target / quarter | E38: 450
A39: H1 2026 net debt | E39: 282
A40: Atonarp transaction consideration | E40: 110
A41: Consensus revenue | E41: 1283 | F41: 1626 | G41: 1822
A42: Consensus EBITDA | E42: 427.7 | F42: 582.8 | G42: 664.5
A43: Company 2027 sales target — low | F43: 1500
...

Sheet Revenue Build
A1: VAT GROUP AG — REVENUE BUILD
A2: Business-unit forecast. Semiconductors = WFE contribution + structural vacuum/share/content outgrowth + backlog/capacity conversion; Service = installed base + utilization / retrofit.
A4: SEMICONDUCTORS — DRIVER-BASED BUILD
A5: CHF m unless stated | B5: 2023A | C5: 2024A | D5: 2025A | E5: 2026E | F5: 2027E | G5: 2028E | H5: 2029E | I5: 2030E
A6: WFE (US$bn) | B6: 96 | C6: 104.3 | D6: 116.9 | E6: ='Assumptions & Sources'!E6 -> 143.9 | F6: ='Assumptions & Sources'!F6 -> 175.3 | G6: ='Assumptions & Sources'!G6 -> 200 | H6: ='Assumptions & Sources'!H6 -> 216 | I6: ='Assumptions & Sources'!I6 -> 205.2
A7: WFE growth | B7: =0 -> 0 | C7: =C6/B6-1 -> 0.086458333 | D7: =D6/C6-1 -> 0.12080537 | E7: ='Assumptions & Sources'!E7 -> 0.23096664 | F7: ='Assumptions & Sources'!F7 -> 0.21820709 | G7: ='Assumptions & Sources'!G7 -> 0.14090131 | H7: ='Assumptions & Sources'!H7 -> 0.08 | I7: ='Assumptions & Sources'!I7 -> -0.05
A8: WFE sensitivity | B8: 0 | C8: 0 | D8: 0 | E8: ='Assumptions & Sources'!E8 -> 0.85 | F8: ='Assumptions & Sources'!F8 -> 1 | G8: ='Assumptions & Sources'!G8 -> 0.9 | H8: ='Assumptions & Sources'!H8 -> 0.8 | I8: ='Assumptions & Sources'!I8 -> 0.8
A9: WFE contribution to VAT growth | E9: =E7*E8 -> 0.19632164 | F9: =F7*F8 -> 0.21820709 | G9: =G7*G8 -> 0.12681118 | H9: =H7*H8 -> 0.064 | I9: =I7*I8 -> -0.04
A10: Vacuum intensity / share / content outgrowth | B10: 0 | C10: 0 | D10: 0 | E10: ='Assumptions & Sources'!E9 -> 0.04 | F10: ='Assumptions & Sources'!F9 -> 0.06 | G10: ='Assumptions & Sources'!G9 -> 0.065 | H10: ='Assumptions & Sources'!H9 -> 0.04 | I10: ='Assumptions & Sources'!I9 -> 0.04
A11: Backlog / capacity conversion uplift | B11: 0 | C11: 0 | D11: 0 | E11: ='Assumptions & Sources'!E10 -> 0.04 | F11: ='Assumptions & Sources'!F10 -> 0.1 | G11: ='Assumptions & Sources'!G10 -> 0.03 | H11: ='Assumptions & Sources'!H10 -> 0 | I11: ='Assumptions & Sources'!I10 -> 0
A12: Semiconductors growth | B12: =0 -> 0 | C12: =C13/B13-1 -> 0.22046332 | D12: =D13/C13-1 -> 0.14631446 | E12: =SUM(E9:E11) -> 0.27632164 | F12: =SUM(F9:F11) -> 0.37820709 | G12: =SUM(G9:G11) -> 0.22181118 | H12: =SUM(H9:H11) -> 0.104 | I12: =SUM(I9:I11) -> -3.469447e-17
A13: Semiconductors revenue | B13: 518 | C13: 632.2 | D13: 724.7 | E13: =D13*(1+E12) -> 924.95029 | F13: =E13*(1+F12) -> 1274.7731 | G13: =F13*(1+G12) -> 1557.532 | H13: =G13*(1+H12) -> 1719.5153 | I13: =H13*(1+I12) -> 1719.5153
A15: Advanced Industrials growth | B15: =0 -> 0 | C15: =C16/B16-1 -> -0.26697531 | D15: =D16/C16-1 -> 0.051929825 | E15: ='Assumptions & Sources'!E11 -> 0 | F15: ='Assumptions & Sources'!F11 -> 0.1 | G15: ='Assumptions & Sources'!G11 -> 0.09 | H15: ='Assumptions & Sources'!H11 -> 0.07 | I15: ='Assumptions & Sources'!I11 -> 0.05
A16: Advanced Industrials revenue | B16: 194.4 | C16: 142.5 | D16: 149.9 | E16: =D16*(1+E15) -> 149.9 | F16: =E16*(1+F15) -> 164.89 | G16: =F16*(1+G15) -> 179.7301 | H16: =G16*(1+H15) -> 192.31121 | I16: =H16*(1+I15) -> 201.92677
A18: Service installed-base contribution | B18: 0 | C18: 0 | D18: 0 | E18: ='Assumptions & Sources'!E12 -> 0.06 | F18: ='Assumptions & Sources'!F12 -> 0.07 | G18: ='Assumptions & Sources'!G12 -> 0.07 | H18: ='Assumptions & Sources'!H12 -> 0.06 | I18: ='Assumptions & Sources'!I12 -> 0.05
A19: Service utilization / retrofit contribution | B19: 0 | C19: 0 | D19: 0 | E19: ='Assumptions & Sources'!E13 -> 0.12 | F19: ='Assumptions & Sources'!F13 -> 0.1 | G19: ='Assumptions & Sources'!G13 -> 0.07 | H19: ='Assumptions & Sources'!H13 -> 0.04 | I19: ='Assumptions & Sources'!I13 -> 0.03
A20: Global Service growth | B20: =0 -> 0 | C20: =C21/B21-1 -> -0.03090237 | D20: =D21/C21-1 -> 0.18696314 | E20: =SUM(E18:E19) -> 0.18 | F20: =SUM(F18:F19) -> 0.17 | G20: =SUM(G18:G19) -> 0.14 | H20: =SUM(H18:H19) -> 0.1 | I20: =SUM(I18:I19) -> 0.08
A21: Global Service revenue | B21: 172.867 | C21: 167.525 | D21: 198.846 | E21: =D21*(1+E20) -> 234.63828 | F21: =E21*(1+F20) -> 274.52679 | G21: =F21*(1+G20) -> 312.96054 | H21: =G21*(1+H20) -> 344.25659 | I21: =H21*(1+I20) -> 371.79712
A23: Rounding / reconciliation | B23: 0.049 | C23: -0.025 | D23: 0.07 | E23: 0 | F23: 0 | G23: 0 | H23: 0 | I23: 0
A24: GROUP NET SALES | B24: 885.316 | C24: 942.2 | D24: 1073.516 | E24: =SUM(E13,E16,E21,E23) -> 1309.4886 | F24: =SUM(F13,F16,F21,F23) -> 1714.1898 | G24: =SUM(G13,G16,G21,G23) -> 2050.2226 | H24: =SUM(H13,H16,H21,H23) -> 2256.0831 | I24: =SUM(I13,I16,I21,I23) -> 2293.2392
A25: YoY growth | B25: =0 -> 0 | C25: =C24/B24-1 -> 0.064252764 | D25: =D24/C24-1 -> 0.13937168 | E25: =E24/D24-1 -> 0.21981282 | F25: =F24/E24-1 -> 0.30905292 | G25: =G24/F24-1 -> 0.19603008 | H25: =H24/G24-1 -> 0.10040885 | I25: =I24/H24-1 -> 0.01646929
A27: Consensus net sales | E27: ='Assumptions & Sources'!E41 -> 1283 | F27: ='Assumptions & Sources'!F41 -> 1626 | G27: ='Assumptions & Sources'!G41 -> 1822
A28: Premium / (discount) to consensus | E28: =E24/E27-1 -> 0.02064581 | F28: =F24/F27-1 -> 0.054237294 | G28: =G24/G27-1 -> 0.12525939
A30: Semiconductors mix | B30: =B13/B24 -> 0.58510182 | C30: =C13/C24 -> 0.67098281 | D30: =D13/D24 -> 0.67507145 | E30: =E13/E24 -> 0.70634468 | F30: =F13/F24 -> 0.7436592 | G30: =G13/G24 -> 0.7596892 | H30: =H13/H24 -> 0.76216842 | I30: =I13/I24 -> 0.74981943
A31: Global Service mix | B31: =B21/B24 -> 0.19526022 | C31: =C21/C24 -> 0.17780195 | D31: =D21/D24 -> 0.18522873 | E31: =E21/E24 -> 0.17918314 | F31: =F21/F24 -> 0.16014958 | G31: =G21/G24 -> 0.1526471 | H31: =H21/H24 -> 0.15259039 | I31: =I21/I24 -> 0.16212749
A34: MODEL READ-THROUGH
A35: Metric | B35: Model output | C35: Interpretation
A36: 2025–28 sales CAGR | B36: =(G24/D24)^(1/3)-1 -> 0.24069252 | C36: WFE + structural vacuum/share/content + backlog conversion
A37: FY28 sales vs consensus | B37: =G28 -> 0.12525939 | C37: Deliberate earnings variant, not a pure multiple call
A38: FY28 EBITDA margin | B38: ='Assumptions & Sources'!G14 -> 0.37 | C38: Top of VAT's stated 30–37% corridor
A39: FY28 group sales | B39: =G24 -> 2050.2226 | C39: ~CHF2.05bn supports the CHF800 framework

Sheet 3-Statement
A1: VAT GROUP AG — SIMPLE 3-STATEMENT MODEL
A2: CHF m except per-share data. 2023A–2025A reported; 2026E–2030E analyst estimates. Revenue is linked to the driver-based Revenue Build.
A4: INCOME STATEMENT
A5: CHF m unless stated | B5: 2023A | C5: 2024A | D5: 2025A | E5: 2026E | F5: 2027E | G5: 2028E | H5: 2029E | I5: 2030E
A6: Net sales | B6: 885.316 | C6: 942.2 | D6: 1073.516 | E6: ='Revenue Build'!E24 -> 1309.4886 | F6: ='Revenue Build'!F24 -> 1714.1898 | G6: ='Revenue Build'!G24 -> 2050.2226 | H6: ='Revenue Build'!H24 -> 2256.0831 | I6: ='Revenue Build'!I24 -> 2293.2392
A7: YoY growth | B7: =0 -> 0 | C7: =C6/B6-1 -> 0.064252764 | D7: =D6/C6-1 -> 0.13937168 | E7: =E6/D6-1 -> 0.21981282 | F7: =F6/E6-1 -> 0.30905292 | G7: =G6/F6-1 -> 0.19603008 | H7: =H6/G6-1 -> 0.10040885 | I7: =I6/H6-1 -> 0.01646929
A8: EBITDA | B8: 270.911 | C8: 293.666 | D8: 321.577 | E8: =E6*'Assumptions & Sources'!E14 -> 432.13123 | F8: =F6*'Assumptions & Sources'!F14 -> 608.53739 | G8: =G6*'Assumptions & Sources'!G14 -> 758.58236 | H8: =H6*'Assumptions & Sources'!H14 -> 834.75074 | I8: =I6*'Assumptions & Sources'!I14 -> 825.5661
A9: EBITDA margin | B9: =B8/B6 -> 0.30600486 | C9: =C8/C6 -> 0.31168117 | D9: =D8/D6 -> 0.29955492 | E9: =E8/E6 -> 0.33 | F9: =F8/F6 -> 0.355 | G9: =G8/G6 -> 0.37 | H9: =H8/H6 -> 0.37 | I9: =I8/I6 -> 0.36
A10: D&A | B10: -42.327 | C10: -43.487 | D10: -48.768 | E10: =-E6*'Assumptions & Sources'!E15 -> -54.99852 | F10: =-F6*'Assumptions & Sources'!F15 -> -68.567594 | G10: =-G6*'Assumptions & Sources'!G15 -> -82.008904 | H10: =-H6*'Assumptions & Sources'!H15 -> -90.243324 | I10: =-I6*'Assumptions & Sources'!I15 -> -91.729567
A11: EBIT | B11: =B8+B10 -> 228.584 | C11: =C8+C10 -> 250.179 | D11: =D8+D10 -> 272.809 | E11: =E8+E10 -> 377.13271 | F11: =F8+F10 -> 539.9698 | G11: =G8+G10 -> 676.57346 | H11: =H8+H10 -> 744.50742 | I11: =I8+I10 -> 733.83654
A12: Net finance result | B12: -21.499 | C12: 2.411 | D12: -15.495 | E12: =-AVERAGE('Assumptions & Sources'!D22,'Assumptions & Sources'!E22)*'Assumptions & Sources'!E24 -> -8.728525 | F12: =-AVERAGE('Assumptions & Sources'!E22,'Assumptions & Sources'!F22)*'Assumptions & Sources'!F24 -> -10.3125 | G12: =-AVERAGE('Assumptions & Sources'!F22,'Assumptions & Sources'!G22)*'Assumptions & Sources'!G24 -> -8.4375 | H12: =-AVERAGE('Assumptions & Sources'!G22,'Assumptions & Sources'!H22)*'Assumptions & Sources'!H24 -> -6.5625 | I12: =-AVERAGE('Assumptions & Sources'!H22,'Assumptions & Sources'!I22)*'Assumptions & Sources'!I24 -> -4.6875
A13: Earnings before tax | B13: =B11+B12 -> 207.085 | C13: =C11+C12 -> 252.59 | D13: =D11+D12 -> 257.314 | E13: =E11+E12 -> 368.40418 | F13: =F11+F12 -> 529.6573 | G13: =G11+G12 -> 668.13596 | H13: =H11+H12 -> 737.94492 | I13: =I11+I12 -> 729.14904
A14: Income tax | B14: -16.775 | C14: -40.791 | D14: -43.034 | E14: =-E13*'Assumptions & Sources'!E25 -> -60.78669 | F14: =-F13*'Assumptions & Sources'!F25 -> -90.041741 | G14: =-G13*'Assumptions & Sources'!G25 -> -113.58311 | H14: =-H13*'Assumptions & Sources'!H25 -> -125.45064 | I14: =-I13*'Assumptions & Sources'!I25 -> -123.95534
A15: Net income | B15: 190.31 | C15: 211.799 | D15: 214.28 | E15: =E13+E14 -> 307.61749 | F15: =F13+F14 -> 439.61556 | G15: =G13+G14 -> 554.55285 | H15: =H13+H14 -> 612.49428 | I15: =I13+I14 -> 605.1937
A16: Diluted EPS (CHF) | B16: 6.35 | C16: 7.06 | D16: 7.15 | E16: =E15/'Assumptions & Sources'!E27 -> 10.253916 | F16: =F15/'Assumptions & Sources'!F27 -> 14.653852 | G16: =G15/'Assumptions & Sources'!G27 -> 18.485095 | H16: =H15/'Assumptions & Sources'!H27 -> 20.416476 | I16: =I15/'Assumptions & Sources'!I27 -> 20.173123
A17: EPS growth | B17: =0 -> 0 | C17: =C16/B16-1 -> 0.11181102 | D17: =D16/C16-1 -> 0.012747875 | E17: =E16/D16-1 -> 0.43411419 | F17: =F16/E16-1 -> 0.42909804 | G17: =G16/F16-1 -> 0.26144955 | H17: =H16/G16-1 -> 0.10448317 | I17: =I16/H16-1 -> -0.01191943
A20: BALANCE SHEET
A21: Cash & cash equivalents | B21: 144.108 | C21: 158.121 | D21: 140.94 | E21: =E59 -> 249.87654 | F21: =F59 -> 347.4393 | G21: =G59 -> 481.94309 | H21: =H59 -> 579.65221 | I21: =I59 -> 636.83062
A22: Trade & other receivables | B22: 108.752 | C22: 141.056 | D22: 125.765 | E22: =E6/365*'Assumptions & Sources'!E16 -> 161.4438 | F22: =F6/365*'Assumptions & Sources'!F16 -> 211.33847 | G22: =G6/365*'Assumptions & Sources'!G16 -> 247.15012 | H22: =H6/365*'Assumptions & Sources'!H16 -> 271.96618 | I22: =I6/365*'Assumptions & Sources'!I16 -> 276.44527
A23: Inventories | B23: 188.455 | C23: 247.596 | D23: 190.021 | E23: =E6/365*'Assumptions & Sources'!E17 -> 287.01119 | F23: =F6/365*'Assumptions & Sources'!F17 -> 338.14156 | G23: =G6/365*'Assumptions & Sources'!G17 -> 365.10814 | H23: =H6/365*'Assumptions & Sources'!H17 -> 383.22507 | I23: =I6/365*'Assumptions & Sources'!I17 -> 376.97082
A24: Other assets | B24: 31.273 | C24: 24.853 | D24: 32.5 | E24: =E6*'Assumptions & Sources'!E19 -> 39.284657 | F24: =F6*'Assumptions & Sources'!F19 -> 51.425695 | G24: =G6*'Assumptions & Sources'!G19 -> 61.506678 | H24: =H6*'Assumptions & Sources'!H19 -> 67.682493 | I24: =I6*'Assumptions & Sources'!I19 -> 68.797175
A25: Fixed & intangible assets | B25: 695.868 | C25: 723.12 | D25: 773.652 | E25: =D25+E6*'Assumptions & Sources'!E21+'Assumptions & Sources'!E23+E10 -> 907.22279 | F25: =E25+F6*'Assumptions & Sources'!F21+'Assumptions & Sources'!F23+F10 -> 924.36469 | G25: =F25+G6*'Assumptions & Sources'!G21+'Assumptions & Sources'!G23+G10 -> 944.86692 | H25: =G25+H6*'Assumptions & Sources'!H21+'Assumptions & Sources'!H23+H10 -> 967.42775 | I25: =H25+I6*'Assumptions & Sources'!I21+'Assumptions & Sources'!I23+I10 -> 990.36014
A26: Total assets | B26: 1168.456 | C26: 1294.746 | D26: 1262.878 | E26: =SUM(E21:E25) -> 1644.839 | F26: =SUM(F21:F25) -> 1872.7097 | G26: =SUM(G21:G25) -> 2100.5749 | H26: =SUM(H21:H25) -> 2269.9537 | I26: =SUM(I21:I25) -> 2349.404
A28: Trade & other payables | B28: 81.867 | C28: 111.853 | D28: 68.019 | E28: =E6/365*'Assumptions & Sources'!E18 -> 107.6292 | F28: =F6/365*'Assumptions & Sources'!F18 -> 140.89232 | G28: =G6/365*'Assumptions & Sources'!G18 -> 168.51145 | H28: =H6/365*'Assumptions & Sources'!H18 -> 185.43149 | I28: =I6/365*'Assumptions & Sources'!I18 -> 188.48541
A29: Other liabilities | B29: 122.122 | C29: 187.231 | D29: 153.408 | E29: =E6*'Assumptions & Sources'!E20 -> 196.42329 | F29: =F6*'Assumptions & Sources'!F20 -> 257.12848 | G29: =G6*'Assumptions & Sources'!G20 -> 307.53339 | H29: =H6*'Assumptions & Sources'!H20 -> 338.41246 | I29: =I6*'Assumptions & Sources'!I20 -> 343.98588
A30: Gross debt / lease liabilities | B30: 207.306 | C30: 241.786 | D30: 248.282 | E30: ='Assumptions & Sources'!E22 -> 450 | F30: ='Assumptions & Sources'!F22 -> 375 | G30: ='Assumptions & Sources'!G22 -> 300 | H30: ='Assumptions & Sources'!H22 -> 225 | I30: ='Assumptions & Sources'!I22 -> 150
A31: Total liabilities | B31: 411.295 | C31: 540.87 | D31: 469.709 | E31: =SUM(E28:E30) -> 754.05248 | F31: =SUM(F28:F30) -> 773.02079 | G31: =SUM(G28:G30) -> 776.04484 | H31: =SUM(H28:H30) -> 748.84395 | I31: =SUM(I28:I30) -> 682.47129
A32: Shareholders' equity | B32: 757.161 | C32: 753.877 | D32: 793.169 | E32: =D32+E15+E53 -> 890.78649 | F32: =E32+F15+F53 -> 1099.6889 | G32: =F32+G15+G53 -> 1324.5301 | H32: =G32+H15+H53 -> 1521.1098 | I32: =H32+I15+I53 -> 1666.9327
A33: Total liabilities & equity | B33: 1168.456 | C33: 1294.747 | D33: 1262.878 | E33: =E31+E32 -> 1644.839 | F33: =F31+F32 -> 1872.7097 | G33: =G31+G32 -> 2100.5749 | H33: =H31+H32 -> 2269.9537 | I33: =I31+I32 -> 2349.404
A34: BALANCE CHECK | B34: =B26-B33 -> 0 | C34: =C26-C33 -> -0.001 | D34: =D26-D33 -> 0 | E34: =E26-E33 -> 0 | F34: =F26-F33 -> 0 | G34: =G26-G33 -> 0 | H34: =H26-H33 -> 0 | I34: =I26-I33 -> 0
A38: CASH FLOW STATEMENT
A39: Net income | B39: =B15 -> 190.31 | C39: =C15 -> 211.799 | D39: =D15 -> 214.28 | E39: =E15 -> 307.61749 | F39: =F15 -> 439.61556 | G39: =G15 -> 554.55285 | H39: =H15 -> 612.49428 | I39: =I15 -> 605.1937
A40: D&A add-back | E40: =-E10 -> 54.99852 | F40: =-F10 -> 68.567594 | G40: =-G10 -> 82.008904 | H40: =-H10 -> 90.243324 | I40: =-I10 -> 91.729567
A41: Change in receivables | E41: =-(E22-D22) -> -35.678797 | F41: =-(F22-E22) -> -49.894677 | G41: =-(G22-F22) -> -35.811649 | H41: =-(H22-G22) -> -24.816059 | I41: =-(I22-H22) -> -4.47909
A42: Change in inventories | E42: =-(E23-D23) -> -96.990194 | F42: =-(F23-E23) -> -51.130363 | G42: =-(G23-F23) -> -26.966578 | H42: =-(H23-G23) -> -18.116938 | I42: =-(I23-H23) -> 6.2542491
A43: Change in other assets | E43: =-(E24-D24) -> -6.7846572 | F43: =-(F24-E24) -> -12.141038 | G43: =-(G24-F24) -> -10.080983 | H43: =-(H24-G24) -> -6.1758146 | I43: =-(I24-H24) -> -1.1146826
A44: Change in trade payables | E44: =E28-D28 -> 39.610198 | F44: =F28-E28 -> 33.263118 | G44: =G28-F28 -> 27.619131 | H44: =H28-G28 -> 16.92004 | I44: =I28-H28 -> 3.053925
A45: Change in other liabilities | E45: =E29-D29 -> 43.015286 | F45: =F29-E29 -> 60.70519 | G45: =G29-F29 -> 50.404915 | H45: =H29-G29 -> 30.879073 | I45: =I29-H29 -> 5.5734132
A46: Cash flow from operations | B46: 256.406 | C46: 240.642 | D46: 299.172 | E46: =SUM(E39:E45) -> 305.78785 | F46: =SUM(F39:F45) -> 488.98538 | G46: =SUM(G39:G45) -> 641.72659 | H46: =SUM(H39:H45) -> 701.42791 | I46: =SUM(I39:I45) -> 706.21108
A48: Capital expenditure | B48: -69.236 | C48: -55.668 | D48: -68.305 | E48: =-E6*'Assumptions & Sources'!E21 -> -78.569314 | F48: =-F6*'Assumptions & Sources'!F21 -> -85.709492 | G48: =-G6*'Assumptions & Sources'!G21 -> -102.51113 | H48: =-H6*'Assumptions & Sources'!H21 -> -112.80415 | I48: =-I6*'Assumptions & Sources'!I21 -> -114.66196
...

Sheet Valuation
A1: VAT GROUP AG — VALUATION
A2: FY28 EV/EBITDA framework. Target price is formula-driven from the operating model; FY28 revenue and EBITDA are analyst estimates.
A4: TARGET PRICE BRIDGE
A5: Metric | B5: Base case
A6: FY28E revenue (CHF m) | B6: ='3-Statement'!G6 -> 2050.2226
A7: FY28E EBITDA margin | B7: ='3-Statement'!G9 -> 0.37
A8: FY28E EBITDA (CHF m) | B8: ='3-Statement'!G8 -> 758.58236
A9: Target EV / EBITDA | B9: ='Assumptions & Sources'!G29 -> 31.4
A10: Target enterprise value (CHF m) | B10: =B8*B9 -> 23819.486
A11: FY28E gross debt (CHF m) | B11: ='3-Statement'!G30 -> 300
A12: FY28E cash (CHF m) | B12: ='3-Statement'!G21 -> 481.94309
A13: FY28E net debt / (cash) (CHF m) | B13: =B11-B12 -> -181.94309
A14: Target equity value (CHF m) | B14: =B10-B13 -> 24001.429
A15: Diluted shares (m) | B15: ='Assumptions & Sources'!G27 -> 30
A16: Target price (CHF/share) | B16: =B14/B15 -> 800.04764
A17: Reference price (CHF/share) | B17: ='Assumptions & Sources'!E45 -> 611.4
A18: Upside / (downside) | B18: =B16/B17-1 -> 0.30855028
A21: MODEL VS CONSENSUS
A22: Metric | B22: Model | C22: Consensus | D22: Premium / (discount)
A23: FY26E revenue | B23: ='3-Statement'!E6 -> 1309.4886 | C23: ='Assumptions & Sources'!E41 -> 1283 | D23: =B23/C23-1 -> 0.02064581
A24: FY27E revenue | B24: ='3-Statement'!F6 -> 1714.1898 | C24: ='Assumptions & Sources'!F41 -> 1626 | D24: =B24/C24-1 -> 0.054237294
A25: FY28E revenue | B25: ='3-Statement'!G6 -> 2050.2226 | C25: ='Assumptions & Sources'!G41 -> 1822 | D25: =B25/C25-1 -> 0.12525939
A26: FY28E EBITDA | B26: ='3-Statement'!G8 -> 758.58236 | C26: ='Assumptions & Sources'!G42 -> 664.5 | D26: =B26/C26-1 -> 0.14158369
A29: TARGET PRICE SENSITIVITY — FY28 EBITDA × EV/EBITDA
A30: FY28 EBITDA vs base | B30: 28 | C30: 30 | D30: 31.4 | E30: 33 | F30: 35
A31: 0.9 | B31: =($B$8*$A31*B$30-$B$13)/$B$15 -> 643.27396 | C31: =($B$8*$A31*C$30-$B$13)/$B$15 -> 688.7889 | D31: =($B$8*$A31*D$30-$B$13)/$B$15 -> 720.64936 | E31: =($B$8*$A31*E$30-$B$13)/$B$15 -> 757.06131 | F31: =($B$8*$A31*F$30-$B$13)/$B$15 -> 802.57625
A32: 0.95 | B32: =($B$8*$A32*B$30-$B$13)/$B$15 -> 678.67447 | C32: =($B$8*$A32*C$30-$B$13)/$B$15 -> 726.71802 | D32: =($B$8*$A32*D$30-$B$13)/$B$15 -> 760.3485 | E32: =($B$8*$A32*E$30-$B$13)/$B$15 -> 798.78334 | F32: =($B$8*$A32*F$30-$B$13)/$B$15 -> 846.82689
A33: 1 | B33: =($B$8*$A33*B$30-$B$13)/$B$15 -> 714.07498 | C33: =($B$8*$A33*C$30-$B$13)/$B$15 -> 764.64713 | D33: =($B$8*$A33*D$30-$B$13)/$B$15 -> 800.04764 | E33: =($B$8*$A33*E$30-$B$13)/$B$15 -> 840.50537 | F33: =($B$8*$A33*F$30-$B$13)/$B$15 -> 891.07753
A34: 1.05 | B34: =($B$8*$A34*B$30-$B$13)/$B$15 -> 749.47549 | C34: =($B$8*$A34*C$30-$B$13)/$B$15 -> 802.57625 | D34: =($B$8*$A34*D$30-$B$13)/$B$15 -> 839.74679 | E34: =($B$8*$A34*E$30-$B$13)/$B$15 -> 882.2274 | F34: =($B$8*$A34*F$30-$B$13)/$B$15 -> 935.32817
A35: 1.1 | B35: =($B$8*$A35*B$30-$B$13)/$B$15 -> 784.876 | C35: =($B$8*$A35*C$30-$B$13)/$B$15 -> 840.50537 | D35: =($B$8*$A35*D$30-$B$13)/$B$15 -> 879.44593 | E35: =($B$8*$A35*E$30-$B$13)/$B$15 -> 923.94943 | F35: =($B$8*$A35*F$30-$B$13)/$B$15 -> 979.5788
A38: VALUATION READ-THROUGH
A39: The CHF800 target requires FY28 EBITDA of ~CHF759m and a 31.4x FY28 EV/EBITDA multiple.
A40: Our FY28 EBITDA sits above the selected consensus snapshot because the model assumes stronger backlog conversion and structural outgrowth versus WFE.
A41: FY28 EBITDA margin of 37% is the top end of VAT's stated 30–37% medium-term corridor; this is an analyst assumption, not FY28 company guidance.
A42: The CHF110m Atonarp acquisition cash outflow is modeled in FY26; no separate Atonarp revenue contribution is included because it is not publicly disclosed.
