Workbook

Sheet Cover
B2: ZYDUS LIFESCIENCES DRUG-BY-DRUG PIPELINE MODEL
B5: FY26A-FY35E | First-principles sales, Zydus revenue capture, probability adjustment and contribution profit
B7: What this model does | C7: Builds each disclosed or material pipeline asset from patients, market sales, product count, units, pricing, share and partner economics. It then reconciles model outputs to the revenue ranges in the detailed note.
B10: How to use it | C10: Edit blue cells only. Every asset sheet has an inclusion toggle, launch curve, economics share, probability of success and margin. The Summary sheet pulls all product tabs and exposes reported and risk-adjusted revenue side by side.
B13: Critical caveat | C13: RK Pharma's molecule is not publicly disclosed. The workbook labels it as undisclosed and uses the disclosed 6.2m-unit addressable market. This is deliberate: the model remains decision-useful without inventing a product name.
B16: Portfolio read-through | C16: The near-term bridge is diversified across palbociclib, olaparib, Saroglitazar, ROLVEDON, NUFYMCO, 505(b)(2)/LiqMeds and biologics CDMO. FYB206 and Usnoflast are larger long-duration assets but should be valued with explicit probability and timing discounts.
B20: Prepared from the manager message, Zydus Detailed Note dated 6 September 2026, company disclosures and primary-source checks.

Sheet Summary
A1: Zydus pipeline model | Consolidated revenue bridge
A2: Reported revenue shows the commercial trajectory. Risk-adjusted revenue applies current product-specific probability of success. US$ millions unless stated.
A4: PORTFOLIO OUTPUTS
A5: Metric | B5: Units | D5: FY26A | E5: FY27E | F5: FY28E | G5: FY29E | H5: FY30E | I5: FY31E | J5: FY32E | K5: FY33E | L5: FY34E | M5: FY35E
A6: Total reported revenue | B6: $m | D6: =SUM(Saroglitazar!D38,Usnoflast!D38,Palbociclib!D38,Olaparib!D38,Ozanimod!D38,Letermovir!D38,Rifaximin!D38,Ibrutinib!D38,Cabozantinib!D38,'ZITUVIO Family'!D38,BEIZRAY!D38,'Synthon 505b2'!D38,NUFYMCO!D38,'FYB206 Pembro'!D38,'RK Pharma Asset'!D38,LiqMeds!D38,'Sentynl Orphans'!D38,ROLVEDON!D38,'Zylidac BOT-BAL'!D38,Tishtha!D38,'Semaglutide India'!D38) -> 113.3964 | E6: =SUM(Saroglitazar!E38,Usnoflast!E38,Palbociclib!E38,Olaparib!E38,Ozanimod!E38,Letermovir!E38,Rifaximin!E38,Ibrutinib!E38,Cabozantinib!E38,'ZITUVIO Family'!E38,BEIZRAY!E38,'Synthon 505b2'!E38,NUFYMCO!E38,'FYB206 Pembro'!E38,'RK Pharma Asset'!E38,LiqMeds!E38,'Sentynl Orphans'!E38,ROLVEDON!E38,'Zylidac BOT-BAL'!E38,Tishtha!E38,'Semaglutide India'!E38) -> 226.74977 | F6: =SUM(Saroglitazar!F38,Usnoflast!F38,Palbociclib!F38,Olaparib!F38,Ozanimod!F38,Letermovir!F38,Rifaximin!F38,Ibrutinib!F38,Cabozantinib!F38,'ZITUVIO Family'!F38,BEIZRAY!F38,'Synthon 505b2'!F38,NUFYMCO!F38,'FYB206 Pembro'!F38,'RK Pharma Asset'!F38,LiqMeds!F38,'Sentynl Orphans'!F38,ROLVEDON!F38,'Zylidac BOT-BAL'!F38,Tishtha!F38,'Semaglutide India'!F38) -> 545.73105 | G6: =SUM(Saroglitazar!G38,Usnoflast!G38,Palbociclib!G38,Olaparib!G38,Ozanimod!G38,Letermovir!G38,Rifaximin!G38,Ibrutinib!G38,Cabozantinib!G38,'ZITUVIO Family'!G38,BEIZRAY!G38,'Synthon 505b2'!G38,NUFYMCO!G38,'FYB206 Pembro'!G38,'RK Pharma Asset'!G38,LiqMeds!G38,'Sentynl Orphans'!G38,ROLVEDON!G38,'Zylidac BOT-BAL'!G38,Tishtha!G38,'Semaglutide India'!G38) -> 673.03715 | H6: =SUM(Saroglitazar!H38,Usnoflast!H38,Palbociclib!H38,Olaparib!H38,Ozanimod!H38,Letermovir!H38,Rifaximin!H38,Ibrutinib!H38,Cabozantinib!H38,'ZITUVIO Family'!H38,BEIZRAY!H38,'Synthon 505b2'!H38,NUFYMCO!H38,'FYB206 Pembro'!H38,'RK Pharma Asset'!H38,LiqMeds!H38,'Sentynl Orphans'!H38,ROLVEDON!H38,'Zylidac BOT-BAL'!H38,Tishtha!H38,'Semaglutide India'!H38) -> 867.42298 | I6: =SUM(Saroglitazar!I38,Usnoflast!I38,Palbociclib!I38,Olaparib!I38,Ozanimod!I38,Letermovir!I38,Rifaximin!I38,Ibrutinib!I38,Cabozantinib!I38,'ZITUVIO Family'!I38,BEIZRAY!I38,'Synthon 505b2'!I38,NUFYMCO!I38,'FYB206 Pembro'!I38,'RK Pharma Asset'!I38,LiqMeds!I38,'Sentynl Orphans'!I38,ROLVEDON!I38,'Zylidac BOT-BAL'!I38,Tishtha!I38,'Semaglutide India'!I38) -> 1020.3054 | J6: =SUM(Saroglitazar!J38,Usnoflast!J38,Palbociclib!J38,Olaparib!J38,Ozanimod!J38,Letermovir!J38,Rifaximin!J38,Ibrutinib!J38,Cabozantinib!J38,'ZITUVIO Family'!J38,BEIZRAY!J38,'Synthon 505b2'!J38,NUFYMCO!J38,'FYB206 Pembro'!J38,'RK Pharma Asset'!J38,LiqMeds!J38,'Sentynl Orphans'!J38,ROLVEDON!J38,'Zylidac BOT-BAL'!J38,Tishtha!J38,'Semaglutide India'!J38) -> 1133.8771 | K6: =SUM(Saroglitazar!K38,Usnoflast!K38,Palbociclib!K38,Olaparib!K38,Ozanimod!K38,Letermovir!K38,Rifaximin!K38,Ibrutinib!K38,Cabozantinib!K38,'ZITUVIO Family'!K38,BEIZRAY!K38,'Synthon 505b2'!K38,NUFYMCO!K38,'FYB206 Pembro'!K38,'RK Pharma Asset'!K38,LiqMeds!K38,'Sentynl Orphans'!K38,ROLVEDON!K38,'Zylidac BOT-BAL'!K38,Tishtha!K38,'Semaglutide India'!K38) -> 1237.5769 | ... M6: =SUM(Saroglitazar!M38,Usnoflast!M38,Palbociclib!M38,Olaparib!M38,Ozanimod!M38,Letermovir!M38,Rifaximin!M38,Ibrutinib!M38,Cabozantinib!M38,'ZITUVIO Family'!M38,BEIZRAY!M38,'Synthon 505b2'!M38,NUFYMCO!M38,'FYB206 Pembro'!M38,'RK Pharma Asset'!M38,LiqMeds!M38,'Sentynl Orphans'!M38,ROLVEDON!M38,'Zylidac BOT-BAL'!M38,Tishtha!M38,'Semaglutide India'!M38) -> 1592.584
A7: Total risk-adjusted revenue | B7: $m | D7: =SUM(Saroglitazar!D39,Usnoflast!D39,Palbociclib!D39,Olaparib!D39,Ozanimod!D39,Letermovir!D39,Rifaximin!D39,Ibrutinib!D39,Cabozantinib!D39,'ZITUVIO Family'!D39,BEIZRAY!D39,'Synthon 505b2'!D39,NUFYMCO!D39,'FYB206 Pembro'!D39,'RK Pharma Asset'!D39,LiqMeds!D39,'Sentynl Orphans'!D39,ROLVEDON!D39,'Zylidac BOT-BAL'!D39,Tishtha!D39,'Semaglutide India'!D39) -> 113.3964 | E7: =SUM(Saroglitazar!E39,Usnoflast!E39,Palbociclib!E39,Olaparib!E39,Ozanimod!E39,Letermovir!E39,Rifaximin!E39,Ibrutinib!E39,Cabozantinib!E39,'ZITUVIO Family'!E39,BEIZRAY!E39,'Synthon 505b2'!E39,NUFYMCO!E39,'FYB206 Pembro'!E39,'RK Pharma Asset'!E39,LiqMeds!E39,'Sentynl Orphans'!E39,ROLVEDON!E39,'Zylidac BOT-BAL'!E39,Tishtha!E39,'Semaglutide India'!E39) -> 226.74977 | F7: =SUM(Saroglitazar!F39,Usnoflast!F39,Palbociclib!F39,Olaparib!F39,Ozanimod!F39,Letermovir!F39,Rifaximin!F39,Ibrutinib!F39,Cabozantinib!F39,'ZITUVIO Family'!F39,BEIZRAY!F39,'Synthon 505b2'!F39,NUFYMCO!F39,'FYB206 Pembro'!F39,'RK Pharma Asset'!F39,LiqMeds!F39,'Sentynl Orphans'!F39,ROLVEDON!F39,'Zylidac BOT-BAL'!F39,Tishtha!F39,'Semaglutide India'!F39) -> 501.44789 | G7: =SUM(Saroglitazar!G39,Usnoflast!G39,Palbociclib!G39,Olaparib!G39,Ozanimod!G39,Letermovir!G39,Rifaximin!G39,Ibrutinib!G39,Cabozantinib!G39,'ZITUVIO Family'!G39,BEIZRAY!G39,'Synthon 505b2'!G39,NUFYMCO!G39,'FYB206 Pembro'!G39,'RK Pharma Asset'!G39,LiqMeds!G39,'Sentynl Orphans'!G39,ROLVEDON!G39,'Zylidac BOT-BAL'!G39,Tishtha!G39,'Semaglutide India'!G39) -> 615.70667 | H7: =SUM(Saroglitazar!H39,Usnoflast!H39,Palbociclib!H39,Olaparib!H39,Ozanimod!H39,Letermovir!H39,Rifaximin!H39,Ibrutinib!H39,Cabozantinib!H39,'ZITUVIO Family'!H39,BEIZRAY!H39,'Synthon 505b2'!H39,NUFYMCO!H39,'FYB206 Pembro'!H39,'RK Pharma Asset'!H39,LiqMeds!H39,'Sentynl Orphans'!H39,ROLVEDON!H39,'Zylidac BOT-BAL'!H39,Tishtha!H39,'Semaglutide India'!H39) -> 747.25749 | I7: =SUM(Saroglitazar!I39,Usnoflast!I39,Palbociclib!I39,Olaparib!I39,Ozanimod!I39,Letermovir!I39,Rifaximin!I39,Ibrutinib!I39,Cabozantinib!I39,'ZITUVIO Family'!I39,BEIZRAY!I39,'Synthon 505b2'!I39,NUFYMCO!I39,'FYB206 Pembro'!I39,'RK Pharma Asset'!I39,LiqMeds!I39,'Sentynl Orphans'!I39,ROLVEDON!I39,'Zylidac BOT-BAL'!I39,Tishtha!I39,'Semaglutide India'!I39) -> 847.66577 | J7: =SUM(Saroglitazar!J39,Usnoflast!J39,Palbociclib!J39,Olaparib!J39,Ozanimod!J39,Letermovir!J39,Rifaximin!J39,Ibrutinib!J39,Cabozantinib!J39,'ZITUVIO Family'!J39,BEIZRAY!J39,'Synthon 505b2'!J39,NUFYMCO!J39,'FYB206 Pembro'!J39,'RK Pharma Asset'!J39,LiqMeds!J39,'Sentynl Orphans'!J39,ROLVEDON!J39,'Zylidac BOT-BAL'!J39,Tishtha!J39,'Semaglutide India'!J39) -> 917.6005 | K7: =SUM(Saroglitazar!K39,Usnoflast!K39,Palbociclib!K39,Olaparib!K39,Ozanimod!K39,Letermovir!K39,Rifaximin!K39,Ibrutinib!K39,Cabozantinib!K39,'ZITUVIO Family'!K39,BEIZRAY!K39,'Synthon 505b2'!K39,NUFYMCO!K39,'FYB206 Pembro'!K39,'RK Pharma Asset'!K39,LiqMeds!K39,'Sentynl Orphans'!K39,ROLVEDON!K39,'Zylidac BOT-BAL'!K39,Tishtha!K39,'Semaglutide India'!K39) -> 961.55865 | ... M7: =SUM(Saroglitazar!M39,Usnoflast!M39,Palbociclib!M39,Olaparib!M39,Ozanimod!M39,Letermovir!M39,Rifaximin!M39,Ibrutinib!M39,Cabozantinib!M39,'ZITUVIO Family'!M39,BEIZRAY!M39,'Synthon 505b2'!M39,NUFYMCO!M39,'FYB206 Pembro'!M39,'RK Pharma Asset'!M39,LiqMeds!M39,'Sentynl Orphans'!M39,ROLVEDON!M39,'Zylidac BOT-BAL'!M39,Tishtha!M39,'Semaglutide India'!M39) -> 1026.415
A8: Total contribution profit | B8: $m | D8: =SUM(Saroglitazar!D41,Usnoflast!D41,Palbociclib!D41,Olaparib!D41,Ozanimod!D41,Letermovir!D41,Rifaximin!D41,Ibrutinib!D41,Cabozantinib!D41,'ZITUVIO Family'!D41,BEIZRAY!D41,'Synthon 505b2'!D41,NUFYMCO!D41,'FYB206 Pembro'!D41,'RK Pharma Asset'!D41,LiqMeds!D41,'Sentynl Orphans'!D41,ROLVEDON!D41,'Zylidac BOT-BAL'!D41,Tishtha!D41,'Semaglutide India'!D41) -> 31.352149 | E8: =SUM(Saroglitazar!E41,Usnoflast!E41,Palbociclib!E41,Olaparib!E41,Ozanimod!E41,Letermovir!E41,Rifaximin!E41,Ibrutinib!E41,Cabozantinib!E41,'ZITUVIO Family'!E41,BEIZRAY!E41,'Synthon 505b2'!E41,NUFYMCO!E41,'FYB206 Pembro'!E41,'RK Pharma Asset'!E41,LiqMeds!E41,'Sentynl Orphans'!E41,ROLVEDON!E41,'Zylidac BOT-BAL'!E41,Tishtha!E41,'Semaglutide India'!E41) -> 62.047527 | F8: =SUM(Saroglitazar!F41,Usnoflast!F41,Palbociclib!F41,Olaparib!F41,Ozanimod!F41,Letermovir!F41,Rifaximin!F41,Ibrutinib!F41,Cabozantinib!F41,'ZITUVIO Family'!F41,BEIZRAY!F41,'Synthon 505b2'!F41,NUFYMCO!F41,'FYB206 Pembro'!F41,'RK Pharma Asset'!F41,LiqMeds!F41,'Sentynl Orphans'!F41,ROLVEDON!F41,'Zylidac BOT-BAL'!F41,Tishtha!F41,'Semaglutide India'!F41) -> 147.45331 | G8: =SUM(Saroglitazar!G41,Usnoflast!G41,Palbociclib!G41,Olaparib!G41,Ozanimod!G41,Letermovir!G41,Rifaximin!G41,Ibrutinib!G41,Cabozantinib!G41,'ZITUVIO Family'!G41,BEIZRAY!G41,'Synthon 505b2'!G41,NUFYMCO!G41,'FYB206 Pembro'!G41,'RK Pharma Asset'!G41,LiqMeds!G41,'Sentynl Orphans'!G41,ROLVEDON!G41,'Zylidac BOT-BAL'!G41,Tishtha!G41,'Semaglutide India'!G41) -> 196.22379 | H8: =SUM(Saroglitazar!H41,Usnoflast!H41,Palbociclib!H41,Olaparib!H41,Ozanimod!H41,Letermovir!H41,Rifaximin!H41,Ibrutinib!H41,Cabozantinib!H41,'ZITUVIO Family'!H41,BEIZRAY!H41,'Synthon 505b2'!H41,NUFYMCO!H41,'FYB206 Pembro'!H41,'RK Pharma Asset'!H41,LiqMeds!H41,'Sentynl Orphans'!H41,ROLVEDON!H41,'Zylidac BOT-BAL'!H41,Tishtha!H41,'Semaglutide India'!H41) -> 261.41112 | I8: =SUM(Saroglitazar!I41,Usnoflast!I41,Palbociclib!I41,Olaparib!I41,Ozanimod!I41,Letermovir!I41,Rifaximin!I41,Ibrutinib!I41,Cabozantinib!I41,'ZITUVIO Family'!I41,BEIZRAY!I41,'Synthon 505b2'!I41,NUFYMCO!I41,'FYB206 Pembro'!I41,'RK Pharma Asset'!I41,LiqMeds!I41,'Sentynl Orphans'!I41,ROLVEDON!I41,'Zylidac BOT-BAL'!I41,Tishtha!I41,'Semaglutide India'!I41) -> 309.0973 | J8: =SUM(Saroglitazar!J41,Usnoflast!J41,Palbociclib!J41,Olaparib!J41,Ozanimod!J41,Letermovir!J41,Rifaximin!J41,Ibrutinib!J41,Cabozantinib!J41,'ZITUVIO Family'!J41,BEIZRAY!J41,'Synthon 505b2'!J41,NUFYMCO!J41,'FYB206 Pembro'!J41,'RK Pharma Asset'!J41,LiqMeds!J41,'Sentynl Orphans'!J41,ROLVEDON!J41,'Zylidac BOT-BAL'!J41,Tishtha!J41,'Semaglutide India'!J41) -> 349.82167 | K8: =SUM(Saroglitazar!K41,Usnoflast!K41,Palbociclib!K41,Olaparib!K41,Ozanimod!K41,Letermovir!K41,Rifaximin!K41,Ibrutinib!K41,Cabozantinib!K41,'ZITUVIO Family'!K41,BEIZRAY!K41,'Synthon 505b2'!K41,NUFYMCO!K41,'FYB206 Pembro'!K41,'RK Pharma Asset'!K41,LiqMeds!K41,'Sentynl Orphans'!K41,ROLVEDON!K41,'Zylidac BOT-BAL'!K41,Tishtha!K41,'Semaglutide India'!K41) -> 396.18879 | ... M8: =SUM(Saroglitazar!M41,Usnoflast!M41,Palbociclib!M41,Olaparib!M41,Ozanimod!M41,Letermovir!M41,Rifaximin!M41,Ibrutinib!M41,Cabozantinib!M41,'ZITUVIO Family'!M41,BEIZRAY!M41,'Synthon 505b2'!M41,NUFYMCO!M41,'FYB206 Pembro'!M41,'RK Pharma Asset'!M41,LiqMeds!M41,'Sentynl Orphans'!M41,ROLVEDON!M41,'Zylidac BOT-BAL'!M41,Tishtha!M41,'Semaglutide India'!M41) -> 599.13774
A9: Risk-adjusted contribution profit | B9: $m | D9: =SUM(Saroglitazar!D42,Usnoflast!D42,Palbociclib!D42,Olaparib!D42,Ozanimod!D42,Letermovir!D42,Rifaximin!D42,Ibrutinib!D42,Cabozantinib!D42,'ZITUVIO Family'!D42,BEIZRAY!D42,'Synthon 505b2'!D42,NUFYMCO!D42,'FYB206 Pembro'!D42,'RK Pharma Asset'!D42,LiqMeds!D42,'Sentynl Orphans'!D42,ROLVEDON!D42,'Zylidac BOT-BAL'!D42,Tishtha!D42,'Semaglutide India'!D42) -> 31.352149 | E9: =SUM(Saroglitazar!E42,Usnoflast!E42,Palbociclib!E42,Olaparib!E42,Ozanimod!E42,Letermovir!E42,Rifaximin!E42,Ibrutinib!E42,Cabozantinib!E42,'ZITUVIO Family'!E42,BEIZRAY!E42,'Synthon 505b2'!E42,NUFYMCO!E42,'FYB206 Pembro'!E42,'RK Pharma Asset'!E42,LiqMeds!E42,'Sentynl Orphans'!E42,ROLVEDON!E42,'Zylidac BOT-BAL'!E42,Tishtha!E42,'Semaglutide India'!E42) -> 62.047527 | F9: =SUM(Saroglitazar!F42,Usnoflast!F42,Palbociclib!F42,Olaparib!F42,Ozanimod!F42,Letermovir!F42,Rifaximin!F42,Ibrutinib!F42,Cabozantinib!F42,'ZITUVIO Family'!F42,BEIZRAY!F42,'Synthon 505b2'!F42,NUFYMCO!F42,'FYB206 Pembro'!F42,'RK Pharma Asset'!F42,LiqMeds!F42,'Sentynl Orphans'!F42,ROLVEDON!F42,'Zylidac BOT-BAL'!F42,Tishtha!F42,'Semaglutide India'!F42) -> 135.60272 | G9: =SUM(Saroglitazar!G42,Usnoflast!G42,Palbociclib!G42,Olaparib!G42,Ozanimod!G42,Letermovir!G42,Rifaximin!G42,Ibrutinib!G42,Cabozantinib!G42,'ZITUVIO Family'!G42,BEIZRAY!G42,'Synthon 505b2'!G42,NUFYMCO!G42,'FYB206 Pembro'!G42,'RK Pharma Asset'!G42,LiqMeds!G42,'Sentynl Orphans'!G42,ROLVEDON!G42,'Zylidac BOT-BAL'!G42,Tishtha!G42,'Semaglutide India'!G42) -> 179.62064 | H9: =SUM(Saroglitazar!H42,Usnoflast!H42,Palbociclib!H42,Olaparib!H42,Ozanimod!H42,Letermovir!H42,Rifaximin!H42,Ibrutinib!H42,Cabozantinib!H42,'ZITUVIO Family'!H42,BEIZRAY!H42,'Synthon 505b2'!H42,NUFYMCO!H42,'FYB206 Pembro'!H42,'RK Pharma Asset'!H42,LiqMeds!H42,'Sentynl Orphans'!H42,ROLVEDON!H42,'Zylidac BOT-BAL'!H42,Tishtha!H42,'Semaglutide India'!H42) -> 226.58391 | I9: =SUM(Saroglitazar!I42,Usnoflast!I42,Palbociclib!I42,Olaparib!I42,Ozanimod!I42,Letermovir!I42,Rifaximin!I42,Ibrutinib!I42,Cabozantinib!I42,'ZITUVIO Family'!I42,BEIZRAY!I42,'Synthon 505b2'!I42,NUFYMCO!I42,'FYB206 Pembro'!I42,'RK Pharma Asset'!I42,LiqMeds!I42,'Sentynl Orphans'!I42,ROLVEDON!I42,'Zylidac BOT-BAL'!I42,Tishtha!I42,'Semaglutide India'!I42) -> 260.4674 | J9: =SUM(Saroglitazar!J42,Usnoflast!J42,Palbociclib!J42,Olaparib!J42,Ozanimod!J42,Letermovir!J42,Rifaximin!J42,Ibrutinib!J42,Cabozantinib!J42,'ZITUVIO Family'!J42,BEIZRAY!J42,'Synthon 505b2'!J42,NUFYMCO!J42,'FYB206 Pembro'!J42,'RK Pharma Asset'!J42,LiqMeds!J42,'Sentynl Orphans'!J42,ROLVEDON!J42,'Zylidac BOT-BAL'!J42,Tishtha!J42,'Semaglutide India'!J42) -> 287.68458 | K9: =SUM(Saroglitazar!K42,Usnoflast!K42,Palbociclib!K42,Olaparib!K42,Ozanimod!K42,Letermovir!K42,Rifaximin!K42,Ibrutinib!K42,Cabozantinib!K42,'ZITUVIO Family'!K42,BEIZRAY!K42,'Synthon 505b2'!K42,NUFYMCO!K42,'FYB206 Pembro'!K42,'RK Pharma Asset'!K42,LiqMeds!K42,'Sentynl Orphans'!K42,ROLVEDON!K42,'Zylidac BOT-BAL'!K42,Tishtha!K42,'Semaglutide India'!K42) -> 306.18943 | ... M9: =SUM(Saroglitazar!M42,Usnoflast!M42,Palbociclib!M42,Olaparib!M42,Ozanimod!M42,Letermovir!M42,Rifaximin!M42,Ibrutinib!M42,Cabozantinib!M42,'ZITUVIO Family'!M42,BEIZRAY!M42,'Synthon 505b2'!M42,NUFYMCO!M42,'FYB206 Pembro'!M42,'RK Pharma Asset'!M42,LiqMeds!M42,'Sentynl Orphans'!M42,ROLVEDON!M42,'Zylidac BOT-BAL'!M42,Tishtha!M42,'Semaglutide India'!M42) -> 350.71092
A10: Total reported revenue | B10: INRm | D10: =SUM(Saroglitazar!D43,Usnoflast!D43,Palbociclib!D43,Olaparib!D43,Ozanimod!D43,Letermovir!D43,Rifaximin!D43,Ibrutinib!D43,Cabozantinib!D43,'ZITUVIO Family'!D43,BEIZRAY!D43,'Synthon 505b2'!D43,NUFYMCO!D43,'FYB206 Pembro'!D43,'RK Pharma Asset'!D43,LiqMeds!D43,'Sentynl Orphans'!D43,ROLVEDON!D43,'Zylidac BOT-BAL'!D43,Tishtha!D43,'Semaglutide India'!D43) -> 9752.09 | E10: =SUM(Saroglitazar!E43,Usnoflast!E43,Palbociclib!E43,Olaparib!E43,Ozanimod!E43,Letermovir!E43,Rifaximin!E43,Ibrutinib!E43,Cabozantinib!E43,'ZITUVIO Family'!E43,BEIZRAY!E43,'Synthon 505b2'!E43,NUFYMCO!E43,'FYB206 Pembro'!E43,'RK Pharma Asset'!E43,LiqMeds!E43,'Sentynl Orphans'!E43,ROLVEDON!E43,'Zylidac BOT-BAL'!E43,Tishtha!E43,'Semaglutide India'!E43) -> 19953.98 | F10: =SUM(Saroglitazar!F43,Usnoflast!F43,Palbociclib!F43,Olaparib!F43,Ozanimod!F43,Letermovir!F43,Rifaximin!F43,Ibrutinib!F43,Cabozantinib!F43,'ZITUVIO Family'!F43,BEIZRAY!F43,'Synthon 505b2'!F43,NUFYMCO!F43,'FYB206 Pembro'!F43,'RK Pharma Asset'!F43,LiqMeds!F43,'Sentynl Orphans'!F43,ROLVEDON!F43,'Zylidac BOT-BAL'!F43,Tishtha!F43,'Semaglutide India'!F43) -> 49115.795 | G10: =SUM(Saroglitazar!G43,Usnoflast!G43,Palbociclib!G43,Olaparib!G43,Ozanimod!G43,Letermovir!G43,Rifaximin!G43,Ibrutinib!G43,Cabozantinib!G43,'ZITUVIO Family'!G43,BEIZRAY!G43,'Synthon 505b2'!G43,NUFYMCO!G43,'FYB206 Pembro'!G43,'RK Pharma Asset'!G43,LiqMeds!G43,'Sentynl Orphans'!G43,ROLVEDON!G43,'Zylidac BOT-BAL'!G43,Tishtha!G43,'Semaglutide India'!G43) -> 61919.418 | H10: =SUM(Saroglitazar!H43,Usnoflast!H43,Palbociclib!H43,Olaparib!H43,Ozanimod!H43,Letermovir!H43,Rifaximin!H43,Ibrutinib!H43,Cabozantinib!H43,'ZITUVIO Family'!H43,BEIZRAY!H43,'Synthon 505b2'!H43,NUFYMCO!H43,'FYB206 Pembro'!H43,'RK Pharma Asset'!H43,LiqMeds!H43,'Sentynl Orphans'!H43,ROLVEDON!H43,'Zylidac BOT-BAL'!H43,Tishtha!H43,'Semaglutide India'!H43) -> 81537.76 | I10: =SUM(Saroglitazar!I43,Usnoflast!I43,Palbociclib!I43,Olaparib!I43,Ozanimod!I43,Letermovir!I43,Rifaximin!I43,Ibrutinib!I43,Cabozantinib!I43,'ZITUVIO Family'!I43,BEIZRAY!I43,'Synthon 505b2'!I43,NUFYMCO!I43,'FYB206 Pembro'!I43,'RK Pharma Asset'!I43,LiqMeds!I43,'Sentynl Orphans'!I43,ROLVEDON!I43,'Zylidac BOT-BAL'!I43,Tishtha!I43,'Semaglutide India'!I43) -> 97949.322 | J10: =SUM(Saroglitazar!J43,Usnoflast!J43,Palbociclib!J43,Olaparib!J43,Ozanimod!J43,Letermovir!J43,Rifaximin!J43,Ibrutinib!J43,Cabozantinib!J43,'ZITUVIO Family'!J43,BEIZRAY!J43,'Synthon 505b2'!J43,NUFYMCO!J43,'FYB206 Pembro'!J43,'RK Pharma Asset'!J43,LiqMeds!J43,'Sentynl Orphans'!J43,ROLVEDON!J43,'Zylidac BOT-BAL'!J43,Tishtha!J43,'Semaglutide India'!J43) -> 111119.95 | K10: =SUM(Saroglitazar!K43,Usnoflast!K43,Palbociclib!K43,Olaparib!K43,Ozanimod!K43,Letermovir!K43,Rifaximin!K43,Ibrutinib!K43,Cabozantinib!K43,'ZITUVIO Family'!K43,BEIZRAY!K43,'Synthon 505b2'!K43,NUFYMCO!K43,'FYB206 Pembro'!K43,'RK Pharma Asset'!K43,LiqMeds!K43,'Sentynl Orphans'!K43,ROLVEDON!K43,'Zylidac BOT-BAL'!K43,Tishtha!K43,'Semaglutide India'!K43) -> 123757.69 | ... M10: =SUM(Saroglitazar!M43,Usnoflast!M43,Palbociclib!M43,Olaparib!M43,Ozanimod!M43,Letermovir!M43,Rifaximin!M43,Ibrutinib!M43,Cabozantinib!M43,'ZITUVIO Family'!M43,BEIZRAY!M43,'Synthon 505b2'!M43,NUFYMCO!M43,'FYB206 Pembro'!M43,'RK Pharma Asset'!M43,LiqMeds!M43,'Sentynl Orphans'!M43,ROLVEDON!M43,'Zylidac BOT-BAL'!M43,Tishtha!M43,'Semaglutide India'!M43) -> 165628.74
A11: Total risk-adjusted revenue | B11: INRm | D11: =SUM(Saroglitazar!D44,Usnoflast!D44,Palbociclib!D44,Olaparib!D44,Ozanimod!D44,Letermovir!D44,Rifaximin!D44,Ibrutinib!D44,Cabozantinib!D44,'ZITUVIO Family'!D44,BEIZRAY!D44,'Synthon 505b2'!D44,NUFYMCO!D44,'FYB206 Pembro'!D44,'RK Pharma Asset'!D44,LiqMeds!D44,'Sentynl Orphans'!D44,ROLVEDON!D44,'Zylidac BOT-BAL'!D44,Tishtha!D44,'Semaglutide India'!D44) -> 9752.09 | E11: =SUM(Saroglitazar!E44,Usnoflast!E44,Palbociclib!E44,Olaparib!E44,Ozanimod!E44,Letermovir!E44,Rifaximin!E44,Ibrutinib!E44,Cabozantinib!E44,'ZITUVIO Family'!E44,BEIZRAY!E44,'Synthon 505b2'!E44,NUFYMCO!E44,'FYB206 Pembro'!E44,'RK Pharma Asset'!E44,LiqMeds!E44,'Sentynl Orphans'!E44,ROLVEDON!E44,'Zylidac BOT-BAL'!E44,Tishtha!E44,'Semaglutide India'!E44) -> 19953.98 | F11: =SUM(Saroglitazar!F44,Usnoflast!F44,Palbociclib!F44,Olaparib!F44,Ozanimod!F44,Letermovir!F44,Rifaximin!F44,Ibrutinib!F44,Cabozantinib!F44,'ZITUVIO Family'!F44,BEIZRAY!F44,'Synthon 505b2'!F44,NUFYMCO!F44,'FYB206 Pembro'!F44,'RK Pharma Asset'!F44,LiqMeds!F44,'Sentynl Orphans'!F44,ROLVEDON!F44,'Zylidac BOT-BAL'!F44,Tishtha!F44,'Semaglutide India'!F44) -> 45130.31 | G11: =SUM(Saroglitazar!G44,Usnoflast!G44,Palbociclib!G44,Olaparib!G44,Ozanimod!G44,Letermovir!G44,Rifaximin!G44,Ibrutinib!G44,Cabozantinib!G44,'ZITUVIO Family'!G44,BEIZRAY!G44,'Synthon 505b2'!G44,NUFYMCO!G44,'FYB206 Pembro'!G44,'RK Pharma Asset'!G44,LiqMeds!G44,'Sentynl Orphans'!G44,ROLVEDON!G44,'Zylidac BOT-BAL'!G44,Tishtha!G44,'Semaglutide India'!G44) -> 56645.013 | H11: =SUM(Saroglitazar!H44,Usnoflast!H44,Palbociclib!H44,Olaparib!H44,Ozanimod!H44,Letermovir!H44,Rifaximin!H44,Ibrutinib!H44,Cabozantinib!H44,'ZITUVIO Family'!H44,BEIZRAY!H44,'Synthon 505b2'!H44,NUFYMCO!H44,'FYB206 Pembro'!H44,'RK Pharma Asset'!H44,LiqMeds!H44,'Sentynl Orphans'!H44,ROLVEDON!H44,'Zylidac BOT-BAL'!H44,Tishtha!H44,'Semaglutide India'!H44) -> 70242.204 | I11: =SUM(Saroglitazar!I44,Usnoflast!I44,Palbociclib!I44,Olaparib!I44,Ozanimod!I44,Letermovir!I44,Rifaximin!I44,Ibrutinib!I44,Cabozantinib!I44,'ZITUVIO Family'!I44,BEIZRAY!I44,'Synthon 505b2'!I44,NUFYMCO!I44,'FYB206 Pembro'!I44,'RK Pharma Asset'!I44,LiqMeds!I44,'Sentynl Orphans'!I44,ROLVEDON!I44,'Zylidac BOT-BAL'!I44,Tishtha!I44,'Semaglutide India'!I44) -> 81375.914 | J11: =SUM(Saroglitazar!J44,Usnoflast!J44,Palbociclib!J44,Olaparib!J44,Ozanimod!J44,Letermovir!J44,Rifaximin!J44,Ibrutinib!J44,Cabozantinib!J44,'ZITUVIO Family'!J44,BEIZRAY!J44,'Synthon 505b2'!J44,NUFYMCO!J44,'FYB206 Pembro'!J44,'RK Pharma Asset'!J44,LiqMeds!J44,'Sentynl Orphans'!J44,ROLVEDON!J44,'Zylidac BOT-BAL'!J44,Tishtha!J44,'Semaglutide India'!J44) -> 89924.849 | K11: =SUM(Saroglitazar!K44,Usnoflast!K44,Palbociclib!K44,Olaparib!K44,Ozanimod!K44,Letermovir!K44,Rifaximin!K44,Ibrutinib!K44,Cabozantinib!K44,'ZITUVIO Family'!K44,BEIZRAY!K44,'Synthon 505b2'!K44,NUFYMCO!K44,'FYB206 Pembro'!K44,'RK Pharma Asset'!K44,LiqMeds!K44,'Sentynl Orphans'!K44,ROLVEDON!K44,'Zylidac BOT-BAL'!K44,Tishtha!K44,'Semaglutide India'!K44) -> 96155.865 | ... M11: =SUM(Saroglitazar!M44,Usnoflast!M44,Palbociclib!M44,Olaparib!M44,Ozanimod!M44,Letermovir!M44,Rifaximin!M44,Ibrutinib!M44,Cabozantinib!M44,'ZITUVIO Family'!M44,BEIZRAY!M44,'Synthon 505b2'!M44,NUFYMCO!M44,'FYB206 Pembro'!M44,'RK Pharma Asset'!M44,LiqMeds!M44,'Sentynl Orphans'!M44,ROLVEDON!M44,'Zylidac BOT-BAL'!M44,Tishtha!M44,'Semaglutide India'!M44) -> 106747.15
A13: RISK-ADJUSTED REVENUE BY CATEGORY
A14: Category | D14: FY26A | E14: FY27E | F14: FY28E | G14: FY29E | H14: FY30E | I14: FY31E | J14: FY32E | K14: FY33E | L14: FY34E | M14: FY35E
A15: NCE / innovation | D15: =SUM(Saroglitazar!D39,Usnoflast!D39) -> 0 | E15: =SUM(Saroglitazar!E39,Usnoflast!E39) -> 0 | F15: =SUM(Saroglitazar!F39,Usnoflast!F39) -> 18.186643 | G15: =SUM(Saroglitazar!G39,Usnoflast!G39) -> 62.452932 | H15: =SUM(Saroglitazar!H39,Usnoflast!H39) -> 113.93367 | I15: =SUM(Saroglitazar!I39,Usnoflast!I39) -> 158.80074 | J15: =SUM(Saroglitazar!J39,Usnoflast!J39) -> 199.16099 | K15: =SUM(Saroglitazar!K39,Usnoflast!K39) -> 242.2452 | ... M15: =SUM(Saroglitazar!M39,Usnoflast!M39) -> 368.94899
A16: Paragraph IV / complex generic | D16: =SUM(Palbociclib!D39,Olaparib!D39,Ozanimod!D39,Letermovir!D39,Rifaximin!D39,Ibrutinib!D39,Cabozantinib!D39) -> 0 | E16: =SUM(Palbociclib!E39,Olaparib!E39,Ozanimod!E39,Letermovir!E39,Rifaximin!E39,Ibrutinib!E39,Cabozantinib!E39) -> 0 | F16: =SUM(Palbociclib!F39,Olaparib!F39,Ozanimod!F39,Letermovir!F39,Rifaximin!F39,Ibrutinib!F39,Cabozantinib!F39) -> 167.50125 | G16: =SUM(Palbociclib!G39,Olaparib!G39,Ozanimod!G39,Letermovir!G39,Rifaximin!G39,Ibrutinib!G39,Cabozantinib!G39) -> 139.21113 | H16: =SUM(Palbociclib!H39,Olaparib!H39,Ozanimod!H39,Letermovir!H39,Rifaximin!H39,Ibrutinib!H39,Cabozantinib!H39) -> 160.04265 | I16: =SUM(Palbociclib!I39,Olaparib!I39,Ozanimod!I39,Letermovir!I39,Rifaximin!I39,Ibrutinib!I39,Cabozantinib!I39) -> 144.20694 | J16: =SUM(Palbociclib!J39,Olaparib!J39,Ozanimod!J39,Letermovir!J39,Rifaximin!J39,Ibrutinib!J39,Cabozantinib!J39) -> 119.34174 | K16: =SUM(Palbociclib!K39,Olaparib!K39,Ozanimod!K39,Letermovir!K39,Rifaximin!K39,Ibrutinib!K39,Cabozantinib!K39) -> 89.43595 | ... M16: =SUM(Palbociclib!M39,Olaparib!M39,Ozanimod!M39,Letermovir!M39,Rifaximin!M39,Ibrutinib!M39,Cabozantinib!M39) -> 46.47283
A17: 505(b)(2) / differentiated | D17: =SUM('ZITUVIO Family'!D39,BEIZRAY!D39,'Synthon 505b2'!D39,'RK Pharma Asset'!D39,LiqMeds!D39) -> 47.825 | E17: =SUM('ZITUVIO Family'!E39,BEIZRAY!E39,'Synthon 505b2'!E39,'RK Pharma Asset'!E39,LiqMeds!E39) -> 62.23 | F17: =SUM('ZITUVIO Family'!F39,BEIZRAY!F39,'Synthon 505b2'!F39,'RK Pharma Asset'!F39,LiqMeds!F39) -> 82.21 | G17: =SUM('ZITUVIO Family'!G39,BEIZRAY!G39,'Synthon 505b2'!G39,'RK Pharma Asset'!G39,LiqMeds!G39) -> 110.192 | H17: =SUM('ZITUVIO Family'!H39,BEIZRAY!H39,'Synthon 505b2'!H39,'RK Pharma Asset'!H39,LiqMeds!H39) -> 134.723 | I17: =SUM('ZITUVIO Family'!I39,BEIZRAY!I39,'Synthon 505b2'!I39,'RK Pharma Asset'!I39,LiqMeds!I39) -> 146.841 | J17: =SUM('ZITUVIO Family'!J39,BEIZRAY!J39,'Synthon 505b2'!J39,'RK Pharma Asset'!J39,LiqMeds!J39) -> 143.79665 | K17: =SUM('ZITUVIO Family'!K39,BEIZRAY!K39,'Synthon 505b2'!K39,'RK Pharma Asset'!K39,LiqMeds!K39) -> 139.4235 | ... M17: =SUM('ZITUVIO Family'!M39,BEIZRAY!M39,'Synthon 505b2'!M39,'RK Pharma Asset'!M39,LiqMeds!M39) -> 125.2469
A18: Acquired specialty / orphan | D18: =SUM('Sentynl Orphans'!D39) -> 59.99 | E18: =SUM('Sentynl Orphans'!E39) -> 66.21 | F18: =SUM('Sentynl Orphans'!F39) -> 74.22 | G18: =SUM('Sentynl Orphans'!G39) -> 85.34 | H18: =SUM('Sentynl Orphans'!H39) -> 94.91 | I18: =SUM('Sentynl Orphans'!I39) -> 103.96 | J18: =SUM('Sentynl Orphans'!J39) -> 112.26 | K18: =SUM('Sentynl Orphans'!K39) -> 120.56 | ... M18: =SUM('Sentynl Orphans'!M39) -> 137.16
A19: Acquired specialty / oncology supportive care | D19: =SUM(ROLVEDON!D39) -> 0 | E19: =SUM(ROLVEDON!E39) -> 66.12 | F19: =SUM(ROLVEDON!F39) -> 78.1 | G19: =SUM(ROLVEDON!G39) -> 79.508 | H19: =SUM(ROLVEDON!H39) -> 77.112 | I19: =SUM(ROLVEDON!I39) -> 74.48 | J19: =SUM(ROLVEDON!J39) -> 71.63 | K19: =SUM(ROLVEDON!K39) -> 68.58 | ... M19: =SUM(ROLVEDON!M39) -> 61.952
A20: Biologics CDMO / innovation | D20: =SUM('Zylidac BOT-BAL'!D39) -> 0 | E20: =SUM('Zylidac BOT-BAL'!E39) -> 12 | F20: =SUM('Zylidac BOT-BAL'!F39) -> 24 | G20: =SUM('Zylidac BOT-BAL'!G39) -> 40 | H20: =SUM('Zylidac BOT-BAL'!H39) -> 44 | I20: =SUM('Zylidac BOT-BAL'!I39) -> 48 | J20: =SUM('Zylidac BOT-BAL'!J39) -> 53 | K20: =SUM('Zylidac BOT-BAL'!K39) -> 60.6 | ... M20: =SUM('Zylidac BOT-BAL'!M39) -> 75
A21: ASSET-BY-ASSET REPORTED REVENUE TRAJECTORY
A22: Asset | B22: Category | C22: Geography | D22: Status / launch | E22: Confidence | F22: Report benchmark | G22: FY26A | H22: FY27E | I22: FY28E | J22: FY29E | K22: FY30E | L22: FY31E | M22: FY32E | N22: FY33E | O22: FY34E | P22: FY35E | Q22: Model peak | R22: Range check | S22: FY29 contrib. | T22: Include
A23: Saroglitazar | US PBC | B23: NCE / innovation | C23: US | D23: PDUFA 27-Nov-2026; target launch Apr-2027 (FY28) | E23: High | F23: $200-300m Peak | G23: =Saroglitazar!D38 -> 0 | H23: =Saroglitazar!E38 -> 0 | I23: =Saroglitazar!F38 -> 21.396051 | J23: =Saroglitazar!G38 -> 73.474038 | K23: =Saroglitazar!H38 -> 134.03961 | L23: =Saroglitazar!I38 -> 186.8244 | M23: =Saroglitazar!J38 -> 234.30704 | N23: =Saroglitazar!K38 -> 267.24559 | ... P23: =Saroglitazar!M38 -> 292.78035 | Q23: =MAX(G23:P23) -> 292.78035 | R23: =Saroglitazar!B13 -> Within range | S23: =Saroglitazar!G41 -> 22.042211 | T23: =Saroglitazar!B9 -> 1
A24: Usnoflast | US ALS | B24: NCE / innovation | C24: US | D24: Phase IIb UNITE-ALS; CY28 readout; launch FY33 earliest | E24: Medium | F24: $300-500m Peak | G24: =Usnoflast!D38 -> 0 | H24: =Usnoflast!E38 -> 0 | I24: =Usnoflast!F38 -> 0 | J24: =Usnoflast!G38 -> 0 | K24: =Usnoflast!H38 -> 0 | L24: =Usnoflast!I38 -> 0 | M24: =Usnoflast!J38 -> 0 | N24: =Usnoflast!K38 -> 60.345779 | ... P24: =Usnoflast!M38 -> 480.34276 | Q24: =MAX(G24:P24) -> 480.34276 | R24: =Usnoflast!B13 -> Within range | S24: =Usnoflast!G41 -> 0 | T24: =Usnoflast!B9 -> 1
A25: Palbociclib | Paragraph IV | B25: Paragraph IV / complex generic | C25: US | D25: Synthon sole first applicant for tablets; modeled launch FY28 | E25: High | F25: $120-180m Peak | G25: =Palbociclib!D38 -> 0 | H25: =Palbociclib!E38 -> 0 | I25: =Palbociclib!F38 -> 143.325 | J25: =Palbociclib!G38 -> 80.73 | K25: =Palbociclib!H38 -> 47.9115 | L25: =Palbociclib!I38 -> 30.875 | M25: =Palbociclib!J38 -> 20.332 | N25: =Palbociclib!K38 -> 15.015 | ... P25: =Palbociclib!M38 -> 7.15 | Q25: =MAX(G25:P25) -> 143.325 | R25: =Palbociclib!B13 -> Within range | S25: =Palbociclib!G41 -> 17.7606 | T25: =Palbociclib!B9 -> 1
A26: Olaparib | Paragraph IV | B26: Paragraph IV / complex generic | C26: US | D26: Earliest plausible entry Sep-2027; modeled FY28 partial-year launch | E26: High | F26: $60-100m Peak | G26: =Olaparib!D38 -> 0 | H26: =Olaparib!E38 -> 0 | I26: =Olaparib!F38 -> 65.25 | J26: =Olaparib!G38 -> 85 | K26: =Olaparib!H38 -> 57.04 | L26: =Olaparib!I38 -> 40.04 | M26: =Olaparib!J38 -> 27.5 | N26: =Olaparib!K38 -> 17.82 | ... P26: =Olaparib!M38 -> 8.96 | Q26: =MAX(G26:P26) -> 85 | R26: =Olaparib!B13 -> Within range | S26: =Olaparib!G41 -> 28.05 | T26: =Olaparib!B9 -> 1
A27: Ozanimod | Synthon Paragraph IV | B27: Paragraph IV / complex generic | C27: US | D27: Partnered with Synthon; modeled launch FY30 | E27: Medium | F27: $40-70m Peak | G27: =Ozanimod!D38 -> 0 | H27: =Ozanimod!E38 -> 0 | I27: =Ozanimod!F38 -> 0 | J27: =Ozanimod!G38 -> 0 | K27: =Ozanimod!H38 -> 42.9975 | L27: =Ozanimod!I38 -> 39.6032 | M27: =Ozanimod!J38 -> 26.026 | N27: =Ozanimod!K38 -> 18.252 | ... P27: =Ozanimod!M38 -> 8.9232 | Q27: =MAX(G27:P27) -> 42.9975 | R27: =Ozanimod!B13 -> Within range | S27: =Ozanimod!G41 -> 0 | T27: =Ozanimod!B9 -> 1
A28: Letermovir | Paragraph IV | B28: Paragraph IV / complex generic | C28: US | D28: Transplant anti-infective; modeled launch FY29 | E28: Medium | F28: $20-40m Peak | G28: =Letermovir!D38 -> 0 | H28: =Letermovir!E38 -> 0 | I28: =Letermovir!F38 -> 0 | J28: =Letermovir!G38 -> 17.0625 | K28: =Letermovir!H38 -> 24.31 | L28: =Letermovir!I38 -> 18.46325 | M28: =Letermovir!J38 -> 14.1856 | N28: =Letermovir!K38 -> 10.556 | ... P28: =Letermovir!M38 -> 5.525 | Q28: =MAX(G28:P28) -> 24.31 | R28: =Letermovir!B13 -> Within range | S28: =Letermovir!G41 -> 4.7775 | T28: =Letermovir!B9 -> 1
A29: Rifaximin 550mg | Paragraph IV | B29: Paragraph IV / complex generic | C29: US | D29: Dense patent estate; modeled launch FY30 | E29: Medium | F29: $75-120m Peak | G29: =Rifaximin!D38 -> 0 | H29: =Rifaximin!E38 -> 0 | I29: =Rifaximin!F38 -> 0 | J29: =Rifaximin!G38 -> 0 | K29: =Rifaximin!H38 -> 71.28 | L29: =Rifaximin!I38 -> 75.264 | M29: =Rifaximin!J38 -> 58.968 | N29: =Rifaximin!K38 -> 43.2 | ... P29: =Rifaximin!M38 -> 23.76 | Q29: =MAX(G29:P29) -> 75.264 | R29: =Rifaximin!B13 -> Within range | S29: =Rifaximin!G41 -> 0 | T29: =Rifaximin!B9 -> 1
A30: Ibrutinib | Paragraph IV | B30: Paragraph IV / complex generic | C30: US | D30: Tentative approval / later oncology opportunity; modeled FY31 | E30: Low | F30: $25-50m Peak | G30: =Ibrutinib!D38 -> 0 | H30: =Ibrutinib!E38 -> 0 | I30: =Ibrutinib!F38 -> 0 | J30: =Ibrutinib!G38 -> 0 | K30: =Ibrutinib!H38 -> 0 | L30: =Ibrutinib!I38 -> 29.12 | M30: =Ibrutinib!J38 -> 32.2 | N30: =Ibrutinib!K38 -> 22.8 | ... P30: =Ibrutinib!M38 -> 11.34 | Q30: =MAX(G30:P30) -> 32.2 | R30: =Ibrutinib!B13 -> Within range | S30: =Ibrutinib!G41 -> 0 | T30: =Ibrutinib!B9 -> 1
A31: Cabozantinib | Paragraph IV | B31: Paragraph IV / complex generic | C31: US | D31: Later oncology opportunity; modeled FY32 | E31: Low | F31: $25-50m Peak | G31: =Cabozantinib!D38 -> 0 | H31: =Cabozantinib!E38 -> 0 | I31: =Cabozantinib!F38 -> 0 | J31: =Cabozantinib!G38 -> 0 | K31: =Cabozantinib!H38 -> 0 | L31: =Cabozantinib!I38 -> 0 | M31: =Cabozantinib!J38 -> 27.72 | N31: =Cabozantinib!K38 -> 31.185 | ... P31: =Cabozantinib!M38 -> 17.955 | Q31: =MAX(G31:P31) -> 31.185 | R31: =Cabozantinib!B13 -> Within range | S31: =Cabozantinib!G41 -> 0 | T31: =Cabozantinib!B9 -> 1
A32: ZITUVIO / ZITUVIMET / XR | B32: 505(b)(2) / differentiated | C32: US | D32: Commercial; existing 505(b)(2) cluster | E32: High | F32: $30-40m Peak | G32: ='ZITUVIO Family'!D38 -> 27.2 | H32: ='ZITUVIO Family'!E38 -> 31.35 | I32: ='ZITUVIO Family'!F38 -> 34 | J32: ='ZITUVIO Family'!G38 -> 35 | K32: ='ZITUVIO Family'!H38 -> 35 | L32: ='ZITUVIO Family'!I38 -> 34 | M32: ='ZITUVIO Family'!J38 -> 33 | N32: ='ZITUVIO Family'!K38 -> 32 | ... P32: ='ZITUVIO Family'!M38 -> 27 | Q32: =MAX(G32:P32) -> 35 | R32: ='ZITUVIO Family'!B13 -> Within range | S32: ='ZITUVIO Family'!G41 -> 10.15 | T32: ='ZITUVIO Family'!B9 -> 1
A33: BEIZRAY | Albumin-solubilised docetaxel | B33: 505(b)(2) / differentiated | C33: US | D33: FDA-approved and launched; uptake slower than expected | E33: High | F33: $15-25m Peak | G33: =BEIZRAY!D38 -> 3.3 | H33: =BEIZRAY!E38 -> 7.48 | I33: =BEIZRAY!F38 -> 12.21 | J33: =BEIZRAY!G38 -> 19.8 | K33: =BEIZRAY!H38 -> 20.295 | L33: =BEIZRAY!I38 -> 19.1675 | M33: =BEIZRAY!J38 -> 17.6 | N33: =BEIZRAY!K38 -> 16.0875 | ... P33: =BEIZRAY!M38 -> 13.2275 | Q33: =MAX(G33:P33) -> 20.295 | R33: =BEIZRAY!B13 -> Within range | S33: =BEIZRAY!G41 -> 5.94 | T33: =BEIZRAY!B9 -> 1
A34: Synthon | Undisclosed 505(b)(2) | B34: 505(b)(2) / differentiated | C34: US | D34: Partnered, molecule undisclosed; modeled launch FY30 | E34: Low | F34: $20-35m Peak | G34: ='Synthon 505b2'!D38 -> 0 | H34: ='Synthon 505b2'!E38 -> 0 | I34: ='Synthon 505b2'!F38 -> 0 | J34: ='Synthon 505b2'!G38 -> 0 | K34: ='Synthon 505b2'!H38 -> 15.6672 | L34: ='Synthon 505b2'!I38 -> 28.611 | M34: ='Synthon 505b2'!J38 -> 27.6573 | N34: ='Synthon 505b2'!K38 -> 23.936 | ... P34: ='Synthon 505b2'!M38 -> 17.85 | Q34: =MAX(G34:P34) -> 28.611 | R34: ='Synthon 505b2'!B13 -> Within range | S34: ='Synthon 505b2'!G41 -> 0 | T34: ='Synthon 505b2'!B9 -> 1
A35: NUFYMCO | Ranibizumab biosimilar | B35: Biosimilar | C35: US | D35: FDA-approved interchangeable biosimilar; US launch ramp | E35: High | F35: $60-90m Peak | G35: =NUFYMCO!D38 -> 0 | H35: =NUFYMCO!E38 -> 0 | I35: =NUFYMCO!F38 -> 20.25 | J35: =NUFYMCO!G38 -> 48.72 | K35: =NUFYMCO!H38 -> 64.4 | L35: =NUFYMCO!I38 -> 65.34 | M35: =NUFYMCO!J38 -> 58.905 | N35: =NUFYMCO!K38 -> 48 | ... P35: =NUFYMCO!M38 -> 30.24 | Q35: =MAX(G35:P35) -> 65.34 | R35: =NUFYMCO!B13 -> Within range | S35: =NUFYMCO!G41 -> 11.6928 | T35: =NUFYMCO!B9 -> 1
A36: FYB206 | Pembrolizumab biosimilar | B36: Biosimilar | C36: US | D36: Positive PK study; filing path; modeled launch FY31 | E36: Medium | F36: $150-250m Peak | G36: ='FYB206 Pembro'!D38 -> 0 | H36: ='FYB206 Pembro'!E38 -> 0 | I36: ='FYB206 Pembro'!F38 -> 0 | J36: ='FYB206 Pembro'!G38 -> 0 | K36: ='FYB206 Pembro'!H38 -> 0 | L36: ='FYB206 Pembro'!I38 -> 75.6 | M36: ='FYB206 Pembro'!J38 -> 162 | N36: ='FYB206 Pembro'!K38 -> 216 | ... P36: ='FYB206 Pembro'!M38 -> 198 | Q36: =MAX(G36:P36) -> 216 | R36: ='FYB206 Pembro'!B13 -> Within range | S36: ='FYB206 Pembro'!G41 -> 0 | T36: ='FYB206 Pembro'!B9 -> 1
A37: RK Pharma | Undisclosed oncology supportive-care injectable | B37: 505(b)(2) / differentiated | C37: US | D37: Molecule not publicly disclosed; NDA filing targeted in 2026; modeled launch FY29 | E37: Low | F37: $20-35m Peak | G37: ='RK Pharma Asset'!D38 -> 0 | H37: ='RK Pharma Asset'!E38 -> 0 | I37: ='RK Pharma Asset'!F38 -> 0 | J37: ='RK Pharma Asset'!G38 -> 6.82 | K37: ='RK Pharma Asset'!H38 -> 21.824 | L37: ='RK Pharma Asset'!I38 -> 27.28 | M37: ='RK Pharma Asset'!J38 -> 27.28 | N37: ='RK Pharma Asset'!K38 -> 27.28 | ... P37: ='RK Pharma Asset'!M38 -> 21.824 | Q37: =MAX(G37:P37) -> 27.28 | R37: ='RK Pharma Asset'!B13 -> Within range | S37: ='RK Pharma Asset'!G41 -> 1.364 | T37: ='RK Pharma Asset'!B9 -> 1
A38: LiqMeds | Oral-liquid portfolio | B38: 505(b)(2) / differentiated | C38: US | D38: 14 filings, 10 approvals, 7 launches disclosed | E38: High | F38: $45-70m Peak | G38: =LiqMeds!D38 -> 17.325 | H38: =LiqMeds!E38 -> 23.4 | I38: =LiqMeds!F38 -> 36 | J38: =LiqMeds!G38 -> 51.3 | K38: =LiqMeds!H38 -> 58.5 | L38: =LiqMeds!I38 -> 63 | M38: =LiqMeds!J38 -> 63 | N38: =LiqMeds!K38 -> 63 | ... P38: =LiqMeds!M38 -> 63 | Q38: =MAX(G38:P38) -> 63 | R38: =LiqMeds!B13 -> Within range | S38: =LiqMeds!G41 -> 13.338 | T38: =LiqMeds!B9 -> 1
A39: Sentynl | Combined orphan-drug portfolio | B39: Acquired specialty / orphan | C39: US / select ex-US | D39: Commercial: NULIBRY, ZOKINVY, ZYCUBO | E39: High | F39: $75-90m FY29 | G39: ='Sentynl Orphans'!D38 -> 59.99 | H39: ='Sentynl Orphans'!E38 -> 66.21 | I39: ='Sentynl Orphans'!F38 -> 74.22 | J39: ='Sentynl Orphans'!G38 -> 85.34 | K39: ='Sentynl Orphans'!H38 -> 94.91 | L39: ='Sentynl Orphans'!I38 -> 103.96 | M39: ='Sentynl Orphans'!J38 -> 112.26 | N39: ='Sentynl Orphans'!K38 -> 120.56 | ... P39: ='Sentynl Orphans'!M38 -> 137.16 | Q39: =MAX(G39:P39) -> 137.16 | R39: ='Sentynl Orphans'!B13 -> Within range | S39: ='Sentynl Orphans'!G41 -> 31.5758 | T39: ='Sentynl Orphans'!B9 -> 1
A40: ROLVEDON | Long-acting G-CSF | B40: Acquired specialty / oncology supportive care | C40: US | D40: Commercial; Assertio acquisition; US$15-20m quarterly run-rate guided from Q2FY27 | E40: High | F40: $75-85m FY29 | G40: =ROLVEDON!D38 -> 0 | H40: =ROLVEDON!E38 -> 66.12 | I40: =ROLVEDON!F38 -> 78.1 | J40: =ROLVEDON!G38 -> 79.508 | K40: =ROLVEDON!H38 -> 77.112 | L40: =ROLVEDON!I38 -> 74.48 | M40: =ROLVEDON!J38 -> 71.63 | N40: =ROLVEDON!K38 -> 68.58 | ... P40: =ROLVEDON!M38 -> 61.952 | Q40: =MAX(G40:P40) -> 79.508 | R40: =ROLVEDON!B13 -> Within range | S40: =ROLVEDON!G41 -> 23.8524 | T40: =ROLVEDON!B9 -> 1
A41: Zylidac Bio | BOT/BAL CDMO + regional rights | B41: Biologics CDMO / innovation | C41: US manufacturing; India/Sri Lanka rights | D41: Two US facilities acquired; BOT/BAL manufacturing live; regional launch FY32 earliest | E41: Medium | F41: $35-45m FY29 | G41: ='Zylidac BOT-BAL'!D38 -> 0 | H41: ='Zylidac BOT-BAL'!E38 -> 12 | I41: ='Zylidac BOT-BAL'!F38 -> 24 | J41: ='Zylidac BOT-BAL'!G38 -> 40 | K41: ='Zylidac BOT-BAL'!H38 -> 44 | L41: ='Zylidac BOT-BAL'!I38 -> 48 | M41: ='Zylidac BOT-BAL'!J38 -> 57 | N41: ='Zylidac BOT-BAL'!K38 -> 72.6 | ... P41: ='Zylidac BOT-BAL'!M38 -> 103 | Q41: =MAX(G41:P41) -> 103 | R41: ='Zylidac BOT-BAL'!B13 -> Within range | S41: ='Zylidac BOT-BAL'!G41 -> 8.8 | T41: ='Zylidac BOT-BAL'!B9 -> 1
A42: Tishtha | India nivolumab biosimilar | B42: Biosimilar | C42: India | D42: Commercial launch Jan-2026 | E42: High | F42: INR2.0-3.0bn Peak | G42: =Tishtha!D38 -> 5.5813953 | H42: =Tishtha!E38 -> 9.9715909 | I42: =Tishtha!F38 -> 17.48 | J42: =Tishtha!G38 -> 25.336957 | K42: =Tishtha!H38 -> 29.412766 | L42: =Tishtha!I38 -> 29.53125 | M42: =Tishtha!J38 -> 29.142857 | N42: =Tishtha!K38 -> 28.314 | ... P42: =Tishtha!M38 -> 25.575 | Q42: =MAX(G42:P42) -> 29.53125 | R42: =Tishtha!B13 -> Within range | S42: =Tishtha!G41 -> 8.8679348 | T42: =Tishtha!B9 -> 1
...

Sheet Global Assump
A1: Global assumptions
A2: Common currency and model conventions. Blue cells are editable inputs; green formulas are cross-sheet links.
A3: CURRENCY | D3: FY26A | E3: FY27E | F3: FY28E | G3: FY29E | H3: FY30E | I3: FY31E | J3: FY32E | K3: FY33E | L3: FY34E | M3: FY35E
A4: INR / US$ | B4: INR per US$ | C4: 2.1% long-run depreciation assumption | D4: 86 | E4: 88 | F4: 90 | G4: 92 | H4: 94 | I4: 96 | J4: 98 | K4: 100 | L4: 102 | M4: 104
A7: MODEL CONVENTIONS
A8: Revenue basis | B8: Reported revenue is Zydus's accounting revenue after partner economics. End-market sales are shown separately.
A9: Risk adjustment | B9: Commercial revenue × current probability of success. Commercial/approved assets use 100%.
A10: Contribution profit | B10: Product-level EBITDA/contribution proxy. It is not a consolidated company EBITDA forecast.
A11: Peak range checks | B11: Checks compare the model with the report's stated mean/peak or specified-year range.
A12: RK Pharma identity | B12: The molecule is undisclosed. The model uses the disclosed 6.2m-unit TAM and an editable revenue/unit assumption.
A13: MASH | B13: Saroglitazar MASH revenue is excluded, consistent with the report.
A16: COLOUR CONVENTION
A17: Blue font / pale yellow fill | B17: Editable assumption
A18: Black font | B18: Within-sheet formula
A19: Green font | B19: Cross-sheet link
A20: Green check | B20: Model lands within report benchmark range
A21: Amber check | B21: Model sits outside the stated range and needs review

Sheet Saroglitazar
A1: Saroglitazar | US PBC
A2: US PBC is the first internal NCE earnings contributor; patient share and access, rather than list price, drive the build.
A4: ASSET FRAME
A5: Asset / franchise | B5: Saroglitazar | US PBC
A6: Category | B6: NCE / innovation
A7: Geography | B7: US
A8: Status / launch window | B8: PDUFA 27-Nov-2026; target launch Apr-2027 (FY28)
A9: Include in Summary? | B9: 1
A10: Report benchmark low ($m) | B10: 200
A11: Report benchmark high ($m) | B11: 300
A12: Model benchmark value (Peak) | B12: =MAX(D38:M38) -> 292.78035
A13: Benchmark check | B13: =IF(AND(B12>=B10,B12<=B11),"Within range",IF(B12<B10,"Below range","Above range")) -> Within range
A14: Evidence confidence | B14: High
A15: Principal risk | B15: Label breadth, payer access, pruritus claim and launch execution
A16: Primary benchmark source | B16: Zydus Detailed Note, pp. 15-17; Zydus Therapeutics EPICS-III
A18: FIRST-PRINCIPLES COMMERCIAL BUILD
A19: Commercial driver | B19: Units | C19: Source / interpretation | D19: FY26A | E19: FY27E | F19: FY28E | G19: FY29E | H19: FY30E | I19: FY31E | J19: FY32E | K19: FY33E | L19: FY34E | M19: FY35E
A20: Eligible treated second-line PBC patients | B20: patients | C20: ~US$1.5bn market divided by c.US$100k net revenue/patient | D20: 14000 | E20: 14280 | F20: 14565.6 | G20: 14856.912 | H20: 15154.05 | I20: 15457.131 | J20: 15766.274 | K20: 16081.599 | L20: 16403.231 | M20: 16731.296
A21: Net annual revenue per patient | B21: $000 | C21: Net price after gross-to-net; list-price benchmark US$138k-151k | D21: 100 | E21: 101 | F21: 102.01 | G21: 103.0301 | H21: 104.0604 | I21: 105.10101 | J21: 106.15202 | K21: 107.21354 | L21: 108.28567 | M21: 109.36853
A22: Average treated share | B22: % | C22: Average share of eligible treated patients; FY28/FY29 calibrated to US$20m/US$70m report forecast | D22: 0 | E22: 0 | F22: 0.016 | G22: 0.048 | H22: 0.085 | I22: 0.115 | J22: 0.14 | K22: 0.155 | L22: 0.16 | M22: 0.16
A23: Launch-year factor | B23: % | C23: Partial-year commercial contribution | D23: 0 | E23: 0 | F23: 0.9 | G23: 1 | H23: 1 | I23: 1 | J23: 1 | K23: 1 | L23: 1 | M23: 1
A24: Treated patient equivalents | B24: patients | C24: Eligible patients × share × launch factor | D24: =D20*D22*D23 -> 0 | E24: =E20*E22*E23 -> 0 | F24: =F20*F22*F23 -> 209.74464 | G24: =G20*G22*G23 -> 713.13178 | H24: =H20*H22*H23 -> 1288.0943 | I24: =I20*I22*I23 -> 1777.5701 | J24: =J20*J22*J23 -> 2207.2783 | K24: =K20*K22*K23 -> 2492.6479 | ... M24: =M20*M22*M23 -> 2677.0074
A25: Zydus end-market sales | B25: $m | C25: Patient equivalents × annual net revenue | D25: =D24*D21/1000 -> 0 | E25: =E24*E21/1000 -> 0 | F25: =F24*F21/1000 -> 21.396051 | G25: =G24*G21/1000 -> 73.474038 | H25: =H24*H21/1000 -> 134.03961 | I25: =I24*I21/1000 -> 186.8244 | J25: =J24*J21/1000 -> 234.30704 | K25: =K24*K21/1000 -> 267.24559 | ... M25: =M24*M21/1000 -> 292.78035
A26: Zydus economics share | B26: % | C26: Internally developed and commercialized; 100% revenue capture | D26: 1 | E26: 1 | F26: 1 | G26: 1 | H26: 1 | I26: 1 | J26: 1 | K26: 1 | L26: 1 | M26: 1
A27: Probability of success | B27: % | C27: Late-stage / regulatory-stage probability before PDUFA | D27: 0.85 | E27: 0.85 | F27: 0.85 | G27: 0.85 | H27: 0.85 | I27: 0.85 | J27: 0.85 | K27: 0.85 | L27: 0.85 | M27: 0.85
A28: Contribution margin | B28: % | C28: Launch investment depresses early margin; mature 35-45% range | D28: 0 | E28: 0 | F28: 0.2 | G28: 0.3 | H28: 0.35 | I28: 0.38 | J28: 0.4 | K28: 0.4 | L28: 0.4 | M28: 0.4
A36: MODEL OUTPUTS
A37: End-market / gross sales | B37: $m | D37: =D25 -> 0 | E37: =E25 -> 0 | F37: =F25 -> 21.396051 | G37: =G25 -> 73.474038 | H37: =H25 -> 134.03961 | I37: =I25 -> 186.8244 | J37: =J25 -> 234.30704 | K37: =K25 -> 267.24559 | ... M37: =M25 -> 292.78035
A38: Zydus reported revenue | B38: $m | D38: =D25*D26*$B$9 -> 0 | E38: =E25*E26*$B$9 -> 0 | F38: =F25*F26*$B$9 -> 21.396051 | G38: =G25*G26*$B$9 -> 73.474038 | H38: =H25*H26*$B$9 -> 134.03961 | I38: =I25*I26*$B$9 -> 186.8244 | J38: =J25*J26*$B$9 -> 234.30704 | K38: =K25*K26*$B$9 -> 267.24559 | ... M38: =M25*M26*$B$9 -> 292.78035
A39: Risk-adjusted revenue | B39: $m | D39: =D38*D27 -> 0 | E39: =E38*E27 -> 0 | F39: =F38*F27 -> 18.186643 | G39: =G38*G27 -> 62.452932 | H39: =H38*H27 -> 113.93367 | I39: =I38*I27 -> 158.80074 | J39: =J38*J27 -> 199.16099 | K39: =K38*K27 -> 227.15875 | ... M39: =M38*M27 -> 248.8633
A40: Contribution margin | B40: % | D40: =D28 -> 0 | E40: =E28 -> 0 | F40: =F28 -> 0.2 | G40: =G28 -> 0.3 | H40: =H28 -> 0.35 | I40: =I28 -> 0.38 | J40: =J28 -> 0.4 | K40: =K28 -> 0.4 | ... M40: =M28 -> 0.4
A41: Contribution profit | B41: $m | D41: =D38*D40 -> 0 | E41: =E38*E40 -> 0 | F41: =F38*F40 -> 4.2792101 | G41: =G38*G40 -> 22.042211 | H41: =H38*H40 -> 46.913862 | I41: =I38*I40 -> 70.993273 | J41: =J38*J40 -> 93.722818 | K41: =K38*K40 -> 106.89824 | ... M41: =M38*M40 -> 117.11214
A42: Risk-adjusted contribution profit | B42: $m | D42: =D39*D40 -> 0 | E42: =E39*E40 -> 0 | F42: =F39*F40 -> 3.6373286 | G42: =G39*G40 -> 18.73588 | H42: =H39*H40 -> 39.876783 | I42: =I39*I40 -> 60.344282 | J42: =J39*J40 -> 79.664395 | K42: =K39*K40 -> 90.863502 | ... M42: =M39*M40 -> 99.54532
A43: Zydus reported revenue | B43: INRm | D43: =D38*'Global Assump'!D$4 -> 0 | E43: =E38*'Global Assump'!E$4 -> 0 | F43: =F38*'Global Assump'!F$4 -> 1925.6446 | G43: =G38*'Global Assump'!G$4 -> 6759.6115 | H43: =H38*'Global Assump'!H$4 -> 12599.723 | I43: =I38*'Global Assump'!I$4 -> 17935.143 | J43: =J38*'Global Assump'!J$4 -> 22962.09 | K43: =K38*'Global Assump'!K$4 -> 26724.559 | ... M43: =M38*'Global Assump'!M$4 -> 30449.157
A44: Risk-adjusted revenue | B44: INRm | D44: =D39*'Global Assump'!D$4 -> 0 | E44: =E39*'Global Assump'!E$4 -> 0 | F44: =F39*'Global Assump'!F$4 -> 1636.7979 | G44: =G39*'Global Assump'!G$4 -> 5745.6698 | H44: =H39*'Global Assump'!H$4 -> 10709.765 | I44: =I39*'Global Assump'!I$4 -> 15244.871 | J44: =J39*'Global Assump'!J$4 -> 19517.777 | K44: =K39*'Global Assump'!K$4 -> 22715.875 | ... M44: =M39*'Global Assump'!M$4 -> 25881.783
A46: SOURCES, LOGIC AND LIMITATIONS
A47: • FY28 and FY29 output is calibrated to approximately US$20m and US$70m, respectively, as stated in the report.
A48: • MASH is excluded from the base case. The report includes no MASH revenue pending registrational evidence.

Sheet Usnoflast
A1: Usnoflast | US ALS
A2: A high-value ALS asset with no near-term earnings contribution; the workbook separates commercial potential from present clinical probability.
A4: ASSET FRAME
A5: Asset / franchise | B5: Usnoflast | US ALS
A6: Category | B6: NCE / innovation
A7: Geography | B7: US
A8: Status / launch window | B8: Phase IIb UNITE-ALS; CY28 readout; launch FY33 earliest
A9: Include in Summary? | B9: 1
A10: Report benchmark low ($m) | B10: 300
A11: Report benchmark high ($m) | B11: 500
A12: Model benchmark value (Peak) | B12: =MAX(D38:M38) -> 480.34276
A13: Benchmark check | B13: =IF(AND(B12>=B10,B12<=B11),"Within range",IF(B12<B10,"Below range","Above range")) -> Within range
A14: Evidence confidence | B14: Medium
A15: Principal risk | B15: Phase IIb efficacy, Phase III requirement, regulatory path and retained US economics
A16: Primary benchmark source | B16: Zydus Detailed Note, pp. 17-18; Zydus Usnoflast Fast Track release
A18: FIRST-PRINCIPLES COMMERCIAL BUILD
A19: Commercial driver | B19: Units | C19: Source / interpretation | D19: FY26A | E19: FY27E | F19: FY28E | G19: FY29E | H19: FY30E | I19: FY31E | J19: FY32E | K19: FY33E | L19: FY34E | M19: FY35E
A20: US prevalent ALS patients | B20: patients | C20: Report benchmark of c.35,000 prevalent patients | D20: 35000 | E20: 35350 | F20: 35703.5 | G20: 36060.535 | H20: 36421.14 | I20: 36785.352 | J20: 37153.205 | K20: 37524.737 | L20: 37899.985 | M20: 38278.985
A21: Net annual revenue per patient | B21: $000 | C21: Analyst net-price assumption; within the range supported by orphan ALS economics | D21: 140 | E21: 142.8 | F21: 145.656 | G21: 148.56912 | H21: 151.5405 | I21: 154.57131 | J21: 157.66274 | K21: 160.81599 | L21: 164.03231 | M21: 167.31296
A22: Average treated share | B22: % | C22: Implies c.3,000-5,000 peak treated patients, consistent with the report | D22: 0 | E22: 0 | F22: 0 | G22: 0 | H22: 0 | I22: 0 | J22: 0 | K22: 0.02 | L22: 0.05 | M22: 0.075
A23: Launch-year factor | B23: % | C23: Partial-year commercial contribution | D23: 0 | E23: 0 | F23: 0 | G23: 0 | H23: 0 | I23: 0 | J23: 0 | K23: 0.5 | L23: 1 | M23: 1
A24: Treated patient equivalents | B24: patients | C24: Eligible patients × share × launch factor | D24: =D20*D22*D23 -> 0 | E24: =E20*E22*E23 -> 0 | F24: =F20*F22*F23 -> 0 | G24: =G20*G22*G23 -> 0 | H24: =H20*H22*H23 -> 0 | I24: =I20*I22*I23 -> 0 | J24: =J20*J22*J23 -> 0 | K24: =K20*K22*K23 -> 375.24737 | ... M24: =M20*M22*M23 -> 2870.9238
A25: Zydus end-market sales | B25: $m | C25: Patient equivalents × annual net revenue | D25: =D24*D21/1000 -> 0 | E25: =E24*E21/1000 -> 0 | F25: =F24*F21/1000 -> 0 | G25: =G24*G21/1000 -> 0 | H25: =H24*H21/1000 -> 0 | I25: =I24*I21/1000 -> 0 | J25: =J24*J21/1000 -> 0 | K25: =K24*K21/1000 -> 60.345779 | ... M25: =M24*M21/1000 -> 480.34276
A26: Zydus economics share | B26: % | C26: Assumes Zydus retains US economics and uses a focused neurology organization | D26: 1 | E26: 1 | F26: 1 | G26: 1 | H26: 1 | I26: 1 | J26: 1 | K26: 1 | L26: 1 | M26: 1
A27: Probability of success | B27: % | C27: Current clinical probability applied to all commercial years; editable | D27: 0.25 | E27: 0.25 | F27: 0.25 | G27: 0.25 | H27: 0.25 | I27: 0.25 | J27: 0.25 | K27: 0.25 | L27: 0.25 | M27: 0.25
A28: Contribution margin | B28: % | C28: Mature incremental EBITDA proxy based on US$150-250m EBITDA on US$300-500m peak sales | D28: 0 | E28: 0 | F28: 0 | G28: 0 | H28: 0 | I28: 0 | J28: 0 | K28: 0.5 | L28: 0.52 | M28: 0.52
A36: MODEL OUTPUTS
A37: End-market / gross sales | B37: $m | D37: =D25 -> 0 | E37: =E25 -> 0 | F37: =F25 -> 0 | G37: =G25 -> 0 | H37: =H25 -> 0 | I37: =I25 -> 0 | J37: =J25 -> 0 | K37: =K25 -> 60.345779 | ... M37: =M25 -> 480.34276
A38: Zydus reported revenue | B38: $m | D38: =D25*D26*$B$9 -> 0 | E38: =E25*E26*$B$9 -> 0 | F38: =F25*F26*$B$9 -> 0 | G38: =G25*G26*$B$9 -> 0 | H38: =H25*H26*$B$9 -> 0 | I38: =I25*I26*$B$9 -> 0 | J38: =J25*J26*$B$9 -> 0 | K38: =K25*K26*$B$9 -> 60.345779 | ... M38: =M25*M26*$B$9 -> 480.34276
A39: Risk-adjusted revenue | B39: $m | D39: =D38*D27 -> 0 | E39: =E38*E27 -> 0 | F39: =F38*F27 -> 0 | G39: =G38*G27 -> 0 | H39: =H38*H27 -> 0 | I39: =I38*I27 -> 0 | J39: =J38*J27 -> 0 | K39: =K38*K27 -> 15.086445 | ... M39: =M38*M27 -> 120.08569
A40: Contribution margin | B40: % | D40: =D28 -> 0 | E40: =E28 -> 0 | F40: =F28 -> 0 | G40: =G28 -> 0 | H40: =H28 -> 0 | I40: =I28 -> 0 | J40: =J28 -> 0 | K40: =K28 -> 0.5 | ... M40: =M28 -> 0.52
A41: Contribution profit | B41: $m | D41: =D38*D40 -> 0 | E41: =E38*E40 -> 0 | F41: =F38*F40 -> 0 | G41: =G38*G40 -> 0 | H41: =H38*H40 -> 0 | I41: =I38*I40 -> 0 | J41: =J38*J40 -> 0 | K41: =K38*K40 -> 30.17289 | ... M41: =M38*M40 -> 249.77824
A42: Risk-adjusted contribution profit | B42: $m | D42: =D39*D40 -> 0 | E42: =E39*E40 -> 0 | F42: =F39*F40 -> 0 | G42: =G39*G40 -> 0 | H42: =H39*H40 -> 0 | I42: =I39*I40 -> 0 | J42: =J39*J40 -> 0 | K42: =K39*K40 -> 7.5432224 | ... M42: =M39*M40 -> 62.444559
A43: Zydus reported revenue | B43: INRm | D43: =D38*'Global Assump'!D$4 -> 0 | E43: =E38*'Global Assump'!E$4 -> 0 | F43: =F38*'Global Assump'!F$4 -> 0 | G43: =G38*'Global Assump'!G$4 -> 0 | H43: =H38*'Global Assump'!H$4 -> 0 | I43: =I38*'Global Assump'!I$4 -> 0 | J43: =J38*'Global Assump'!J$4 -> 0 | K43: =K38*'Global Assump'!K$4 -> 6034.5779 | ... M43: =M38*'Global Assump'!M$4 -> 49955.648
A44: Risk-adjusted revenue | B44: INRm | D44: =D39*'Global Assump'!D$4 -> 0 | E44: =E39*'Global Assump'!E$4 -> 0 | F44: =F39*'Global Assump'!F$4 -> 0 | G44: =G39*'Global Assump'!G$4 -> 0 | H44: =H39*'Global Assump'!H$4 -> 0 | I44: =I39*'Global Assump'!I$4 -> 0 | J44: =J39*'Global Assump'!J$4 -> 0 | K44: =K39*'Global Assump'!K$4 -> 1508.6445 | ... M44: =M39*'Global Assump'!M$4 -> 12488.912
A46: SOURCES, LOGIC AND LIMITATIONS
A47: • No revenue is included through FY31. FY33 is the first launch year in the base trajectory.
A48: • The commercial peak is visible separately from the probability-adjusted revenue used for valuation discipline.

Sheet Palbociclib
A1: Palbociclib | Paragraph IV
A2: The largest near-term replacement product; exclusivity monetization is tempered by capsule competition and partner economics.
A4: ASSET FRAME
A5: Asset / franchise | B5: Palbociclib | Paragraph IV
A6: Category | B6: Paragraph IV / complex generic
A7: Geography | B7: US
A8: Status / launch window | B8: Synthon sole first applicant for tablets; modeled launch FY28
A9: Include in Summary? | B9: 1
A10: Report benchmark low ($m) | B10: 120
A11: Report benchmark high ($m) | B11: 180
A12: Model benchmark value (Peak) | B12: =MAX(D38:M38) -> 143.325
A13: Benchmark check | B13: =IF(AND(B12>=B10,B12<=B11),"Within range",IF(B12<B10,"Below range","Above range")) -> Within range
A14: Evidence confidence | B14: High
A15: Principal risk | B15: Settlement timing, capsule competition, entrant count and Synthon economics
A16: Primary benchmark source | B16: Zydus Detailed Note, p. 11
A18: FIRST-PRINCIPLES COMMERCIAL BUILD
A19: Commercial driver | B19: Units | C19: Source / interpretation | D19: FY26A | E19: FY27E | F19: FY28E | G19: FY29E | H19: FY30E | I19: FY31E | J19: FY32E | K19: FY33E | L19: FY34E | M19: FY35E
A20: Reference / addressable market | B20: $m | C20: US reference-brand market / analyst estimate | D20: 2700 | E20: 2550 | F20: 2400 | G20: 2300 | H20: 2100 | I20: 1900 | J20: 1700 | K20: 1500 | L20: 1300 | M20: 1100
A21: Addressable pool / price-retention factor | B21: % | C21: Post-LOE price retention / addressable dosage-form factor | D21: 0 | E21: 0 | F21: 0.35 | G21: 0.18 | H21: 0.13 | I21: 0.1 | J21: 0.08 | K21: 0.07 | L21: 0.06 | M21: 0.05
A22: Addressable commercial pool | B22: $m | C22: Reference market × addressable factor | D22: =D20*D21 -> 0 | E22: =E20*E21 -> 0 | F22: =F20*F21 -> 840 | G22: =G20*G21 -> 414 | H22: =H20*H21 -> 273 | I22: =I20*I21 -> 190 | J22: =J20*J21 -> 136 | K22: =K20*K21 -> 105 | ... M22: =M20*M21 -> 55
A23: Zydus end-market share | B23: % | C23: Zydus share of generic/biosimilar pool | D23: 0 | E23: 0 | F23: 0.35 | G23: 0.3 | H23: 0.27 | I23: 0.25 | J23: 0.23 | K23: 0.22 | L23: 0.2 | M23: 0.2
A24: Launch-year factor | B24: % | C24: Partial-year commercial contribution | D24: 0 | E24: 0 | F24: 0.75 | G24: 1 | H24: 1 | I24: 1 | J24: 1 | K24: 1 | L24: 1 | M24: 1
A25: Zydus end-market sales | B25: $m | C25: Addressable pool × share × launch factor | D25: =D22*D23*D24 -> 0 | E25: =E22*E23*E24 -> 0 | F25: =F22*F23*F24 -> 220.5 | G25: =G22*G23*G24 -> 124.2 | H25: =H22*H23*H24 -> 73.71 | I25: =I22*I23*I24 -> 47.5 | J25: =J22*J23*J24 -> 31.28 | K25: =K22*K23*K24 -> 23.1 | ... M25: =M22*M23*M24 -> 11
A26: Zydus economics share | B26: % | C26: Zydus share after partner/supply economics | D26: 0.65 | E26: 0.65 | F26: 0.65 | G26: 0.65 | H26: 0.65 | I26: 0.65 | J26: 0.65 | K26: 0.65 | L26: 0.65 | M26: 0.65
A27: Probability of success | B27: % | C27: Legal, filing and approval probability | D27: 0.85 | E27: 0.85 | F27: 0.85 | G27: 0.85 | H27: 0.85 | I27: 0.85 | J27: 0.85 | K27: 0.85 | L27: 0.85 | M27: 0.85
A28: Contribution margin | B28: % | C28: Contribution margin proxy | D28: 0 | E28: 0 | F28: 0.23 | G28: 0.22 | H28: 0.21 | I28: 0.2 | J28: 0.2 | K28: 0.2 | L28: 0.2 | M28: 0.2
A36: MODEL OUTPUTS
A37: End-market / gross sales | B37: $m | D37: =D25 -> 0 | E37: =E25 -> 0 | F37: =F25 -> 220.5 | G37: =G25 -> 124.2 | H37: =H25 -> 73.71 | I37: =I25 -> 47.5 | J37: =J25 -> 31.28 | K37: =K25 -> 23.1 | ... M37: =M25 -> 11
A38: Zydus reported revenue | B38: $m | D38: =D25*D26*$B$9 -> 0 | E38: =E25*E26*$B$9 -> 0 | F38: =F25*F26*$B$9 -> 143.325 | G38: =G25*G26*$B$9 -> 80.73 | H38: =H25*H26*$B$9 -> 47.9115 | I38: =I25*I26*$B$9 -> 30.875 | J38: =J25*J26*$B$9 -> 20.332 | K38: =K25*K26*$B$9 -> 15.015 | ... M38: =M25*M26*$B$9 -> 7.15
A39: Risk-adjusted revenue | B39: $m | D39: =D38*D27 -> 0 | E39: =E38*E27 -> 0 | F39: =F38*F27 -> 121.82625 | G39: =G38*G27 -> 68.6205 | H39: =H38*H27 -> 40.724775 | I39: =I38*I27 -> 26.24375 | J39: =J38*J27 -> 17.2822 | K39: =K38*K27 -> 12.76275 | ... M39: =M38*M27 -> 6.0775
A40: Contribution margin | B40: % | D40: =D28 -> 0 | E40: =E28 -> 0 | F40: =F28 -> 0.23 | G40: =G28 -> 0.22 | H40: =H28 -> 0.21 | I40: =I28 -> 0.2 | J40: =J28 -> 0.2 | K40: =K28 -> 0.2 | ... M40: =M28 -> 0.2
A41: Contribution profit | B41: $m | D41: =D38*D40 -> 0 | E41: =E38*E40 -> 0 | F41: =F38*F40 -> 32.96475 | G41: =G38*G40 -> 17.7606 | H41: =H38*H40 -> 10.061415 | I41: =I38*I40 -> 6.175 | J41: =J38*J40 -> 4.0664 | K41: =K38*K40 -> 3.003 | ... M41: =M38*M40 -> 1.43
A42: Risk-adjusted contribution profit | B42: $m | D42: =D39*D40 -> 0 | E42: =E39*E40 -> 0 | F42: =F39*F40 -> 28.020038 | G42: =G39*G40 -> 15.09651 | H42: =H39*H40 -> 8.5522027 | I42: =I39*I40 -> 5.24875 | J42: =J39*J40 -> 3.45644 | K42: =K39*K40 -> 2.55255 | ... M42: =M39*M40 -> 1.2155
A43: Zydus reported revenue | B43: INRm | D43: =D38*'Global Assump'!D$4 -> 0 | E43: =E38*'Global Assump'!E$4 -> 0 | F43: =F38*'Global Assump'!F$4 -> 12899.25 | G43: =G38*'Global Assump'!G$4 -> 7427.16 | H43: =H38*'Global Assump'!H$4 -> 4503.681 | I43: =I38*'Global Assump'!I$4 -> 2964 | J43: =J38*'Global Assump'!J$4 -> 1992.536 | K43: =K38*'Global Assump'!K$4 -> 1501.5 | ... M43: =M38*'Global Assump'!M$4 -> 743.6
A44: Risk-adjusted revenue | B44: INRm | D44: =D39*'Global Assump'!D$4 -> 0 | E44: =E39*'Global Assump'!E$4 -> 0 | F44: =F39*'Global Assump'!F$4 -> 10964.362 | G44: =G39*'Global Assump'!G$4 -> 6313.086 | H44: =H39*'Global Assump'!H$4 -> 3828.1289 | I44: =I39*'Global Assump'!I$4 -> 2519.4 | J44: =J39*'Global Assump'!J$4 -> 1693.6556 | K44: =K39*'Global Assump'!K$4 -> 1276.275 | ... M44: =M39*'Global Assump'!M$4 -> 632.06
A46: SOURCES, LOGIC AND LIMITATIONS
A47: • Tablet economics are modeled separately from the wider palbociclib molecule market.
A48: • Revenue declines rapidly after the launch window as price and share normalize.

Sheet Olaparib
A1: Olaparib | Paragraph IV
A2: A three-to-four-player oncology market supports a smaller but more durable post-exclusivity pool than commodity generics.
A4: ASSET FRAME
A5: Asset / franchise | B5: Olaparib | Paragraph IV
A6: Category | B6: Paragraph IV / complex generic
A7: Geography | B7: US
A8: Status / launch window | B8: Earliest plausible entry Sep-2027; modeled FY28 partial-year launch
A9: Include in Summary? | B9: 1
A10: Report benchmark low ($m) | B10: 60
A11: Report benchmark high ($m) | B11: 100
A12: Model benchmark value (Peak) | B12: =MAX(D38:M38) -> 85
A13: Benchmark check | B13: =IF(AND(B12>=B10,B12<=B11),"Within range",IF(B12<B10,"Below range","Above range")) -> Within range
A14: Evidence confidence | B14: High
A15: Principal risk | B15: Patent timing, additional entrants and launch-at-risk constraints
A16: Primary benchmark source | B16: Zydus Detailed Note, p. 11
A18: FIRST-PRINCIPLES COMMERCIAL BUILD
A19: Commercial driver | B19: Units | C19: Source / interpretation | D19: FY26A | E19: FY27E | F19: FY28E | G19: FY29E | H19: FY30E | I19: FY31E | J19: FY32E | K19: FY33E | L19: FY34E | M19: FY35E
A20: Reference / addressable market | B20: $m | C20: US reference-brand market / analyst estimate | D20: 0 | E20: 0 | F20: 1800 | G20: 1700 | H20: 1550 | I20: 1400 | J20: 1250 | K20: 1100 | L20: 950 | M20: 800
A21: Addressable pool / price-retention factor | B21: % | C21: Post-LOE price retention / addressable dosage-form factor | D21: 0 | E21: 0 | F21: 0.25 | G21: 0.2 | H21: 0.16 | I21: 0.13 | J21: 0.11 | K21: 0.09 | L21: 0.08 | M21: 0.07
